<?xml version="1.0" ?>
<!-- =================================================================================== -->
<!-- |    This document was autogenerated by xacro from urdf/tx2_60l.xacro             | -->
<!-- |    EDITING THIS FILE BY HAND IS NOT RECOMMENDED                                 | -->
<!-- =================================================================================== -->
<robot name="staubli_tx2_60l">
  <!-- colours based on RAL values supplied by Staubli -->
  <!-- all RAL colours converted using http://www.visual-graphics.de/en/customer-care/ral-colours -->
  <!-- default colours for robots -->
  <!-- links: main serial chain -->
  <link name="base_link">
    <visual>
      <origin rpy="0 0 0" xyz="0 0 0"/>
      <geometry>
        <mesh filename="package://staubli_tx2_60_support/meshes/tx2_60/visual/base_link.stl"/>
      </geometry>
      <material name="">
        <color rgba="1.0 0.6078431372549019 0.0 1.0"/>
      </material>
    </visual>
    <collision>
      <origin rpy="0 0 0" xyz="0 0 0"/>
      <geometry>
        <mesh filename="package://staubli_tx2_60_support/meshes/tx2_60/collision/base_link.stl"/>
      </geometry>
    </collision>
  </link>
  <link name="link_1">
    <visual>
      <origin rpy="0 0 0" xyz="0 0 0"/>
      <geometry>
        <mesh filename="package://staubli_tx2_60_support/meshes/tx2_60/visual/link_1.stl"/>
      </geometry>
      <material name="">
        <color rgba="1.0 0.6078431372549019 0.0 1.0"/>
      </material>
    </visual>
    <collision>
      <origin rpy="0 0 0" xyz="0 0 0"/>
      <geometry>
        <mesh filename="package://staubli_tx2_60_support/meshes/tx2_60/collision/link_1.stl"/>
      </geometry>
    </collision>
  </link>
  <link name="link_2">
    <visual>
      <origin rpy="0 0 0" xyz="0 0 0"/>
      <geometry>
        <mesh filename="package://staubli_tx2_60_support/meshes/tx2_60l/visual/link_2.stl"/>
      </geometry>
      <material name="">
        <color rgba="1.0 0.6078431372549019 0.0 1.0"/>
      </material>
    </visual>
    <collision>
      <origin rpy="0 0 0" xyz="0 0 0"/>
      <geometry>
        <mesh filename="package://staubli_tx2_60_support/meshes/tx2_60l/collision/link_2.stl"/>
      </geometry>
    </collision>
  </link>
  <link name="link_3">
    <visual>
      <origin rpy="0 0 0" xyz="0 0 0"/>
      <geometry>
        <mesh filename="package://staubli_tx2_60_support/meshes/tx2_60/visual/link_3.stl"/>
      </geometry>
      <material name="">
        <color rgba="1.0 0.6078431372549019 0.0 1.0"/>
      </material>
    </visual>
    <collision>
      <origin rpy="0 0 0" xyz="0 0 0"/>
      <geometry>
        <mesh filename="package://staubli_tx2_60_support/meshes/tx2_60/collision/link_3.stl"/>
      </geometry>
    </collision>
  </link>
  <link name="link_4">
    <visual>
      <origin rpy="0 0 0" xyz="0 0 0"/>
      <geometry>
        <mesh filename="package://staubli_tx2_60_support/meshes/tx2_60l/visual/link_4.stl"/>
      </geometry>
      <material name="">
        <color rgba="1.0 0.6078431372549019 0.0 1.0"/>
      </material>
    </visual>
    <collision>
      <origin rpy="0 0 0" xyz="0 0 0"/>
      <geometry>
        <mesh filename="package://staubli_tx2_60_support/meshes/tx2_60l/collision/link_4.stl"/>
      </geometry>
    </collision>
  </link>
  <link name="link_5">
    <visual>
      <origin rpy="0 0 0" xyz="0 0 0"/>
      <geometry>
        <mesh filename="package://staubli_tx60_support/meshes/tx60/visual/link_5.stl"/>
      </geometry>
      <material name="">
        <color rgba="0.5294117647058824 0.5215686274509804 0.5058823529411764 1.0"/>
      </material>
    </visual>
    <collision>
      <origin rpy="0 0 0" xyz="0 0 0"/>
      <geometry>
        <mesh filename="package://staubli_tx60_support/meshes/tx60/collision/link_5.stl"/>
      </geometry>
    </collision>
  </link>
  <link name="link_6">
    <visual>
      <origin rpy="0 0 0" xyz="0 0 0"/>
      <geometry>
        <mesh filename="package://staubli_tx60_support/meshes/tx60/visual/link_6.stl"/>
      </geometry>
      <material name="">
        <color rgba="0.5294117647058824 0.5215686274509804 0.5058823529411764 1.0"/>
      </material>
    </visual>
    <collision>
      <origin rpy="0 0 0" xyz="0 0 0"/>
      <geometry>
        <mesh filename="package://staubli_tx60_support/meshes/tx60/collision/link_6.stl"/>
      </geometry>
    </collision>
  </link>
  <!-- joints: main serial chain -->
  <joint name="joint_1" type="revolute">
    <origin rpy="0 0 0" xyz="0 0 0.375"/>
    <parent link="base_link"/>
    <child link="link_1"/>
    <axis xyz="0 0 1"/>
    <!-- from Staubli instruction manual:
      (1) effort limit = 126 Nm if floor mounted
      (2) effort limit = 40 Nm if wall mounted -->
    <!-- nominal velocity limits are used -->
    <limit effort="126.0" lower="-3.141592653589793" upper="3.141592653589793" velocity="7.592182246175334"/>
  </joint>
  <joint name="joint_2" type="revolute">
    <origin rpy="0 0 0" xyz="0 0 0"/>
    <parent link="link_1"/>
    <child link="link_2"/>
    <axis xyz="0 1 0"/>
    <!-- nominal velocity limits are used -->
    <limit effort="47.0" lower="-2.2252947962927703" upper="2.2252947962927703" velocity="6.719517620178169"/>
  </joint>
  <joint name="joint_3" type="revolute">
    <origin rpy="0 0 0" xyz="0 0.02 0.40"/>
    <parent link="link_2"/>
    <child link="link_3"/>
    <axis xyz="0 1 0"/>
    <!-- nominal velocity limits are used -->
    <limit effort="32.0" lower="-2.6616271092913526" upper="2.6616271092913526" velocity="8.726646259971648"/>
  </joint>
  <joint name="joint_4" type="revolute">
    <origin rpy="0 0 0" xyz="0 0 0"/>
    <parent link="link_3"/>
    <child link="link_4"/>
    <axis xyz="0 0 1"/>
    <!-- nominal velocity limits are used -->
    <limit effort="7.0" lower="-4.71238898038469" upper="4.71238898038469" velocity="17.36602605734358"/>
  </joint>
  <joint name="joint_5" type="revolute">
    <origin rpy="0 0 0" xyz="0 0 0.45"/>
    <parent link="link_4"/>
    <child link="link_5"/>
    <axis xyz="0 1 0"/>
    <!-- nominal velocity limits are used -->
    <limit effort="8.0" lower="-2.111848394913139" upper="2.3125612588924866" velocity="18.58775653373961"/>
  </joint>
  <joint name="joint_6" type="revolute">
    <origin rpy="0 0 0" xyz="0 0 0.07"/>
    <parent link="link_5"/>
    <child link="link_6"/>
    <axis xyz="0 0 1"/>
    <!-- nominal velocity limits are used -->
    <limit effort="2.0" lower="-4.71238898038469" upper="4.71238898038469" velocity="25.220007691318063"/>
  </joint>
  <!-- ROS-Industrial 'base' frame: base_link to Staubli World Coordinates transform -->
  <link name="base"/>
  <joint name="base_link-base" type="fixed">
    <origin rpy="0 0 0" xyz="0 0 0.375"/>
    <parent link="base_link"/>
    <child link="base"/>
  </joint>
  <!-- ROS-Industrial 'flange' frame: attachment point for EEF models -->
  <link name="flange"/>
  <joint name="joint_6-flange" type="fixed">
    <origin rpy="0 -1.5707963267948966 0" xyz="0 0 0"/>
    <parent link="link_6"/>
    <child link="flange"/>
  </joint>
  <!-- ROS-Industrial 'tool0' frame: all-zeros tool frame -->
  <link name="tool0"/>
  <joint name="flange-tool0" type="fixed">
    <origin rpy="0 1.5707963267948966 0" xyz="0 0 0"/>
    <parent link="flange"/>
    <child link="tool0"/>
  </joint>
</robot>

