<?xml version="1.0" ?>
<!-- =================================================================================== -->
<!-- |    This document was autogenerated by xacro from irb6640_185_280.xacro          | -->
<!-- |    EDITING THIS FILE BY HAND IS NOT RECOMMENDED                                 | -->
<!-- =================================================================================== -->
<robot name="abb_irb6640_185_280" xmlns:xacro="http://ros.org/wiki/xacro">
  <!-- link list -->
  <link name="base_link">
    <collision name="collision">
      <geometry>
        <mesh filename="package://collision/base_link.stl"/>
      </geometry>
    </collision>
    <visual name="visual">
      <geometry>
        <mesh filename="package://visual/base_link.dae"/>
      </geometry>
      <material name="yellow">
        <color rgba="1 1 0 1"/>
      </material>
    </visual>
  </link>
  <link name="link_1">
    <collision name="collision">
      <geometry>
        <mesh filename="package://collision/link_1.stl"/>
      </geometry>
    </collision>
    <visual name="visual">
      <geometry>
        <mesh filename="package://visual/link_1.dae"/>
      </geometry>
      <material name="yellow"/>
    </visual>
  </link>
  <link name="link_2">
    <collision name="collision">
      <geometry>
        <mesh filename="package://collision/link_2.stl"/>
      </geometry>
    </collision>
    <visual name="visual">
      <geometry>
        <mesh filename="package://visual/link_2.dae"/>
      </geometry>
      <material name="yellow"/>
    </visual>
  </link>
  <link name="link_3">
    <collision name="collision">
      <geometry>
        <mesh filename="package://collision/link_3.stl"/>
      </geometry>
    </collision>
    <visual name="visual">
      <geometry>
        <mesh filename="package://visual/link_3.dae"/>
      </geometry>
      <material name="yellow"/>
    </visual>
  </link>
  <link name="link_4">
    <collision name="collision">
      <geometry>
        <mesh filename="package://collision/link_4.stl"/>
      </geometry>
    </collision>
    <visual name="visual">
      <geometry>
        <mesh filename="package://visual/link_4.dae"/>
      </geometry>
      <material name="yellow"/>
    </visual>
  </link>
  <link name="link_5">
    <collision name="collision">
      <geometry>
        <mesh filename="package://collision/link_5.stl"/>
      </geometry>
    </collision>
    <visual name="visual">
      <geometry>
        <mesh filename="package://visual/link_5.dae"/>
      </geometry>
      <material name="yellow"/>
    </visual>
  </link>
  <link name="link_6">
    <collision name="collision">
      <geometry>
        <mesh filename="package://collision/link_6.stl"/>
      </geometry>
    </collision>
    <visual name="visual">
      <geometry>
        <mesh filename="package://visual/link_6.dae"/>
      </geometry>
      <material name="yellow"/>
    </visual>
  </link>
  <link name="tool0"/>
  <!--Cylinder and piston -->
  <link name="link_cylinder">
    <collision name="collision">
      <geometry>
        <mesh filename="package://collision/cylinder_link.stl"/>
      </geometry>
    </collision>
    <visual name="visual">
      <geometry>
        <mesh filename="package://visual/cylinder_link.dae"/>
      </geometry>
      <material name="yellow"/>
    </visual>
  </link>
  <link name="link_piston">
    <collision name="collision">
      <geometry>
        <mesh filename="package://collision/piston_link.stl"/>
      </geometry>
    </collision>
    <visual name="visual">
      <geometry>
        <mesh filename="package://visual/piston_link.dae"/>
      </geometry>
      <material name="yellow"/>
    </visual>
  </link>
  <!-- end of link list -->
  <!-- joint list -->
  <joint name="joint_1" type="revolute">
    <origin rpy="0 0 0" xyz="0 0 0.780"/>
    <axis xyz="0 0 1"/>
    <parent link="base_link"/>
    <child link="link_1"/>
    <limit effort="0" lower="-2.967" upper="2.967" velocity="1.7453"/>
  </joint>
  <joint name="joint_2" type="revolute">
    <origin rpy="0 0 0" xyz="0.320 0 0"/>
    <axis xyz="0 1 0"/>
    <parent link="link_1"/>
    <child link="link_2"/>
    <limit effort="0" lower="-1.134" upper="1.4855" velocity="1.5707"/>
  </joint>
  <joint name="joint_3" type="revolute">
    <origin rpy="0 0 0" xyz="0 0 1.075"/>
    <axis xyz="0 1 0"/>
    <parent link="link_2"/>
    <child link="link_3"/>
    <limit effort="0" lower="-3.142" upper="1.222" velocity="1.5707"/>
  </joint>
  <joint name="joint_4" type="revolute">
    <origin rpy="0 0 0" xyz="0 0 0.2"/>
    <axis xyz="1 0 0"/>
    <parent link="link_3"/>
    <child link="link_4"/>
    <limit effort="0" lower="-5.236" upper="5.236" velocity="2.9671"/>
  </joint>
  <joint name="joint_5" type="revolute">
    <origin rpy="0 0 0" xyz="1.392 0 0 "/>
    <axis xyz="0 1 0"/>
    <parent link="link_4"/>
    <child link="link_5"/>
    <limit effort="0" lower="-2.094" upper="2.094" velocity="2.4435"/>
  </joint>
  <joint name="joint_6" type="revolute">
    <origin rpy="0 0 0" xyz="0.2 0 0 "/>
    <axis xyz="1 0 0"/>
    <parent link="link_5"/>
    <child link="link_6"/>
    <limit effort="0" lower="-6.283" upper="6.283" velocity="3.3161"/>
  </joint>
  <joint name="joint_6-tool0" type="fixed">
    <parent link="link_6"/>
    <child link="tool0"/>
    <origin rpy="0 1.57079632679 0" xyz="0 0 0"/>
  </joint>
  <joint name="joint_cylinder" type="continuous">
    <origin rpy="0 0 0" xyz="-0.3647 0 -0.1455"/>
    <axis xyz="0 1 0"/>
    <parent link="link_1"/>
    <child link="link_cylinder"/>
    <mimic joint="joint_2" multiplier="-0.25"/>
  </joint>
  <joint name="joint_piston" type="continuous">
    <origin rpy="0 0 0" xyz="-0.22 0 -0.0672"/>
    <axis xyz="0 1 0"/>
    <parent link="link_2"/>
    <child link="link_piston"/>
    <mimic joint="joint_2" multiplier="-1.25"/>
  </joint>
  <!-- end of joint list -->
  <!-- ROS base_link to ABB World Coordinates transform -->
  <link name="base"/>
  <joint name="base_link-base" type="fixed">
    <origin rpy="0 0 0" xyz="0 0 0"/>
    <parent link="base_link"/>
    <child link="base"/>
  </joint>
</robot>

