<?xml version="1.0" ?>
<!-- =================================================================================== -->
<!-- |    This document was autogenerated by xacro from urdf/tx90xl.xacro              | -->
<!-- |    EDITING THIS FILE BY HAND IS NOT RECOMMENDED                                 | -->
<!-- =================================================================================== -->
<robot name="staubli_tx90xl">
  <!-- colours based on RAL values supplied by Staubli -->
  <!-- all RAL colours converted using http://www.visual-graphics.de/en/customer-care/ral-colours -->
  <!-- default colours for robots -->
  <!-- links: main serial chain -->
  <link name="base_link">
    <visual>
      <origin rpy="0 0 0" xyz="0 0 0"/>
      <geometry>
        <mesh filename="package://staubli_tx90_support/meshes/tx90/visual/base_link.stl"/>
      </geometry>
      <material name="">
        <color rgba="1.0 0.6078431372549019 0.0 1.0"/>
      </material>
    </visual>
    <collision>
      <origin rpy="0 0 0" xyz="0 0 0"/>
      <geometry>
        <mesh filename="package://staubli_tx90_support/meshes/tx90/collision/base_link.stl"/>
      </geometry>
    </collision>
    <inertial>
      <mass value="10.733459"/>
      <origin rpy="0.0 0.0 0.0" xyz="0.014288 0.000001 0.122264"/>
      <inertia ixx="0.09659003750" ixy="-0.00000507582" ixz="-0.00380302939" iyy="0.08759138191" iyz="-0.00000102074" izz="0.08163249578"/>
    </inertial>
  </link>
  <link name="link_1">
    <visual>
      <origin rpy="0 0 0" xyz="0 0 0"/>
      <geometry>
        <mesh filename="package://staubli_tx90_support/meshes/tx90/visual/link_1.stl"/>
      </geometry>
      <material name="">
        <color rgba="1.0 0.6078431372549019 0.0 1.0"/>
      </material>
    </visual>
    <collision>
      <origin rpy="0 0 0" xyz="0 0 0"/>
      <geometry>
        <mesh filename="package://staubli_tx90_support/meshes/tx90/collision/link_1.stl"/>
      </geometry>
    </collision>
    <inertial>
      <mass value="16.934564"/>
      <origin rpy="0.0 0.0 0.0" xyz="0.019143 0.024764 -0.064596"/>
      <inertia ixx="0.222318" ixy="0.016499" ixz="0.023794" iyy="0.208959" iyz="0.031663" izz="0.157081"/>
    </inertial>
  </link>
  <link name="link_2">
    <visual>
      <origin rpy="0 0 0" xyz="0 0 0"/>
      <geometry>
        <mesh filename="package://staubli_tx90_support/meshes/tx90xl/visual/link_2.stl"/>
      </geometry>
      <material name="">
        <color rgba="1.0 0.6078431372549019 0.0 1.0"/>
      </material>
    </visual>
    <collision>
      <origin rpy="0 0 0" xyz="0 0 0"/>
      <geometry>
        <mesh filename="package://staubli_tx90_support/meshes/tx90xl/collision/link_2.stl"/>
      </geometry>
    </collision>
    <inertial>
      <mass value="17.789372"/>
      <origin rpy="0.0 0.0 0.0" xyz="-0.000005 0.219316 0.276936"/>
      <inertia ixx="1.071537" ixy="0.000005" ixz="-0.000015" iyy="1.108645" iyz="-0.007651" izz="0.074022"/>
    </inertial>
  </link>
  <link name="link_3">
    <visual>
      <origin rpy="0 0 0" xyz="0 0 0"/>
      <geometry>
        <mesh filename="package://staubli_tx90_support/meshes/tx90/visual/link_3.stl"/>
      </geometry>
      <material name="">
        <color rgba="1.0 0.6078431372549019 0.0 1.0"/>
      </material>
    </visual>
    <collision>
      <origin rpy="0 0 0" xyz="0 0 0"/>
      <geometry>
        <mesh filename="package://staubli_tx90_support/meshes/tx90/collision/link_3.stl"/>
      </geometry>
    </collision>
    <inertial>
      <mass value="7.501506"/>
      <origin rpy="0.0 0.0 0.0" xyz="0.000002 0.065008 0.003572"/>
      <inertia ixx="0.058902" ixy="0.000000" ixz="0.000001" iyy="0.056884" iyz="-0.003672" izz="0.034271"/>
    </inertial>
  </link>
  <link name="link_4">
    <visual>
      <origin rpy="0 0 0" xyz="0 0 0"/>
      <geometry>
        <mesh filename="package://staubli_tx90_support/meshes/tx90xl/visual/link_4.stl"/>
      </geometry>
      <material name="">
        <color rgba="1.0 0.6078431372549019 0.0 1.0"/>
      </material>
    </visual>
    <collision>
      <origin rpy="0 0 0" xyz="0 0 0"/>
      <geometry>
        <mesh filename="package://staubli_tx90_support/meshes/tx90xl/collision/link_4.stl"/>
      </geometry>
    </collision>
    <inertial>
      <mass value="7.916800"/>
      <origin rpy="0.0 0.0 0.0" xyz="-0.001746 0.050006 0.410582"/>
      <inertia ixx="0.188254" ixy="0.000042" ixz="-0.001998" iyy="0.182701" iyz="0.000005" izz="0.022684"/>
    </inertial>
  </link>
  <link name="link_5">
    <visual>
      <origin rpy="0 0 0" xyz="0 0 0"/>
      <geometry>
        <mesh filename="package://staubli_tx90_support/meshes/tx90/visual/link_5.stl"/>
      </geometry>
      <material name="">
        <color rgba="0.5294117647058824 0.5215686274509804 0.5058823529411764 1.0"/>
      </material>
    </visual>
    <collision>
      <origin rpy="0 0 0" xyz="0 0 0"/>
      <geometry>
        <mesh filename="package://staubli_tx90_support/meshes/tx90/collision/link_5.stl"/>
      </geometry>
    </collision>
    <inertial>
      <mass value="0.568760"/>
      <origin rpy="0.0 0.0 0.0" xyz="-0.000001 0.049931 0.022823"/>
      <inertia ixx="0.001084" ixy="0.000000" ixz="0.000000" iyy="0.001123" iyz="0.000001" izz="0.000383"/>
    </inertial>
  </link>
  <link name="link_6">
    <visual>
      <origin rpy="0 0 0" xyz="0 0 0"/>
      <geometry>
        <mesh filename="package://staubli_tx90_support/meshes/tx90/visual/link_6.stl"/>
      </geometry>
      <material name="">
        <color rgba="0.5294117647058824 0.5215686274509804 0.5058823529411764 1.0"/>
      </material>
    </visual>
    <collision>
      <origin rpy="0 0 0" xyz="0 0 0"/>
      <geometry>
        <mesh filename="package://staubli_tx90_support/meshes/tx90/collision/link_6.stl"/>
      </geometry>
    </collision>
    <inertial>
      <mass value="0.030977"/>
      <origin rpy="0.0 0.0 0.0" xyz="-0.000243 0.050001 -0.006293"/>
      <inertia ixx="0.000012" ixy="0.000000" ixz="0.000000" iyy="0.000011" iyz="0.000000" izz="0.000022"/>
    </inertial>
  </link>
  <!-- joints: main serial chain -->
  <joint name="joint_1" type="revolute">
    <origin rpy="0 0 0" xyz="0 0 0.478"/>
    <parent link="base_link"/>
    <child link="link_1"/>
    <axis xyz="0 0 1"/>
    <!-- from Staubli instruction manual:
      (1) effort limit = 318 Nm if floor mounted
      (2) effort limit = 111 Nm if wall mounted -->
    <limit effort="318.0" lower="-3.141592653589793" upper="3.141592653589793" velocity="6.981317007977318"/>
    <dynamics damping="0.0" friction="0.0"/>
  </joint>
  <joint name="joint_2" type="revolute">
    <origin rpy="0 0 0" xyz="0.050 0 0"/>
    <parent link="link_1"/>
    <child link="link_2"/>
    <axis xyz="0 1 0"/>
    <limit effort="90.0" lower="-2.2689280275926285" upper="2.5743606466916362" velocity="6.1086523819801535"/>
    <dynamics damping="0.0" friction="0.0"/>
  </joint>
  <joint name="joint_3" type="revolute">
    <origin rpy="0 0 0" xyz="0 0.05 0.650"/>
    <parent link="link_2"/>
    <child link="link_3"/>
    <axis xyz="0 1 0"/>
    <limit effort="53.0" lower="-2.530727415391778" upper="2.530727415391778" velocity="7.155849933176751"/>
    <dynamics damping="0.0" friction="0.0"/>
  </joint>
  <joint name="joint_4" type="revolute">
    <origin rpy="0 0 0" xyz="0 0 0"/>
    <parent link="link_3"/>
    <child link="link_4"/>
    <axis xyz="0 0 1"/>
    <limit effort="34.0" lower="-4.71238898038469" upper="4.71238898038469" velocity="9.42477796076938"/>
    <dynamics damping="0.0" friction="0.0"/>
  </joint>
  <joint name="joint_5" type="revolute">
    <origin rpy="0 0 0" xyz="0 0 0.650"/>
    <parent link="link_4"/>
    <child link="link_5"/>
    <axis xyz="0 1 0"/>
    <limit effort="29.0" lower="-2.007128639793479" upper="2.443460952792061" velocity="8.290313946973065"/>
    <dynamics damping="0.0" friction="0.0"/>
  </joint>
  <joint name="joint_6" type="revolute">
    <origin rpy="0 0 0" xyz="0 0 0.100"/>
    <parent link="link_5"/>
    <child link="link_6"/>
    <axis xyz="0 0 1"/>
    <limit effort="11.0" lower="-4.71238898038469" upper="4.71238898038469" velocity="13.264502315156905"/>
    <dynamics damping="0.0" friction="0.0"/>
  </joint>
  <!-- ROS-Industrial 'base' frame: base_link to Staubli World Coordinates transform -->
  <link name="base"/>
  <joint name="base_link-base" type="fixed">
    <origin rpy="0 0 0" xyz="0 0 0.478"/>
    <parent link="base_link"/>
    <child link="base"/>
  </joint>
  <!-- ROS-Industrial 'flange' frame: attachment point for EEF models -->
  <link name="flange"/>
  <joint name="joint_6-flange" type="fixed">
    <origin rpy="0 -1.5707963267948966 0" xyz="0 0 0"/>
    <parent link="link_6"/>
    <child link="flange"/>
  </joint>
  <!-- ROS-Industrial 'tool0' frame: all-zeros tool frame -->
  <link name="tool0"/>
  <joint name="flange-tool0" type="fixed">
    <origin rpy="0 1.5707963267948966 0" xyz="0 0 0"/>
    <parent link="flange"/>
    <child link="tool0"/>
  </joint>
</robot>

