<?xml version="1.0" ?>
<!-- =================================================================================== -->
<!-- |    This document was autogenerated by xacro from robot.urdf.xacro               | -->
<!-- |    EDITING THIS FILE BY HAND IS NOT RECOMMENDED                                 | -->
<!-- =================================================================================== -->
<robot name="lwa4p" xmlns:xacro="http://www.ros.org/wiki/xacro">
  <!-- common stuff -->
  <!-- see https://secure.wikimedia.org/wikipedia/en/wiki/List_of_moment_of_inertia_tensors -->
  <material name="Schunk/LightGrey">
    <color rgba="0.7 0.7 0.7 1.0"/>
  </material>
  <material name="Schunk/DarkGrey">
    <color rgba="0.4 0.4 0.4 1.0"/>
  </material>
  <material name="Schunk/Black">
    <color rgba="0.0 0.0 0.0 1.0"/>
  </material>
  <material name="Schunk/DarkGolden">
    <color rgba="0.4 0.4 0.3 1.0"/>
  </material>
  <material name="Schunk/Blue">
    <color rgba="0.0 0.0 0.8 1.0"/>
  </material>
  <!--pg70 gripper -->
  <!-- schunk lwa4p -->
  <gazebo>
    <plugin filename="libhwi_switch_gazebo_ros_control.so" name="ros_control">
      <robotNamespace>gripper</robotNamespace>
      <filterJointsParam>joint_names</filterJointsParam>
    </plugin>
  </gazebo>
  <!-- Used for fixing robot to Gazebo -->
  <link name="world"/>
  <!-- arm -->
  <!-- joint between base_link and lwa4p_extended_connector_link -->
  <joint name="arm_podest_joint" type="fixed">
    <origin rpy="0 0 0" xyz="0 0 0.052"/>
    <parent link="world"/>
    <child link="arm_podest_link"/>
  </joint>
  <link name="arm_podest_link">
    <inertial>
      <mass value="0.01"/>
      <origin xyz="0 0 0"/>
      <inertia ixx="0.001" ixy="0.0" ixz="0.0" iyy="0.001" iyz="0.0" izz="0.001"/>
    </inertial>
    <visual>
      <origin rpy="0 3.14159265359 0" xyz="0 0 0"/>
      <geometry>
        <mesh filename="package://schunk_description/meshes/lwa4p/arm_base_link.stl"/>
      </geometry>
    </visual>
    <collision>
      <origin rpy="0 3.14159265359 0" xyz="0 0 0"/>
      <geometry>
        <mesh filename="package://schunk_description/meshes/lwa4p/arm_base_link.stl"/>
      </geometry>
    </collision>
  </link>
  <joint name="arm_base_joint" type="fixed">
    <origin rpy="0 0 0" xyz="0 0 0.10"/>
    <parent link="arm_podest_link"/>
    <child link="arm_base_link"/>
  </joint>
  <link name="arm_base_link">
    <inertial>
      <mass value="0.01"/>
      <origin xyz="0 0 0"/>
      <inertia ixx="0.001" ixy="0.0" ixz="0.0" iyy="0.001" iyz="0.0" izz="0.001"/>
    </inertial>
  </link>
  <!-- joint between arm_0_link and arm_1_link -->
  <joint name="arm_1_joint" type="revolute">
    <origin rpy="0 0 0" xyz="0 0 0"/>
    <parent link="arm_base_link"/>
    <child link="arm_1_link"/>
    <axis xyz="0 0 1"/>
    <limit effort="370" lower="-2.94" upper="2.94" velocity="2.0"/>
    <!--safety_controller k_position="20" k_velocity="50" soft_lower_limit="${-6.28 + 0.01}" soft_upper_limit="${6.28 - 0.01}" /-->
  </joint>
  <link name="arm_1_link">
    <inertial>
      <mass value="0.01"/>
      <origin xyz="0 0 0"/>
      <inertia ixx="0.001" ixy="0.0" ixz="0.0" iyy="0.001" iyz="0.0" izz="0.001"/>
    </inertial>
    <!--
      <inertial>
        <origin xyz="0 0 0" rpy="0 0 0" />
        <mass value="0.29364"/>
        <inertia ixx="0.01" ixy="0" ixz="0" iyy="0.01" iyz="0" izz="0.01" />
      </inertial>
-->
    <visual>
      <origin rpy="0 0 0" xyz="0 0 0"/>
      <geometry>
        <mesh filename="package://schunk_description/meshes/lwa4p/arm_1_link.stl"/>
      </geometry>
      <material name="Schunk/Blue"/>
    </visual>
    <collision>
      <origin rpy="0 0 0" xyz="0 0 0"/>
      <geometry>
        <mesh filename="package://schunk_description/meshes/lwa4p/arm_1_link.stl"/>
      </geometry>
    </collision>
  </link>
  <!-- joint between arm_1_link and arm_2_link -->
  <joint name="arm_2_joint" type="revolute">
    <origin rpy="1.5708 0 0" xyz="0 0 0"/>
    <parent link="arm_1_link"/>
    <child link="arm_2_link"/>
    <axis xyz="0 0 1"/>
    <limit effort="370" lower="-2.94" upper="2.94" velocity="2.0"/>
    <!--safety_controller k_position="20" k_velocity="50" soft_lower_limit="${-2.09 + 0.01}" soft_upper_limit="${2.09 - 0.01}" /-->
  </joint>
  <link name="arm_2_link">
    <inertial>
      <mass value="0.01"/>
      <origin xyz="0 0 0"/>
      <inertia ixx="0.001" ixy="0.0" ixz="0.0" iyy="0.001" iyz="0.0" izz="0.001"/>
    </inertial>
    <!--
      <inertial>
        <origin xyz="0 0 0" rpy="0 0 0"/>
        <mass value="1.68311"/>
        <inertia ixx="0.03" ixy="0" ixz="0" iyy="0.03" iyz="0" izz="0.03" />
      </inertial>
-->
    <visual>
      <origin rpy="0 0 0" xyz="0 0 0"/>
      <geometry>
        <mesh filename="package://schunk_description/meshes/lwa4p/arm_2_link.stl"/>
      </geometry>
      <material name="Schunk/LightGrey"/>
    </visual>
    <collision>
      <origin rpy="0 0 0" xyz="0 0 0"/>
      <geometry>
        <mesh filename="package://schunk_description/meshes/lwa4p/arm_2_link.stl"/>
      </geometry>
    </collision>
  </link>
  <!-- joint between arm_2_link and arm_3_link -->
  <joint name="arm_3_joint" type="revolute">
    <origin rpy="0 3.14159 0" xyz="0 0.350 0"/>
    <parent link="arm_2_link"/>
    <child link="arm_3_link"/>
    <axis xyz="0 0 1"/>
    <limit effort="176" lower="-2.68" upper="2.68" velocity="2.0"/>
    <!--safety_controller k_position="20" k_velocity="25" soft_lower_limit="${-6.28 + 0.01}" soft_upper_limit="${6.28 - 0.01}" /-->
  </joint>
  <link name="arm_3_link">
    <inertial>
      <mass value="0.01"/>
      <origin xyz="0 0 0"/>
      <inertia ixx="0.001" ixy="0.0" ixz="0.0" iyy="0.001" iyz="0.0" izz="0.001"/>
    </inertial>
    <!--
      <inertial>
        <origin xyz="0 0 0" rpy="0 0 0"/>
        <mass value="2.1"/>
        <inertia ixx="0.03" ixy="0" ixz="0" iyy="0.03" iyz="0" izz="0.03" />
      </inertial>
-->
    <visual>
      <origin rpy="0 0 0" xyz="0 0 0"/>
      <geometry>
        <mesh filename="package://schunk_description/meshes/lwa4p/arm_3_link.stl"/>
      </geometry>
      <material name="Schunk/Blue"/>
    </visual>
    <collision>
      <origin rpy="0 0 0" xyz="0 0 0"/>
      <geometry>
        <mesh filename="package://schunk_description/meshes/lwa4p/arm_3_link.stl"/>
      </geometry>
    </collision>
  </link>
  <!-- joint between arm_3_link and arm_4_link -->
  <joint name="arm_4_joint" type="revolute">
    <origin rpy="-1.5708 3.14159 0" xyz="0 0 0"/>
    <parent link="arm_3_link"/>
    <child link="arm_4_link"/>
    <axis xyz="0 0 1"/>
    <limit effort="176" lower="-2.94" upper="2.94" velocity="2.0"/>
    <!--safety_controller k_position="20" k_velocity="25" soft_lower_limit="${-2.09 + 0.01}" soft_upper_limit="${2.09 - 0.01}" /-->
  </joint>
  <link name="arm_4_link">
    <inertial>
      <mass value="0.01"/>
      <origin xyz="0 0 0"/>
      <inertia ixx="0.001" ixy="0.0" ixz="0.0" iyy="0.001" iyz="0.0" izz="0.001"/>
    </inertial>
    <!--
      <inertial>
        <origin xyz="0 0 0" rpy="0 0 0"/>
        <mass value="1.68311"/>
        <inertia ixx="0.03" ixy="0" ixz="0" iyy="0.03" iyz="0" izz="0.03" />
      </inertial>
-->
    <visual>
      <origin rpy="0 0 0" xyz="0 0 0"/>
      <geometry>
        <mesh filename="package://schunk_description/meshes/lwa4p/arm_4_link.stl"/>
      </geometry>
      <material name="Schunk/LightGrey"/>
    </visual>
    <collision>
      <origin rpy="0 0 0" xyz="0 0 0"/>
      <geometry>
        <mesh filename="package://schunk_description/meshes/lwa4p/arm_4_link.stl"/>
      </geometry>
    </collision>
  </link>
  <!-- joint between arm_4_link and arm_5_link -->
  <joint name="arm_5_joint" type="revolute">
    <origin rpy="1.5708 0 3.14159" xyz="0 0.005263 0.305"/>
    <parent link="arm_4_link"/>
    <child link="arm_5_link"/>
    <axis xyz="0 0 1"/>
    <limit effort="41.6" lower="-2.94" upper="2.94" velocity="2.0"/>
    <!--safety_controller k_position="20" k_velocity="25" soft_lower_limit="${-6.28 + 0.01}" soft_upper_limit="${6.28 - 0.01}" /-->
  </joint>
  <link name="arm_5_link">
    <inertial>
      <mass value="0.01"/>
      <origin xyz="0 0 0"/>
      <inertia ixx="0.001" ixy="0.0" ixz="0.0" iyy="0.001" iyz="0.0" izz="0.001"/>
    </inertial>
    <!--
      <inertial>
        <origin xyz="0 0 0" rpy="0 0 0"/>
        <mass value="0.807"/>
        <inertia ixx="0.03" ixy="0" ixz="0" iyy="0.03" iyz="0" izz="0.03" />
      </inertial>
-->
    <visual>
      <origin rpy="0 0 0" xyz="0 0 0"/>
      <geometry>
        <mesh filename="package://schunk_description/meshes/lwa4p/arm_5_link.stl"/>
      </geometry>
      <material name="Schunk/Blue"/>
    </visual>
    <collision>
      <origin rpy="0 0 0" xyz="0 0 0"/>
      <geometry>
        <mesh filename="package://schunk_description/meshes/lwa4p/arm_5_link.stl"/>
      </geometry>
    </collision>
  </link>
  <!-- joint between arm_5_link and arm_6_link -->
  <joint name="arm_6_joint" type="revolute">
    <origin rpy="-1.5708 0 0" xyz="0 0 0"/>
    <parent link="arm_5_link"/>
    <child link="arm_6_link"/>
    <axis xyz="0 0 1"/>
    <limit effort="20.1" lower="-2.94" upper="2.94" velocity="2.0"/>
    <!--safety_controller k_position="20" k_velocity="25" soft_lower_limit="${-2.09 + 0.01}" soft_upper_limit="${2.09 - 0.01}" /-->
  </joint>
  <link name="arm_6_link">
    <inertial>
      <mass value="0.01"/>
      <origin xyz="0 0 0"/>
      <inertia ixx="0.001" ixy="0.0" ixz="0.0" iyy="0.001" iyz="0.0" izz="0.001"/>
    </inertial>
    <!--
      <inertial>
        <origin xyz="0 0 0" rpy="0 0 0"/>
        <mass value="0.819"/>
        <inertia ixx="0.01" ixy="0" ixz="0" iyy="0.01" iyz="0" izz="0.01" />
      </inertial>
-->
    <visual>
      <origin rpy="0 0 0" xyz="0 0 0"/>
      <geometry>
        <mesh filename="package://schunk_description/meshes/lwa4p/arm_6_link.stl"/>
      </geometry>
      <material name="Schunk/LightGrey"/>
    </visual>
    <collision>
      <origin rpy="0 0 0" xyz="0 0 0"/>
      <geometry>
        <mesh filename="package://schunk_description/meshes/lwa4p/arm_6_link.stl"/>
      </geometry>
    </collision>
  </link>
  <!-- extensions -->
  <gazebo reference="arm_0_link">
    <gravity>true</gravity>
    <self_collide>false</self_collide>
    <material value="Schunk/LightGrey"/>
  </gazebo>
  <gazebo reference="arm_1_link">
    <gravity>true</gravity>
    <self_collide>false</self_collide>
    <material value="Schunk/Blue"/>
  </gazebo>
  <gazebo reference="arm_2_link">
    <gravity>true</gravity>
    <self_collide>false</self_collide>
    <material value="Schunk/LightGrey"/>
  </gazebo>
  <gazebo reference="arm_3_link">
    <gravity>true</gravity>
    <self_collide>false</self_collide>
    <material value="Schunk/Blue"/>
  </gazebo>
  <gazebo reference="arm_4_link">
    <gravity>true</gravity>
    <self_collide>false</self_collide>
    <material value="Schunk/LightGrey"/>
  </gazebo>
  <gazebo reference="arm_5_link">
    <gravity>true</gravity>
    <self_collide>false</self_collide>
    <material value="Schunk/Blue"/>
  </gazebo>
  <gazebo reference="arm_6_link">
    <gravity>true</gravity>
    <self_collide>false</self_collide>
    <material value="Schunk/LightGrey"/>
  </gazebo>
  <transmission name="arm_1_trans">
    <type>transmission_interface/SimpleTransmission</type>
    <joint name="arm_1_joint">
      <hardwareInterface>PositionJointInterface</hardwareInterface>
      <hardwareInterface>VelocityJointInterface</hardwareInterface>
    </joint>
    <actuator name="arm_1_motor">
      <mechanicalReduction>1</mechanicalReduction>
    </actuator>
  </transmission>
  <transmission name="arm_2_trans">
    <type>transmission_interface/SimpleTransmission</type>
    <joint name="arm_2_joint">
      <hardwareInterface>PositionJointInterface</hardwareInterface>
      <hardwareInterface>VelocityJointInterface</hardwareInterface>
    </joint>
    <actuator name="arm_2_motor">
      <mechanicalReduction>1</mechanicalReduction>
    </actuator>
  </transmission>
  <transmission name="arm_3_trans">
    <type>transmission_interface/SimpleTransmission</type>
    <joint name="arm_3_joint">
      <hardwareInterface>PositionJointInterface</hardwareInterface>
      <hardwareInterface>VelocityJointInterface</hardwareInterface>
    </joint>
    <actuator name="arm_3_motor">
      <mechanicalReduction>1</mechanicalReduction>
    </actuator>
  </transmission>
  <transmission name="arm_4_trans">
    <type>transmission_interface/SimpleTransmission</type>
    <joint name="arm_4_joint">
      <hardwareInterface>PositionJointInterface</hardwareInterface>
      <hardwareInterface>VelocityJointInterface</hardwareInterface>
    </joint>
    <actuator name="arm_4_motor">
      <mechanicalReduction>1</mechanicalReduction>
    </actuator>
  </transmission>
  <transmission name="arm_5_trans">
    <type>transmission_interface/SimpleTransmission</type>
    <joint name="arm_5_joint">
      <hardwareInterface>PositionJointInterface</hardwareInterface>
      <hardwareInterface>VelocityJointInterface</hardwareInterface>
    </joint>
    <actuator name="arm_5_motor">
      <mechanicalReduction>1</mechanicalReduction>
    </actuator>
  </transmission>
  <transmission name="arm_6_trans">
    <type>transmission_interface/SimpleTransmission</type>
    <joint name="arm_6_joint">
      <hardwareInterface>PositionJointInterface</hardwareInterface>
      <hardwareInterface>VelocityJointInterface</hardwareInterface>
    </joint>
    <actuator name="arm_6_motor">
      <mechanicalReduction>1</mechanicalReduction>
    </actuator>
  </transmission>
  <joint name="pg70_palm_joint" type="fixed">
    <parent link="arm_6_link"/>
    <child link="pg70_palm_link"/>
    <origin rpy="0 0 0" xyz="0 0 0.075"/>
  </joint>
  <link name="pg70_palm_link">
    <inertial>
      <origin rpy="0 0 0" xyz="0 0 0"/>
      <mass value="1"/>
      <inertia ixx="0.01" ixy="0" ixz="0" iyy="0.01" iyz="0" izz="0.01"/>
    </inertial>
    <visual>
      <geometry>
        <mesh filename="package://schunk_description/meshes/pg70/pg70.dae"/>
      </geometry>
      <material name="blue">
        <color rgba="0 0 1 1"/>
      </material>
    </visual>
    <collision>
      <geometry>
        <mesh filename="package://schunk_description/meshes/pg70/pg70.dae"/>
      </geometry>
      <material name="blue">
        <color rgba="0 0 1 1"/>
      </material>
    </collision>
  </link>
  <joint name="pg70_finger_left_joint" type="prismatic">
    <parent link="pg70_palm_link"/>
    <child link="pg70_finger_left_link"/>
    <limit effort="100" lower="0.03" upper="0.114" velocity="2.0"/>
    <origin rpy="0 0 0" xyz="0 0 0.0789"/>
    <axis xyz="0 1 0"/>
  </joint>
  <link name="pg70_finger_left_link">
    <inertial>
      <origin rpy="0 0 0" xyz="0 0 0"/>
      <mass value="1"/>
      <inertia ixx="0.01" ixy="0" ixz="0" iyy="0.01" iyz="0" izz="0.01"/>
    </inertial>
    <visual>
      <geometry>
        <box size="0.03 0.01 0.01"/>
      </geometry>
      <material name="black">
        <color rgba="0 0 0 1"/>
      </material>
    </visual>
    <collision>
      <geometry>
        <box size="0.03 0.01 0.01"/>
      </geometry>
      <material name="black">
        <color rgba="0 0 0 1"/>
      </material>
    </collision>
  </link>
  <joint name="pg70_finger_right_joint" type="prismatic">
    <mimic joint="pg70_finger_left_joint" multiplier="1" offset="0"/>
    <parent link="pg70_palm_link"/>
    <child link="pg70_finger_right_link"/>
    <limit effort="100" lower="0.02" upper="1.14" velocity="2.0"/>
    <origin rpy="-0 0 0" xyz="0 0 0.0789"/>
    <axis xyz="0 -1 0"/>
  </joint>
  <link name="pg70_finger_right_link">
    <inertial>
      <origin rpy="0 0 0" xyz="0 0 0"/>
      <mass value="1"/>
      <inertia ixx="0.01" ixy="0" ixz="0" iyy="0.01" iyz="0" izz="0.01"/>
    </inertial>
    <visual>
      <geometry>
        <box size="0.03 0.01 0.01"/>
      </geometry>
      <material name="black">
        <color rgba="0 0 0 1"/>
      </material>
    </visual>
    <collision>
      <geometry>
        <box size="0.03 0.01 0.01"/>
      </geometry>
      <material name="black">
        <color rgba="0 0 0 1"/>
      </material>
    </collision>
  </link>
  <!-- extensions -->
  <gazebo reference="pg70_palm_link">
    <gravity>true</gravity>
    <self_collide>false</self_collide>
    <material>Schunk/LightGrey</material>
  </gazebo>
  <gazebo reference="pg70_finger_left_link">
    <gravity>true</gravity>
    <self_collide>false</self_collide>
    <material>Schunk/LightGrey</material>
  </gazebo>
  <gazebo reference="pg70_finger_right_link">
    <gravity>true</gravity>
    <self_collide>false</self_collide>
    <material>Schunk/LightGrey</material>
  </gazebo>
  <!-- finger1 -->
  <transmission name="pg70_finger_left_trans">
    <type>transmission_interface/SimpleTransmission</type>
    <joint name="pg70_finger_left_joint">
      <hardwareInterface>EffortJointInterface</hardwareInterface>
      <hardwareInterface>PositionJointInterface</hardwareInterface>
      <hardwareInterface>VelocityJointInterface</hardwareInterface>
    </joint>
    <actuator name="pg70_finger_left_motor">
      <mechanicalReduction>0.5</mechanicalReduction>
    </actuator>
  </transmission>
  <!-- finger2 - mimic -->
  <transmission name="pg70_finger_right_trans">
    <type>transmission_interface/SimpleTransmission</type>
    <joint name="pg70_finger_right_joint">
      <hardwareInterface>EffortJointInterface</hardwareInterface>
      <hardwareInterface>PositionJointInterface</hardwareInterface>
      <hardwareInterface>VelocityJointInterface</hardwareInterface>
    </joint>
    <actuator name="pg70_finger_right_motor">
      <mechanicalReduction>0.5</mechanicalReduction>
    </actuator>
  </transmission>
  <!-- gazebo_plugin for arm -->
  <gazebo>
    <plugin filename="libhwi_switch_gazebo_ros_control.so" name="ros_control">
      <robotNamespace>arm</robotNamespace>
      <filterJointsParam>joint_names</filterJointsParam>
    </plugin>
  </gazebo>
</robot>
