<?xml version="1.0" ?>
<!-- =================================================================================== -->
<!-- |    This document was autogenerated by xacro from C:\Users\tola\Anaconda3\envs\urdf_analyzer\Lib\site-packages\rtbdata\xacro\interbotix_descriptions\urdf\px150.urdf.xacro | -->
<!-- |    EDITING THIS FILE BY HAND IS NOT RECOMMENDED                                 | -->
<!-- =================================================================================== -->
<robot name="px150">
  <material name="interbotix_black">
    <texture filename="package://interbotix_descriptions/meshes/interbotix_black.png"/>
  </material>
  <link name="/base_link">
    <visual>
      <origin rpy="0 0 -1.5707963267948966" xyz="0 0 0"/>
      <geometry>
        <mesh filename="package://interbotix_descriptions/meshes/meshes_px150/PXA-150-M-1-Base.stl" scale="0.001 0.001 0.001"/>
      </geometry>
      <material name="interbotix_black"/>
    </visual>
    <collision>
      <origin rpy="0 0 -1.5707963267948966" xyz="0 0 0"/>
      <geometry>
        <mesh filename="package://interbotix_descriptions/meshes/meshes_px150/PXA-150-M-1-Base.stl" scale="0.001 0.001 0.001"/>
      </geometry>
    </collision>
    <inertial>
      <origin rpy="0 0 1.5707963267948966" xyz="-0.0354561000 -0.0033567000 0.0253423000"/>
      <mass value="0.766173"/>
      <inertia ixx="0.0033550000" ixy="-0.0001248000" ixz="0.0000110400" iyy="0.0013570000" iyz="0.0002101000" izz="0.0041120000"/>
    </inertial>
  </link>
  <joint name="waist" type="revolute">
    <axis xyz="0 0 1"/>
    <limit effort="100" lower="-3.141592653589793" upper="3.141592653589793" velocity="3.141592653589793"/>
    <origin rpy="0 0 0" xyz="0 0 0.065"/>
    <parent link="/base_link"/>
    <child link="/shoulder_link"/>
  </joint>
  <transmission name="trans_waist">
    <type>transmission_interface/SimpleTransmission</type>
    <joint name="waist">
      <hardwareInterface>hardware_interface/EffortJointInterface</hardwareInterface>
    </joint>
    <actuator name="waist_motor">
      <mechanicalReduction>1</mechanicalReduction>
    </actuator>
  </transmission>
  <link name="/shoulder_link">
    <visual>
      <origin rpy="0 0 -1.5707963267948966" xyz="0 0 0.0015"/>
      <geometry>
        <mesh filename="package://interbotix_descriptions/meshes/meshes_px150/PXA-150-M-2-Shoulder.stl" scale="0.001 0.001 0.001"/>
      </geometry>
      <material name="interbotix_black"/>
    </visual>
    <collision>
      <origin rpy="0 0 -1.5707963267948966" xyz="0 0 0.0015"/>
      <geometry>
        <mesh filename="package://interbotix_descriptions/meshes/meshes_px150/PXA-150-M-2-Shoulder.stl" scale="0.001 0.001 0.001"/>
      </geometry>
    </collision>
    <inertial>
      <origin rpy="0 0 1.5707963267948966" xyz="-0.0001000750 0.0000203624 0.0104104000"/>
      <mass value="0.287601"/>
      <inertia ixx="0.0002390000" ixy="0.0000000010" ixz="0.0000000348" iyy="0.0003634000" iyz="0.0000003613" izz="0.0004126000"/>
    </inertial>
  </link>
  <joint name="shoulder" type="revolute">
    <axis xyz="0 1 0"/>
    <limit effort="100" lower="-1.9373154697137058" upper="1.9373154697137058" velocity="3.141592653589793"/>
    <origin rpy="0 0 0" xyz="0 0 0.03891"/>
    <parent link="/shoulder_link"/>
    <child link="/upper_arm_link"/>
  </joint>
  <transmission name="trans_shoulder">
    <type>transmission_interface/SimpleTransmission</type>
    <joint name="shoulder">
      <hardwareInterface>hardware_interface/EffortJointInterface</hardwareInterface>
    </joint>
    <actuator name="shoulder_motor">
      <mechanicalReduction>1</mechanicalReduction>
    </actuator>
  </transmission>
  <link name="/upper_arm_link">
    <visual>
      <origin rpy="0 0 1.5707963267948966" xyz="0 0 0"/>
      <geometry>
        <mesh filename="package://interbotix_descriptions/meshes/meshes_px150/PXA-150-M-3-UA.stl" scale="0.001 0.001 0.001"/>
      </geometry>
      <material name="interbotix_black"/>
    </visual>
    <collision>
      <origin rpy="0 0 1.5707963267948966" xyz="0 0 0"/>
      <geometry>
        <mesh filename="package://interbotix_descriptions/meshes/meshes_px150/PXA-150-M-3-UA.stl" scale="0.001 0.001 0.001"/>
      </geometry>
    </collision>
    <inertial>
      <origin rpy="0 0 1.5707963267948966" xyz="0.0166098000 0.0000000279 0.1157350000"/>
      <mass value="0.338081"/>
      <inertia ixx="0.0010210000" ixy="-0.0000000001" ixz="0.0000000000" iyy="0.0011320000" iyz="0.0001839000" izz="0.0003525000"/>
    </inertial>
  </link>
  <joint name="elbow" type="revolute">
    <axis xyz="0 1 0"/>
    <limit effort="100" lower="-1.6580627893946132" upper="2.0943951023931953" velocity="3.141592653589793"/>
    <origin rpy="3.141592653589793 0 0" xyz="0.05 0 0.15"/>
    <parent link="/upper_arm_link"/>
    <child link="/forearm_link"/>
  </joint>
  <transmission name="trans_elbow">
    <type>transmission_interface/SimpleTransmission</type>
    <joint name="elbow">
      <hardwareInterface>hardware_interface/EffortJointInterface</hardwareInterface>
    </joint>
    <actuator name="elbow_motor">
      <mechanicalReduction>1</mechanicalReduction>
    </actuator>
  </transmission>
  <link name="/forearm_link">
    <visual>
      <origin rpy="0 0 1.5707963267948966" xyz="0 0 0"/>
      <geometry>
        <mesh filename="package://interbotix_descriptions/meshes/meshes_px150/PXA-150-M-4-Forearm.stl" scale="0.001 0.001 0.001"/>
      </geometry>
      <material name="interbotix_black"/>
    </visual>
    <collision>
      <origin rpy="0 0 1.5707963267948966" xyz="0 0 0"/>
      <geometry>
        <mesh filename="package://interbotix_descriptions/meshes/meshes_px150/PXA-150-M-4-Forearm.stl" scale="0.001 0.001 0.001"/>
      </geometry>
    </collision>
    <inertial>
      <origin rpy="0 0 1.5707963267948966" xyz="0.0848470000 -0.0001072261 0.0000000000"/>
      <mass value="0.226542"/>
      <inertia ixx="0.0005125000" ixy="-0.0000013403" ixz="0.0000000000" iyy="0.0000498800" iyz="0.0000000000" izz="0.0005207000"/>
    </inertial>
  </link>
  <joint name="wrist_angle" type="revolute">
    <axis xyz="0 1 0"/>
    <limit effort="100" lower="-2.1467549799530254" upper="1.7453292519943295" velocity="3.141592653589793"/>
    <origin rpy="0 0 0" xyz="0.15 0 0"/>
    <parent link="/forearm_link"/>
    <child link="/wrist_link"/>
  </joint>
  <transmission name="trans_wrist_angle">
    <type>transmission_interface/SimpleTransmission</type>
    <joint name="wrist_angle">
      <hardwareInterface>hardware_interface/EffortJointInterface</hardwareInterface>
    </joint>
    <actuator name="wrist_angle_motor">
      <mechanicalReduction>1</mechanicalReduction>
    </actuator>
  </transmission>
  <link name="/wrist_link">
    <visual>
      <origin rpy="0 3.141592653589793 1.5707963267948966" xyz="0 0 0"/>
      <geometry>
        <mesh filename="package://interbotix_descriptions/meshes/meshes_px150/PXA-150-M-5-Wrist.stl" scale="0.001 0.001 0.001"/>
      </geometry>
      <material name="interbotix_black"/>
    </visual>
    <collision>
      <origin rpy="0 3.141592653589793 1.5707963267948966" xyz="0 0 0"/>
      <geometry>
        <mesh filename="package://interbotix_descriptions/meshes/meshes_px150/PXA-150-M-5-Wrist.stl" scale="0.001 0.001 0.001"/>
      </geometry>
    </collision>
    <inertial>
      <origin rpy="0 3.141592653589793 1.5707963267948966" xyz="0.0423600000 0.0000104110 -0.0105770000"/>
      <mass value="0.084957"/>
      <inertia ixx="0.0000308200" ixy="0.0000000191" ixz="0.0000000023" iyy="0.0000282200" iyz="0.0000025481" izz="0.0000315200"/>
    </inertial>
  </link>
  <joint name="wrist_rotate" type="revolute">
    <axis xyz="1 0 0"/>
    <limit effort="100" lower="-3.141592653589793" upper="3.141592653589793" velocity="3.141592653589793"/>
    <origin rpy="-3.141592653589793 0 0" xyz="0.065 0 0"/>
    <parent link="/wrist_link"/>
    <child link="/gripper_link"/>
  </joint>
  <transmission name="trans_wrist_rotate">
    <type>transmission_interface/SimpleTransmission</type>
    <joint name="wrist_rotate">
      <hardwareInterface>hardware_interface/EffortJointInterface</hardwareInterface>
    </joint>
    <actuator name="wrist_rotate_motor">
      <mechanicalReduction>1</mechanicalReduction>
    </actuator>
  </transmission>
  <link name="/gripper_link">
    <visual>
      <origin rpy="0 0 1.5707963267948966" xyz="-0.02 0 0"/>
      <geometry>
        <mesh filename="package://interbotix_descriptions/meshes/meshes_px150/PXA-150-M-6-Gripper.stl" scale="0.001 0.001 0.001"/>
      </geometry>
      <material name="interbotix_black"/>
    </visual>
    <collision>
      <origin rpy="0 0 1.5707963267948966" xyz="-0.02 0 0"/>
      <geometry>
        <mesh filename="package://interbotix_descriptions/meshes/meshes_px150/PXA-150-M-6-Gripper.stl" scale="0.001 0.001 0.001"/>
      </geometry>
    </collision>
    <inertial>
      <origin rpy="0 0 1.5707963267948966" xyz="0.0216300000 0.0000000000 0.0114100000"/>
      <mass value="0.072885"/>
      <inertia ixx="0.0000253700" ixy="0.0000000000" ixz="0.0000000000" iyy="0.0000183600" iyz="0.0000004340" izz="0.0000167400"/>
    </inertial>
  </link>
  <joint name="ee_arm" type="fixed">
    <axis xyz="1 0 0"/>
    <origin rpy="0 0 0" xyz="0.043 0 0"/>
    <parent link="/gripper_link"/>
    <child link="/ee_arm_link"/>
  </joint>
  <link name="/ee_arm_link">
    <inertial>
      <mass value="0.001"/>
      <inertia ixx="0.0001" ixy="0" ixz="0" iyy="0.0001" iyz="0" izz="0.0001"/>
    </inertial>
  </link>
  <joint name="gripper" type="continuous">
    <axis xyz="1 0 0"/>
    <limit effort="100" velocity="3.141592653589793"/>
    <origin rpy="0 0 0" xyz="0.0055 0 0"/>
    <parent link="/ee_arm_link"/>
    <child link="/gripper_prop_link"/>
  </joint>
  <transmission name="trans_gripper">
    <type>transmission_interface/SimpleTransmission</type>
    <joint name="gripper">
      <hardwareInterface>hardware_interface/EffortJointInterface</hardwareInterface>
    </joint>
    <actuator name="gripper_motor">
      <mechanicalReduction>1</mechanicalReduction>
    </actuator>
  </transmission>
  <link name="/gripper_prop_link">
    <visual>
      <origin rpy="0 0 1.5707963267948966" xyz="-0.0685 0 0"/>
      <geometry>
        <mesh filename="package://interbotix_descriptions/meshes/meshes_px150/PXA-150-M-7-Gripper-Prop.stl" scale="0.001 0.001 0.001"/>
      </geometry>
      <material name="interbotix_black"/>
    </visual>
    <collision>
      <origin rpy="0 0 1.5707963267948966" xyz="-0.0685 0 0"/>
      <geometry>
        <mesh filename="package://interbotix_descriptions/meshes/meshes_px150/PXA-150-M-7-Gripper-Prop.stl" scale="0.001 0.001 0.001"/>
      </geometry>
    </collision>
    <inertial>
      <origin rpy="0 0 1.5707963267948966" xyz="0.0008460000 -0.0000019330 0.0000420000"/>
      <mass value="0.00434"/>
      <inertia ixx="0.0000005923" ixy="0.0000000000" ixz="0.0000003195" iyy="0.0000011156" iyz="-0.0000000004" izz="0.0000005743"/>
    </inertial>
  </link>
  <!-- If the default gripper bar is being used, then also add the gripper bar -->
  <joint name="gripper_bar" type="fixed">
    <axis xyz="1 0 0"/>
    <origin rpy="0 0 0" xyz="0 0 0"/>
    <parent link="/ee_arm_link"/>
    <child link="/gripper_bar_link"/>
  </joint>
  <link name="/gripper_bar_link">
    <visual>
      <origin rpy="0 0 1.5707963267948966" xyz="-0.063 0 0"/>
      <geometry>
        <mesh filename="package://interbotix_descriptions/meshes/meshes_px150/PXA-150-M-8-Gripper-Bar.stl" scale="0.001 0.001 0.001"/>
      </geometry>
      <material name="interbotix_black"/>
    </visual>
    <collision>
      <origin rpy="0 0 1.5707963267948966" xyz="-0.063 0 0"/>
      <geometry>
        <mesh filename="package://interbotix_descriptions/meshes/meshes_px150/PXA-150-M-8-Gripper-Bar.stl" scale="0.001 0.001 0.001"/>
      </geometry>
    </collision>
    <inertial>
      <origin rpy="0 0 1.5707963267948966" xyz="0.0096870000 0.0000005660 0.0049620000"/>
      <mass value="0.034199"/>
      <inertia ixx="0.0000074125" ixy="-0.0000000008" ixz="-0.0000000006" iyy="0.0000284300" iyz="-0.0000013889" izz="0.0000286000"/>
    </inertial>
  </link>
  <joint name="ee_bar" type="fixed">
    <axis xyz="1 0 0"/>
    <origin rpy="0 0 0" xyz="0.023 0 0"/>
    <parent link="/gripper_bar_link"/>
    <child link="/fingers_link"/>
  </joint>
  <link name="/fingers_link">
    <inertial>
      <mass value="0.001"/>
      <inertia ixx="0.0001" ixy="0" ixz="0" iyy="0.0001" iyz="0" izz="0.0001"/>
    </inertial>
  </link>
  <!-- If the default gripper fingers are being used, add those as well -->
  <joint name="left_finger" type="prismatic">
    <axis xyz="0 1 0"/>
    <limit effort="10" lower="0.015" upper="0.037" velocity="1"/>
    <origin rpy="0 0 0" xyz="0 0 0"/>
    <parent link="/fingers_link"/>
    <child link="/left_finger_link"/>
  </joint>
  <transmission name="trans_left_finger">
    <type>transmission_interface/SimpleTransmission</type>
    <joint name="left_finger">
      <hardwareInterface>hardware_interface/EffortJointInterface</hardwareInterface>
    </joint>
    <actuator name="left_finger_motor">
      <mechanicalReduction>1</mechanicalReduction>
    </actuator>
  </transmission>
  <link name="/left_finger_link">
    <visual>
      <origin rpy="3.141592653589793 3.141592653589793 0" xyz="0 0.005 0"/>
      <geometry>
        <mesh filename="package://interbotix_descriptions/meshes/meshes_px150/PXA-150-M-9-Finger.stl" scale="0.001 0.001 0.001"/>
      </geometry>
      <material name="interbotix_black"/>
    </visual>
    <collision>
      <origin rpy="3.141592653589793 3.141592653589793 0" xyz="0 0.005 0"/>
      <geometry>
        <mesh filename="package://interbotix_descriptions/meshes/meshes_px150/PXA-150-M-9-Finger.stl" scale="0.001 0.001 0.001"/>
      </geometry>
    </collision>
    <inertial>
      <origin rpy="3.141592653589793 3.141592653589793 1.5707963267948966" xyz="0.0138160000 0.0000000000 0.0000000000"/>
      <mass value="0.016246"/>
      <inertia ixx="0.0000047310" ixy="-0.0000004560" ixz="0.0000000000" iyy="0.0000015506" iyz="0.0000000000" izz="0.0000037467"/>
    </inertial>
  </link>
  <joint name="right_finger" type="prismatic">
    <axis xyz="0 1 0"/>
    <limit effort="10" lower="-0.037" upper="-0.015" velocity="1"/>
    <origin rpy="0 0 0" xyz="0 0 0"/>
    <parent link="/fingers_link"/>
    <child link="/right_finger_link"/>
    <mimic joint="left_finger" multiplier="-1" offset="0"/>
  </joint>
  <transmission name="trans_right_finger">
    <type>transmission_interface/SimpleTransmission</type>
    <joint name="right_finger">
      <hardwareInterface>hardware_interface/EffortJointInterface</hardwareInterface>
    </joint>
    <actuator name="right_finger_motor">
      <mechanicalReduction>1</mechanicalReduction>
    </actuator>
  </transmission>
  <link name="/right_finger_link">
    <visual>
      <origin rpy="0 3.141592653589793 0" xyz="0 -0.005 0"/>
      <geometry>
        <mesh filename="package://interbotix_descriptions/meshes/meshes_px150/PXA-150-M-9-Finger.stl" scale="0.001 0.001 0.001"/>
      </geometry>
      <material name="interbotix_black"/>
    </visual>
    <collision>
      <origin rpy="0 3.141592653589793 0" xyz="0 -0.005 0"/>
      <geometry>
        <mesh filename="package://interbotix_descriptions/meshes/meshes_px150/PXA-150-M-9-Finger.stl" scale="0.001 0.001 0.001"/>
      </geometry>
    </collision>
    <inertial>
      <origin rpy="0 3.141592653589793 1.5707963267948966" xyz="0.0138160000 0.0000000000  0.0000000000"/>
      <mass value="0.016246"/>
      <inertia ixx="0.0000047310" ixy="0.0000004560" ixz="0.0000000000" iyy="0.0000015506" iyz="0.0000000000" izz="0.0000037467"/>
    </inertial>
  </link>
  <joint name="ee_gripper" type="fixed">
    <axis xyz="1 0 0"/>
    <origin rpy="0 0 0" xyz="0.027575 0 0"/>
    <parent link="/fingers_link"/>
    <child link="/ee_gripper_link"/>
  </joint>
  <link name="/ee_gripper_link">
    <inertial>
      <mass value="0.001"/>
      <inertia ixx="0.0001" ixy="0" ixz="0" iyy="0.0001" iyz="0" izz="0.0001"/>
    </inertial>
  </link>
</robot>
