<?xml version="1.0" ?>
<!-- =================================================================================== -->
<!-- |    This document was autogenerated by xacro from example_end_effector.urdf.xacro | -->
<!-- |    EDITING THIS FILE BY HAND IS NOT RECOMMENDED                                 | -->
<!-- =================================================================================== -->
<robot name="left_electric_gripper">
  <!-- Base of end effector -->
  <link name="left_gripper_base">
    <visual>
      <origin rpy="-1.5707963267948966 3.141592653589793 0" xyz="0 0 0"/>
      <geometry>
        <mesh filename="package://rethink_ee_description/meshes/electric_gripper/electric_gripper_base.DAE"/>
      </geometry>
    </visual>
    <collision>
      <origin rpy="-1.5707963267948966 3.141592653589793 0" xyz="0.0 0.0 0"/>
      <geometry>
        <cylinder length="0.1" radius="0.029"/>
      </geometry>
      <material name="darkred">
        <color rgba=".5 .1 .1 1"/>
      </material>
    </collision>
    <inertial>
      <origin rpy="-1.5707963267948966 3.141592653589793 0" xyz="0.0 0.0 0.0"/>
      <mass value="0.3"/>
      <inertia ixx="2e-08" ixy="0" ixz="0" iyy="3e-08" iyz="0" izz="2e-08"/>
    </inertial>
  </link>
  <link name="l_gripper_l_finger">
    <visual>
      <origin rpy="0 0 -3.141592653589793" xyz="0 0 0"/>
      <geometry>
        <mesh filename="package://rethink_ee_description/meshes/electric_gripper/fingers/extended_narrow.DAE"/>
      </geometry>
    </visual>
    <collision>
      <origin rpy="0 0 -3.141592653589793" xyz="0 0.01725 0.0615"/>
      <geometry>
        <box size="0.01 0.0135 0.1127"/>
      </geometry>
    </collision>
    <collision>
      <origin rpy="0 0 -3.141592653589793" xyz="-0.005 -0.003 0.0083"/>
      <geometry>
        <box size="0.01 0.05 0.017"/>
      </geometry>
    </collision>
    <inertial>
      <origin rpy="0 0 -3.141592653589793" xyz="0 0 0"/>
      <mass value="0.02"/>
      <inertia ixx="0.01" ixy="0" ixz="0" iyy="0.01" iyz="0" izz="0.01"/>
    </inertial>
  </link>
  <gazebo reference="l_gripper_l_finger">
    <mu1>1000</mu1>
    <mu2>1000</mu2>
    <fdir1>0.0 0.0 1.0</fdir1>
    <kp>1e5</kp>
    <kd>1.0</kd>
  </gazebo>
  <link name="l_gripper_l_finger_tip">
    <visual>
      <origin rpy="0 0 3.141592653589793" xyz="0 0 0"/>
      <geometry>
        <mesh filename="package://rethink_ee_description/meshes/electric_gripper/fingers/paddle_tip.DAE"/>
      </geometry>
    </visual>
    <collision>
      <origin rpy="0 0 3.141592653589793" xyz="0 -0.0045 -0.015"/>
      <geometry>
        <box size="0.042 0.0065 0.037"/>
      </geometry>
    </collision>
    <inertial>
      <origin rpy="0 0 3.141592653589793" xyz="0 0 0"/>
      <mass value="0.01"/>
      <inertia ixx="0.01" ixy="0" ixz="0" iyy="0.01" iyz="0" izz="0.01"/>
    </inertial>
  </link>
  <joint name="l_gripper_l_finger_tip_joint" type="fixed">
    <origin rpy="0 0 0" xyz="0.0 0.01725 0.1127"/>
    <parent link="l_gripper_l_finger"/>
    <child link="l_gripper_l_finger_tip"/>
  </joint>
  <link name="l_gripper_r_finger">
    <visual>
      <origin rpy="0 0 -0.0" xyz="0 0 0"/>
      <geometry>
        <mesh filename="package://rethink_ee_description/meshes/electric_gripper/fingers/extended_narrow.DAE"/>
      </geometry>
    </visual>
    <collision>
      <origin rpy="0 0 -0.0" xyz="0 -0.01725 0.0615"/>
      <geometry>
        <box size="0.01 0.0135 0.1127"/>
      </geometry>
    </collision>
    <collision>
      <origin rpy="0 0 -0.0" xyz="0.005 0.003 0.0083"/>
      <geometry>
        <box size="0.01 0.05 0.017"/>
      </geometry>
    </collision>
    <inertial>
      <origin rpy="0 0 -0.0" xyz="0 0 0"/>
      <mass value="0.02"/>
      <inertia ixx="0.01" ixy="0" ixz="0" iyy="0.01" iyz="0" izz="0.01"/>
    </inertial>
  </link>
  <gazebo reference="l_gripper_r_finger">
    <mu1>1000</mu1>
    <mu2>1000</mu2>
    <fdir1>0.0 0.0 1.0</fdir1>
    <kp>1e5</kp>
    <kd>1.0</kd>
  </gazebo>
  <link name="l_gripper_r_finger_tip">
    <visual>
      <origin rpy="0 0 0.0" xyz="0 0 0"/>
      <geometry>
        <mesh filename="package://rethink_ee_description/meshes/electric_gripper/fingers/basic_hard_tip.DAE"/>
      </geometry>
    </visual>
    <collision>
      <origin rpy="0 0 0.0" xyz="0 0.0045 -0.015"/>
      <geometry>
        <box size="0.016 0.0065 0.037"/>
      </geometry>
    </collision>
    <inertial>
      <origin rpy="0 0 0.0" xyz="0 0 0"/>
      <mass value="0.01"/>
      <inertia ixx="0.01" ixy="0" ixz="0" iyy="0.01" iyz="0" izz="0.01"/>
    </inertial>
  </link>
  <joint name="l_gripper_r_finger_tip_joint" type="fixed">
    <origin rpy="0 0 0" xyz="0.0 -0.01725 0.1127"/>
    <parent link="l_gripper_r_finger"/>
    <child link="l_gripper_r_finger_tip"/>
  </joint>
  <!-- Electric Gripper Base Joint -->
  <joint name="left_gripper_base" type="fixed">
    <origin rpy="0 0 0" xyz="0 0 0.025"/>
    <parent link="left_hand"/>
    <child link="left_gripper_base"/>
  </joint>
  <!-- Electric Gripper Tip joint -->
  <joint name="left_endpoint" type="fixed">
    <origin rpy="0 0 0" xyz="0 0 0.13269999999999998"/>
    <parent link="left_gripper_base"/>
    <child link="left_gripper"/>
  </joint>
  <!-- Electric Gripper Tip link -->
  <link name="left_gripper">
    <inertial>
      <origin rpy="0 0 0" xyz="0 0 0"/>
      <mass value="0.0001"/>
      <inertia ixx="0" ixy="0" ixz="0" iyy="0" iyz="0" izz="0.0"/>
    </inertial>
  </link>
  <joint name="l_gripper_l_finger_joint" type="prismatic">
    <origin rpy="0 0 0" xyz="0.0 -0.0014999999999999996 0.02"/>
    <axis xyz="0 1 0"/>
    <parent link="left_gripper_base"/>
    <child link="l_gripper_l_finger"/>
    <limit effort="20.0" lower="0.0" upper="0.020833" velocity="5.0"/>
    <dynamics damping="0.7" friction="0.0"/>
  </joint>
  <joint name="l_gripper_r_finger_joint" type="prismatic">
    <origin rpy="0 0 0" xyz="0.0 0.0014999999999999996 0.02"/>
    <axis xyz="0 1 0"/>
    <parent link="left_gripper_base"/>
    <child link="l_gripper_r_finger"/>
    <limit effort="20.0" lower="-0.020833" upper="0.0" velocity="5.0"/>
    <mimic joint="l_gripper_l_finger_joint" multiplier="-1.0"/>
    <dynamics damping="0.7" friction="0.0"/>
  </joint>
  <transmission name="gripper_left1">
    <type>transmission_interface/SimpleTransmission</type>
    <joint name="l_gripper_r_finger_joint">
      <hardwareInterface>EffortJointInterface</hardwareInterface>
    </joint>
    <actuator name="gripper_l1_motor1">
      <hardwareInterface>EffortJointInterface</hardwareInterface>
      <mechanicalReduction>1</mechanicalReduction>
    </actuator>
  </transmission>
  <transmission name="gripper_left2">
    <type>transmission_interface/SimpleTransmission</type>
    <joint name="l_gripper_l_finger_joint">
      <hardwareInterface>EffortJointInterface</hardwareInterface>
    </joint>
    <actuator name="gripper_l1_motor2">
      <hardwareInterface>EffortJointInterface</hardwareInterface>
      <mechanicalReduction>1</mechanicalReduction>
    </actuator>
  </transmission>
  <gazebo reference="l_gripper_r_finger_joint">
    <implicitSpringDamper>1</implicitSpringDamper>
  </gazebo>
  <gazebo reference="l_gripper_l_finger_joint">
    <implicitSpringDamper>1</implicitSpringDamper>
  </gazebo>
</robot>

