<?xml version="1.0" ?>
<!-- =================================================================================== -->
<!-- |    This document was autogenerated by xacro from urdf/kr10r1420.xacro           | -->
<!-- |    EDITING THIS FILE BY HAND IS NOT RECOMMENDED                                 | -->
<!-- =================================================================================== -->
<robot name="kuka_kr10r1420">
  <!-- colours based on RAL values given in "FAQ - Colours of robot and robot
       controller", version "KUKA.Tifs | 2010-01-21 |YM| DefaultColorsRobotAndController.doc",
       downloaded 2015-07-18 from
       http://www.kuka.be/main/cservice/faqs/hardware/DefaultColorsRobotAndController.pdf

       all RAL colours converted using http://www.visual-graphics.de/en/customer-care/ral-colours
  -->
  <link name="base_link">
    <visual>
      <origin rpy="0 0 0" xyz="0 0 0"/>
      <geometry>
        <mesh filename="package://kuka_kr10_support/meshes/kr10r1420/visual/base_link.stl"/>
      </geometry>
      <material name="">
        <color rgba="0.054901960784313725 0.054901960784313725 0.06274509803921569 1.0"/>
      </material>
    </visual>
    <collision>
      <origin rpy="0 0 0" xyz="0 0 0"/>
      <geometry>
        <mesh filename="package://kuka_kr10_support/meshes/kr10r1420/collision/base_link.stl"/>
      </geometry>
    </collision>
  </link>
  <link name="link_1">
    <visual>
      <origin rpy="0 0 0" xyz="0 0 0"/>
      <geometry>
        <mesh filename="package://kuka_kr10_support/meshes/kr10r1420/visual/link_1.stl"/>
      </geometry>
      <material name="">
        <color rgba="0.9647058823529412 0.47058823529411764 0.1568627450980392 1.0"/>
      </material>
    </visual>
    <collision>
      <origin rpy="0 0 0" xyz="0 0 0"/>
      <geometry>
        <mesh filename="package://kuka_kr10_support/meshes/kr10r1420/collision/link_1.stl"/>
      </geometry>
    </collision>
  </link>
  <link name="link_2">
    <visual>
      <origin rpy="0 0 0" xyz="0 0 0"/>
      <geometry>
        <mesh filename="package://kuka_kr10_support/meshes/kr10r1420/visual/link_2.stl"/>
      </geometry>
      <material name="">
        <color rgba="0.9647058823529412 0.47058823529411764 0.1568627450980392 1.0"/>
      </material>
    </visual>
    <collision>
      <origin rpy="0 0 0" xyz="0 0 0"/>
      <geometry>
        <mesh filename="package://kuka_kr10_support/meshes/kr10r1420/collision/link_2.stl"/>
      </geometry>
    </collision>
  </link>
  <link name="link_3">
    <visual>
      <origin rpy="0 0 0" xyz="0 0 0"/>
      <geometry>
        <mesh filename="package://kuka_kr10_support/meshes/kr10r1420/visual/link_3.stl"/>
      </geometry>
      <material name="">
        <color rgba="0.9647058823529412 0.47058823529411764 0.1568627450980392 1.0"/>
      </material>
    </visual>
    <collision>
      <origin rpy="0 0 0" xyz="0 0 0"/>
      <geometry>
        <mesh filename="package://kuka_kr10_support/meshes/kr10r1420/collision/link_3.stl"/>
      </geometry>
    </collision>
  </link>
  <link name="link_4">
    <visual>
      <origin rpy="0 0 0" xyz="0 0 0"/>
      <geometry>
        <mesh filename="package://kuka_kr10_support/meshes/kr10r1420/visual/link_4.stl"/>
      </geometry>
      <material name="">
        <color rgba="0.9647058823529412 0.47058823529411764 0.1568627450980392 1.0"/>
      </material>
    </visual>
    <collision>
      <origin rpy="0 0 0" xyz="0 0 0"/>
      <geometry>
        <mesh filename="package://kuka_kr10_support/meshes/kr10r1420/collision/link_4.stl"/>
      </geometry>
    </collision>
  </link>
  <link name="link_5">
    <visual>
      <origin rpy="0 0 0" xyz="0 0 0"/>
      <geometry>
        <mesh filename="package://kuka_kr10_support/meshes/kr10r1420/visual/link_5.stl"/>
      </geometry>
      <material name="">
        <color rgba="0.9647058823529412 0.47058823529411764 0.1568627450980392 1.0"/>
      </material>
    </visual>
    <collision>
      <origin rpy="0 0 0" xyz="0 0 0"/>
      <geometry>
        <mesh filename="package://kuka_kr10_support/meshes/kr10r1420/collision/link_5.stl"/>
      </geometry>
    </collision>
  </link>
  <link name="link_6">
    <visual>
      <origin rpy="0 0 0" xyz="0 0 0"/>
      <geometry>
        <mesh filename="package://kuka_kr10_support/meshes/kr10r1420/visual/link_6.stl"/>
      </geometry>
      <material name="">
        <color rgba="0.5058823529411764 0.47058823529411764 0.38823529411764707 1.0"/>
      </material>
    </visual>
    <collision>
      <origin rpy="0 0 0" xyz="0 0 0"/>
      <geometry>
        <mesh filename="package://kuka_kr10_support/meshes/kr10r1420/collision/link_6.stl"/>
      </geometry>
    </collision>
  </link>
  <!-- Following REP199, this frame shall be use to attach EEF or other equipment -->
  <link name="flange"/>
  <joint name="joint_a1" type="revolute">
    <origin rpy="0 0 0" xyz="0 0 0.450"/>
    <parent link="base_link"/>
    <child link="link_1"/>
    <axis xyz="0 0 -1"/>
    <limit effort="0" lower="-2.9670597283903604" upper="2.9670597283903604" velocity="3.839724354387525"/>
  </joint>
  <joint name="joint_a2" type="revolute">
    <origin rpy="0 0 0" xyz="0.150 0 0"/>
    <parent link="link_1"/>
    <child link="link_2"/>
    <axis xyz="0 1 0"/>
    <limit effort="0" lower="-3.2288591161895095" upper="1.1344640137963142" velocity="3.6651914291880923"/>
  </joint>
  <joint name="joint_a3" type="revolute">
    <origin rpy="0 0 0" xyz="0.610 0 0"/>
    <parent link="link_2"/>
    <child link="link_3"/>
    <axis xyz="0 1 0"/>
    <limit effort="0" lower="-2.3911010752322315" upper="2.8448866807507573" velocity="4.71238898038469"/>
  </joint>
  <joint name="joint_a4" type="revolute">
    <origin rpy="0 0 0" xyz="0 0 0.02"/>
    <parent link="link_3"/>
    <child link="link_4"/>
    <axis xyz="-1 0 0"/>
    <limit effort="0" lower="-3.2288591161895095" upper="3.2288591161895095" velocity="6.649704450098396"/>
  </joint>
  <joint name="joint_a5" type="revolute">
    <origin rpy="0 0 0" xyz="0.660 0 0"/>
    <parent link="link_4"/>
    <child link="link_5"/>
    <axis xyz="0 1 0"/>
    <limit effort="0" lower="-2.0943951023931953" upper="2.0943951023931953" velocity="5.427973973702365"/>
  </joint>
  <joint name="joint_a6" type="revolute">
    <origin rpy="0 0 0" xyz="0.080 0 0"/>
    <parent link="link_5"/>
    <child link="link_6"/>
    <axis xyz="-1 0 0"/>
    <limit effort="0" lower="-6.1086523819801535" upper="6.1086523819801535" velocity="8.587019919812102"/>
  </joint>
  <joint name="joint_a6-flange" type="fixed">
    <parent link="link_6"/>
    <child link="flange"/>
    <origin rpy="0 0 0" xyz="0 0 0"/>
  </joint>
  <!-- ROS base_link to KUKA $ROBROOT coordinate system transform -->
  <link name="base"/>
  <joint name="base_link-base" type="fixed">
    <origin rpy="0 0 0" xyz="0 0 0"/>
    <parent link="base_link"/>
    <child link="base"/>
  </joint>
  <!-- This frame corresponds to the $TOOL coordinate system in KUKA KRC controllers -->
  <link name="tool0"/>
  <joint name="flange-tool0" type="fixed">
    <parent link="flange"/>
    <child link="tool0"/>
    <origin rpy="0 1.5707963267948966 0" xyz="0 0 0"/>
  </joint>
</robot>

