<?xml version="1.0" ?>
<!-- =================================================================================== -->
<!-- |    This document was autogenerated by xacro from urdf/robot.urdf.xacro          | -->
<!-- |    EDITING THIS FILE BY HAND IS NOT RECOMMENDED                                 | -->
<!-- =================================================================================== -->
<robot name="lwa4p">
  <material name="Schunk/LightGrey">
    <color rgba="0.7 0.7 0.7 1.0"/>
  </material>
  <material name="Schunk/DarkGrey">
    <color rgba="0.4 0.4 0.4 1.0"/>
  </material>
  <material name="Schunk/Black">
    <color rgba="0.0 0.0 0.0 1.0"/>
  </material>
  <material name="Schunk/DarkGolden">
    <color rgba="0.4 0.4 0.3 1.0"/>
  </material>
  <material name="Schunk/Blue">
    <color rgba="0.0 0.0 0.8 1.0"/>
  </material>
  <!-- Used for fixing robot to Gazebo -->
  <link name="world"/>
  <!-- joint between base_link and lwa4p_extended_connector_link -->
  <joint name="arm_podest_joint" type="fixed">
    <origin rpy="0 0 0" xyz="0 0 0.052"/>
    <parent link="world"/>
    <child link="arm_podest_link"/>
  </joint>
  <link name="arm_podest_link">
    <inertial>
      <mass value="0.01"/>
      <origin xyz="0 0 0"/>
      <inertia ixx="0.001" ixy="0.0" ixz="0.0" iyy="0.001" iyz="0.0" izz="0.001"/>
    </inertial>
    <visual>
      <origin rpy="0 3.141592653589793 0" xyz="0 0 0"/>
      <geometry>
        <mesh filename="package://schunk_description/meshes/lwa4p/arm_base_link.stl"/>
      </geometry>
    </visual>
    <collision>
      <origin rpy="0 3.141592653589793 0" xyz="0 0 0"/>
      <geometry>
        <mesh filename="package://schunk_description/meshes/lwa4p/arm_base_link.stl"/>
      </geometry>
    </collision>
  </link>
  <joint name="arm_base_joint" type="fixed">
    <origin rpy="0 0 0" xyz="0 0 0.10"/>
    <parent link="arm_podest_link"/>
    <child link="arm_base_link"/>
  </joint>
  <link name="arm_base_link">
    <inertial>
      <mass value="0.01"/>
      <origin xyz="0 0 0"/>
      <inertia ixx="0.001" ixy="0.0" ixz="0.0" iyy="0.001" iyz="0.0" izz="0.001"/>
    </inertial>
  </link>
  <!-- joint between arm_0_link and arm_1_link -->
  <joint name="arm_1_joint" type="revolute">
    <origin rpy="0 0 0" xyz="0 0 0"/>
    <parent link="arm_base_link"/>
    <child link="arm_1_link"/>
    <axis xyz="0 0 1"/>
    <limit effort="370" lower="-2.947" upper="2.947" velocity="1.26"/>
    <!--safety_controller k_position="20" k_velocity="50" soft_lower_limit="${-6.28 + 0.01}" soft_upper_limit="${6.28 - 0.01}" /-->
  </joint>
  <link name="arm_1_link">
    <inertial>
      <mass value="0.01"/>
      <origin xyz="0 0 0"/>
      <inertia ixx="0.001" ixy="0.0" ixz="0.0" iyy="0.001" iyz="0.0" izz="0.001"/>
    </inertial>
    <!--
      <inertial>
        <origin xyz="0 0 0" rpy="0 0 0" />
        <mass value="0.29364"/>
        <inertia ixx="0.01" ixy="0" ixz="0" iyy="0.01" iyz="0" izz="0.01" />
      </inertial>
-->
    <visual>
      <origin rpy="0 0 0" xyz="0 0 0"/>
      <geometry>
        <mesh filename="package://schunk_description/meshes/lwa4p/arm_1_link.stl"/>
      </geometry>
      <material name="Schunk/Blue"/>
    </visual>
    <collision>
      <origin rpy="0 0 0" xyz="0 0 0"/>
      <geometry>
        <mesh filename="package://schunk_description/meshes/lwa4p/arm_1_link.stl"/>
      </geometry>
    </collision>
  </link>
  <!-- joint between arm_1_link and arm_2_link -->
  <joint name="arm_2_joint" type="revolute">
    <origin rpy="1.5708 0 0" xyz="0 0 0"/>
    <parent link="arm_1_link"/>
    <child link="arm_2_link"/>
    <axis xyz="0 0 1"/>
    <limit effort="370" lower="-2.947" upper="2.947" velocity="1.26"/>
    <!--safety_controller k_position="20" k_velocity="50" soft_lower_limit="${-2.09 + 0.01}" soft_upper_limit="${2.09 - 0.01}" /-->
  </joint>
  <link name="arm_2_link">
    <inertial>
      <mass value="0.01"/>
      <origin xyz="0 0 0"/>
      <inertia ixx="0.001" ixy="0.0" ixz="0.0" iyy="0.001" iyz="0.0" izz="0.001"/>
    </inertial>
    <!--
      <inertial>
        <origin xyz="0 0 0" rpy="0 0 0"/>
        <mass value="1.68311"/>
        <inertia ixx="0.03" ixy="0" ixz="0" iyy="0.03" iyz="0" izz="0.03" />
      </inertial>
-->
    <visual>
      <origin rpy="0 0 0" xyz="0 0 0"/>
      <geometry>
        <mesh filename="package://schunk_description/meshes/lwa4p/arm_2_link.stl"/>
      </geometry>
      <material name="Schunk/LightGrey"/>
    </visual>
    <collision>
      <origin rpy="0 0 0" xyz="0 0 0"/>
      <geometry>
        <mesh filename="package://schunk_description/meshes/lwa4p/arm_2_link.stl"/>
      </geometry>
    </collision>
  </link>
  <!-- joint between arm_2_link and arm_3_link -->
  <joint name="arm_3_joint" type="revolute">
    <origin rpy="0 3.14159 0" xyz="0 0.350 0"/>
    <parent link="arm_2_link"/>
    <child link="arm_3_link"/>
    <axis xyz="0 0 1"/>
    <limit effort="176" lower="-2.694" upper="2.694" velocity="1.26"/>
    <!--safety_controller k_position="20" k_velocity="25" soft_lower_limit="${-6.28 + 0.01}" soft_upper_limit="${6.28 - 0.01}" /-->
  </joint>
  <link name="arm_3_link">
    <inertial>
      <mass value="0.01"/>
      <origin xyz="0 0 0"/>
      <inertia ixx="0.001" ixy="0.0" ixz="0.0" iyy="0.001" iyz="0.0" izz="0.001"/>
    </inertial>
    <!--
      <inertial>
        <origin xyz="0 0 0" rpy="0 0 0"/>
        <mass value="2.1"/>
        <inertia ixx="0.03" ixy="0" ixz="0" iyy="0.03" iyz="0" izz="0.03" />
      </inertial>
-->
    <visual>
      <origin rpy="0 0 0" xyz="0 0 0"/>
      <geometry>
        <mesh filename="package://schunk_description/meshes/lwa4p/arm_3_link.stl"/>
      </geometry>
      <material name="Schunk/Blue"/>
    </visual>
    <collision>
      <origin rpy="0 0 0" xyz="0 0 0"/>
      <geometry>
        <mesh filename="package://schunk_description/meshes/lwa4p/arm_3_link.stl"/>
      </geometry>
    </collision>
  </link>
  <!-- joint between arm_3_link and arm_4_link -->
  <joint name="arm_4_joint" type="revolute">
    <origin rpy="-1.5708 3.14159 0" xyz="0 0 0"/>
    <parent link="arm_3_link"/>
    <child link="arm_4_link"/>
    <axis xyz="0 0 1"/>
    <limit effort="176" lower="-2.947" upper="2.947" velocity="1.26"/>
    <!--safety_controller k_position="20" k_velocity="25" soft_lower_limit="${-2.09 + 0.01}" soft_upper_limit="${2.09 - 0.01}" /-->
  </joint>
  <link name="arm_4_link">
    <inertial>
      <mass value="0.01"/>
      <origin xyz="0 0 0"/>
      <inertia ixx="0.001" ixy="0.0" ixz="0.0" iyy="0.001" iyz="0.0" izz="0.001"/>
    </inertial>
    <!--
      <inertial>
        <origin xyz="0 0 0" rpy="0 0 0"/>
        <mass value="1.68311"/>
        <inertia ixx="0.03" ixy="0" ixz="0" iyy="0.03" iyz="0" izz="0.03" />
      </inertial>
-->
    <visual>
      <origin rpy="0 0 0" xyz="0 0 0"/>
      <geometry>
        <mesh filename="package://schunk_description/meshes/lwa4p/arm_4_link.stl"/>
      </geometry>
      <material name="Schunk/LightGrey"/>
    </visual>
    <collision>
      <origin rpy="0 0 0" xyz="0 0 0"/>
      <geometry>
        <mesh filename="package://schunk_description/meshes/lwa4p/arm_4_link.stl"/>
      </geometry>
    </collision>
  </link>
  <!-- joint between arm_4_link and arm_5_link -->
  <joint name="arm_5_joint" type="revolute">
    <origin rpy="1.5708 0 3.14159" xyz="0 0.005263 0.305"/>
    <parent link="arm_4_link"/>
    <child link="arm_5_link"/>
    <axis xyz="0 0 1"/>
    <limit effort="41.6" lower="-2.947" upper="2.947" velocity="1.26"/>
    <!--safety_controller k_position="20" k_velocity="25" soft_lower_limit="${-6.28 + 0.01}" soft_upper_limit="${6.28 - 0.01}" /-->
  </joint>
  <link name="arm_5_link">
    <inertial>
      <mass value="0.01"/>
      <origin xyz="0 0 0"/>
      <inertia ixx="0.001" ixy="0.0" ixz="0.0" iyy="0.001" iyz="0.0" izz="0.001"/>
    </inertial>
    <!--
      <inertial>
        <origin xyz="0 0 0" rpy="0 0 0"/>
        <mass value="0.807"/>
        <inertia ixx="0.03" ixy="0" ixz="0" iyy="0.03" iyz="0" izz="0.03" />
      </inertial>
-->
    <visual>
      <origin rpy="0 0 0" xyz="0 0 0"/>
      <geometry>
        <mesh filename="package://schunk_description/meshes/lwa4p/arm_5_link.stl"/>
      </geometry>
      <material name="Schunk/Blue"/>
    </visual>
    <collision>
      <origin rpy="0 0 0" xyz="0 0 0"/>
      <geometry>
        <mesh filename="package://schunk_description/meshes/lwa4p/arm_5_link.stl"/>
      </geometry>
    </collision>
  </link>
  <!-- joint between arm_5_link and arm_6_link -->
  <joint name="arm_6_joint" type="revolute">
    <origin rpy="-1.5708 0 0" xyz="0 0 0"/>
    <parent link="arm_5_link"/>
    <child link="arm_6_link"/>
    <axis xyz="0 0 1"/>
    <limit effort="20.1" lower="-2.947" upper="2.947" velocity="1.26"/>
    <!--safety_controller k_position="20" k_velocity="25" soft_lower_limit="${-2.09 + 0.01}" soft_upper_limit="${2.09 - 0.01}" /-->
  </joint>
  <link name="arm_6_link">
    <inertial>
      <mass value="0.01"/>
      <origin xyz="0 0 0"/>
      <inertia ixx="0.001" ixy="0.0" ixz="0.0" iyy="0.001" iyz="0.0" izz="0.001"/>
    </inertial>
    <!--
      <inertial>
        <origin xyz="0 0 0" rpy="0 0 0"/>
        <mass value="0.819"/>
        <inertia ixx="0.01" ixy="0" ixz="0" iyy="0.01" iyz="0" izz="0.01" />
      </inertial>
-->
    <visual>
      <origin rpy="0 0 0" xyz="0 0 0"/>
      <geometry>
        <mesh filename="package://schunk_description/meshes/lwa4p/arm_6_link.stl"/>
      </geometry>
      <material name="Schunk/LightGrey"/>
    </visual>
    <collision>
      <origin rpy="0 0 0" xyz="0 0 0"/>
      <geometry>
        <mesh filename="package://schunk_description/meshes/lwa4p/arm_6_link.stl"/>
      </geometry>
    </collision>
  </link>
  <gazebo reference="arm_0_link">
    <gravity>true</gravity>
    <self_collide>false</self_collide>
    <material value="Schunk/LightGrey"/>
  </gazebo>
  <gazebo reference="arm_1_link">
    <gravity>true</gravity>
    <self_collide>false</self_collide>
    <material value="Schunk/Blue"/>
  </gazebo>
  <gazebo reference="arm_2_link">
    <gravity>true</gravity>
    <self_collide>false</self_collide>
    <material value="Schunk/LightGrey"/>
  </gazebo>
  <gazebo reference="arm_3_link">
    <gravity>true</gravity>
    <self_collide>false</self_collide>
    <material value="Schunk/Blue"/>
  </gazebo>
  <gazebo reference="arm_4_link">
    <gravity>true</gravity>
    <self_collide>false</self_collide>
    <material value="Schunk/LightGrey"/>
  </gazebo>
  <gazebo reference="arm_5_link">
    <gravity>true</gravity>
    <self_collide>false</self_collide>
    <material value="Schunk/Blue"/>
  </gazebo>
  <gazebo reference="arm_6_link">
    <gravity>true</gravity>
    <self_collide>false</self_collide>
    <material value="Schunk/LightGrey"/>
  </gazebo>
  <transmission name="arm_1_trans">
    <type>transmission_interface/SimpleTransmission</type>
    <joint name="arm_1_joint">
      <hardwareInterface>hardware_interface/PositionJointInterface</hardwareInterface>
      <hardwareInterface>hardware_interface/VelocityJointInterface</hardwareInterface>
      <!--hardwareInterface>EffortJointInterface</hardwareInterface-->
    </joint>
    <actuator name="arm_1_motor">
      <mechanicalReduction>1</mechanicalReduction>
    </actuator>
  </transmission>
  <transmission name="arm_2_trans">
    <type>transmission_interface/SimpleTransmission</type>
    <joint name="arm_2_joint">
      <hardwareInterface>hardware_interface/PositionJointInterface</hardwareInterface>
      <hardwareInterface>hardware_interface/VelocityJointInterface</hardwareInterface>
      <!--hardwareInterface>EffortJointInterface</hardwareInterface-->
    </joint>
    <actuator name="arm_2_motor">
      <mechanicalReduction>1</mechanicalReduction>
    </actuator>
  </transmission>
  <transmission name="arm_3_trans">
    <type>transmission_interface/SimpleTransmission</type>
    <joint name="arm_3_joint">
      <hardwareInterface>hardware_interface/PositionJointInterface</hardwareInterface>
      <hardwareInterface>hardware_interface/VelocityJointInterface</hardwareInterface>
      <!--hardwareInterface>EffortJointInterface</hardwareInterface-->
    </joint>
    <actuator name="arm_3_motor">
      <mechanicalReduction>1</mechanicalReduction>
    </actuator>
  </transmission>
  <transmission name="arm_4_trans">
    <type>transmission_interface/SimpleTransmission</type>
    <joint name="arm_4_joint">
      <hardwareInterface>hardware_interface/PositionJointInterface</hardwareInterface>
      <hardwareInterface>hardware_interface/VelocityJointInterface</hardwareInterface>
      <!--hardwareInterface>EffortJointInterface</hardwareInterface-->
    </joint>
    <actuator name="arm_4_motor">
      <mechanicalReduction>1</mechanicalReduction>
    </actuator>
  </transmission>
  <transmission name="arm_5_trans">
    <type>transmission_interface/SimpleTransmission</type>
    <joint name="arm_5_joint">
      <hardwareInterface>hardware_interface/PositionJointInterface</hardwareInterface>
      <hardwareInterface>hardware_interface/VelocityJointInterface</hardwareInterface>
      <!--hardwareInterface>EffortJointInterface</hardwareInterface-->
    </joint>
    <actuator name="arm_5_motor">
      <mechanicalReduction>1</mechanicalReduction>
    </actuator>
  </transmission>
  <transmission name="arm_6_trans">
    <type>transmission_interface/SimpleTransmission</type>
    <joint name="arm_6_joint">
      <hardwareInterface>hardware_interface/PositionJointInterface</hardwareInterface>
      <hardwareInterface>hardware_interface/VelocityJointInterface</hardwareInterface>
      <!--hardwareInterface>EffortJointInterface</hardwareInterface-->
    </joint>
    <actuator name="arm_6_motor">
      <mechanicalReduction>1</mechanicalReduction>
    </actuator>
  </transmission>
  <!-- ros_control plugin -->
  <gazebo>
    <plugin filename="libhwi_switch_gazebo_ros_control.so" name="ros_control">
      <robotNamespace>arm</robotNamespace>
      <filterJointsParam>joint_names</filterJointsParam>
    </plugin>
  </gazebo>
</robot>

