<?xml version="1.0" ?>
<!-- =================================================================================== -->
<!-- |    This document was autogenerated by xacro from urdf/robot.urdf.xacro          | -->
<!-- |    EDITING THIS FILE BY HAND IS NOT RECOMMENDED                                 | -->
<!-- =================================================================================== -->
<robot name="pg70">
  <material name="Schunk/LightGrey">
    <color rgba="0.7 0.7 0.7 1.0"/>
  </material>
  <material name="Schunk/DarkGrey">
    <color rgba="0.4 0.4 0.4 1.0"/>
  </material>
  <material name="Schunk/Black">
    <color rgba="0.0 0.0 0.0 1.0"/>
  </material>
  <material name="Schunk/DarkGolden">
    <color rgba="0.4 0.4 0.3 1.0"/>
  </material>
  <material name="Schunk/Blue">
    <color rgba="0.0 0.0 0.8 1.0"/>
  </material>
  <!-- Used for fixing robot to Gazebo -->
  <link name="world"/>
  <joint name="pg70_podest_joint" type="fixed">
    <origin rpy="0 0 0" xyz="0 0 0.026"/>
    <parent link="world"/>
    <child link="pg70_podest_link"/>
  </joint>
  <link name="pg70_podest_link">
    <inertial>
      <mass value="0.01"/>
      <origin xyz="0 0 0"/>
      <inertia ixx="0.001" ixy="0.0" ixz="0.0" iyy="0.001" iyz="0.0" izz="0.001"/>
    </inertial>
    <visual>
      <origin rpy="0 3.141592653589793 0" xyz="0 0 0"/>
      <geometry>
        <mesh filename="package://schunk_description/meshes/lwa4p/arm_base_link.stl"/>
      </geometry>
    </visual>
    <collision>
      <origin rpy="0 3.141592653589793 0" xyz="0 0 0"/>
      <geometry>
        <mesh filename="package://schunk_description/meshes/lwa4p/arm_base_link.stl"/>
      </geometry>
    </collision>
  </link>
  <joint name="pg70_palm_joint" type="fixed">
    <origin rpy="0 0 0" xyz="0 0 0.10"/>
    <parent link="pg70_podest_link"/>
    <child link="pg70_palm_link"/>
  </joint>
  <link name="pg70_palm_link">
    <inertial>
      <origin rpy="0 0 0" xyz="0 0 0"/>
      <mass value="1"/>
      <inertia ixx="0.01" ixy="0" ixz="0" iyy="0.01" iyz="0" izz="0.01"/>
    </inertial>
    <visual>
      <geometry>
        <mesh filename="package://schunk_description/meshes/pg70/pg70.dae"/>
      </geometry>
    </visual>
    <collision>
      <origin rpy="0 0 0" xyz="0 0 0.03145"/>
      <geometry>
        <box size="0.082 0.114 0.080"/>
      </geometry>
    </collision>
  </link>
  <joint name="pg70_finger_left_joint" type="prismatic">
    <origin rpy="0 0 0" xyz="0 0.0055 0.0789"/>
    <parent link="pg70_palm_link"/>
    <child link="pg70_finger_left_link"/>
    <axis xyz="0 1 0"/>
    <limit effort="10" lower="-0.001" upper="0.0301" velocity="0.041"/>
  </joint>
  <link name="pg70_finger_left_link">
    <inertial>
      <origin rpy="0 0 0" xyz="0 0 0"/>
      <mass value="1"/>
      <inertia ixx="0.01" ixy="0" ixz="0" iyy="0.01" iyz="0" izz="0.01"/>
    </inertial>
    <visual>
      <geometry>
        <box size="0.03 0.01 0.01"/>
      </geometry>
      <material name="black">
        <color rgba="0 0 0 1"/>
      </material>
    </visual>
    <collision>
      <geometry>
        <box size="0.03 0.01 0.01"/>
      </geometry>
      <material name="black">
        <color rgba="0 0 0 1"/>
      </material>
    </collision>
  </link>
  <joint name="pg70_finger_right_joint" type="prismatic">
    <origin rpy="-0 0 0" xyz="0 -0.0055 0.0789"/>
    <parent link="pg70_palm_link"/>
    <child link="pg70_finger_right_link"/>
    <axis xyz="0 -1 0"/>
    <mimic joint="pg70_finger_left_joint" multiplier="1" offset="0"/>
    <limit effort="10" lower="-0.001" upper="0.0301" velocity="0.041"/>
  </joint>
  <link name="pg70_finger_right_link">
    <inertial>
      <origin rpy="0 0 0" xyz="0 0 0"/>
      <mass value="1"/>
      <inertia ixx="0.01" ixy="0" ixz="0" iyy="0.01" iyz="0" izz="0.01"/>
    </inertial>
    <visual>
      <geometry>
        <box size="0.03 0.01 0.01"/>
      </geometry>
      <material name="black">
        <color rgba="0 0 0 1"/>
      </material>
    </visual>
    <collision>
      <geometry>
        <box size="0.03 0.01 0.01"/>
      </geometry>
      <material name="black">
        <color rgba="0 0 0 1"/>
      </material>
    </collision>
  </link>
  <gazebo reference="pg70_palm_link">
    <gravity>true</gravity>
    <self_collide>false</self_collide>
  </gazebo>
  <gazebo reference="pg70_finger_left_link">
    <gravity>true</gravity>
    <self_collide>false</self_collide>
  </gazebo>
  <gazebo reference="pg70_finger_right_link">
    <gravity>true</gravity>
    <self_collide>false</self_collide>
  </gazebo>
  <transmission name="pg70_finger_left_trans">
    <type>transmission_interface/SimpleTransmission</type>
    <joint name="pg70_finger_left_joint">
      <hardwareInterface>hardware_interface/PositionJointInterface</hardwareInterface>
      <hardwareInterface>hardware_interface/VelocityJointInterface</hardwareInterface>
      <!--hardwareInterface>EffortJointInterface</hardwareInterface-->
    </joint>
    <actuator name="pg70_finger_left_motor">
      <mechanicalReduction>1</mechanicalReduction>
    </actuator>
  </transmission>
  <transmission name="pg70_finger_right_trans">
    <type>transmission_interface/SimpleTransmission</type>
    <joint name="pg70_finger_right_joint">
      <hardwareInterface>hardware_interface/PositionJointInterface</hardwareInterface>
      <hardwareInterface>hardware_interface/VelocityJointInterface</hardwareInterface>
      <!--hardwareInterface>EffortJointInterface</hardwareInterface-->
    </joint>
    <actuator name="pg70_finger_right_motor">
      <mechanicalReduction>1</mechanicalReduction>
    </actuator>
  </transmission>
  <!-- ros_control plugin -->
  <gazebo>
    <plugin filename="libhwi_switch_gazebo_ros_control.so" name="ros_control">
      <robotNamespace>pg70</robotNamespace>
      <filterJointsParam>joint_names</filterJointsParam>
    </plugin>
  </gazebo>
</robot>

