<?xml version="1.0" ?>
<!-- =================================================================================== -->
<!-- |    This document was autogenerated by xacro from urdf/robot.urdf.xacro          | -->
<!-- |    EDITING THIS FILE BY HAND IS NOT RECOMMENDED                                 | -->
<!-- =================================================================================== -->
<robot name="lwa4p_extended">
  <material name="Schunk/LightGrey">
    <color rgba="0.7 0.7 0.7 1.0"/>
  </material>
  <material name="Schunk/DarkGrey">
    <color rgba="0.4 0.4 0.4 1.0"/>
  </material>
  <material name="Schunk/Black">
    <color rgba="0.0 0.0 0.0 1.0"/>
  </material>
  <material name="Schunk/DarkGolden">
    <color rgba="0.4 0.4 0.3 1.0"/>
  </material>
  <material name="Schunk/Blue">
    <color rgba="0.0 0.0 0.8 1.0"/>
  </material>
  <!-- Used for fixing robot to Gazebo -->
  <link name="world"/>
  <!-- joint between base_link and lwa4p_extended_connector_link -->
  <joint name="arm_podest_joint" type="fixed">
    <origin rpy="0 0 0" xyz="0 0 0.026"/>
    <parent link="world"/>
    <child link="arm_podest_link"/>
  </joint>
  <link name="arm_podest_link">
    <inertial>
      <mass value="0.01"/>
      <origin xyz="0 0 0"/>
      <inertia ixx="0.001" ixy="0.0" ixz="0.0" iyy="0.001" iyz="0.0" izz="0.001"/>
    </inertial>
    <visual>
      <origin rpy="0 0 0" xyz="0 0 0"/>
      <geometry>
        <cylinder length="0.05" radius="0.03"/>
      </geometry>
    </visual>
    <collision>
      <origin rpy="0 0 0" xyz="0 0 0"/>
      <geometry>
        <cylinder length="0.05" radius="0.03"/>
      </geometry>
    </collision>
  </link>
  <joint name="arm_base_joint" type="fixed">
    <origin rpy="0 0 0" xyz="0 0 0.025"/>
    <parent link="arm_podest_link"/>
    <child link="arm_base_link"/>
  </joint>
  <!-- static part of PRL100 -->
  <link name="arm_base_link">
    <inertial>
      <mass value="0.01"/>
      <origin xyz="0 0 0"/>
      <inertia ixx="0.001" ixy="0.0" ixz="0.0" iyy="0.001" iyz="0.0" izz="0.001"/>
    </inertial>
    <!--
      <xacro:cylinder_inertial radius="0.056" length="0.12" mass="2.0">
        <origin xyz="0 0 ${0.12/2}" rpy="0 0 0" />
      </xacro:cylinder_inertial>
  -->
    <visual>
      <origin rpy="0 0 0" xyz="0 0 0"/>
      <geometry>
        <mesh filename="package://schunk_description/meshes/lwa4p_extended/arm_base_link.stl"/>
      </geometry>
    </visual>
    <collision>
      <origin rpy="0 0 0" xyz="0 0 0"/>
      <geometry>
        <mesh filename="package://schunk_description/meshes/lwa4p_extended/arm_base_link.stl"/>
      </geometry>
    </collision>
  </link>
  <!-- joint between arm_base_link and arm_1_link -->
  <joint name="arm_1_joint" type="revolute">
    <origin rpy="0 0 0" xyz="0 0 0.139"/>
    <parent link="arm_base_link"/>
    <child link="arm_1_link"/>
    <axis xyz="0 0 1"/>
    <dynamics damping="0" friction="0"/>
    <limit effort="81.5" lower="-4.69" upper="4.69" velocity="0.66"/>
    <!--Theoretical limit +/-270 , Real Limit +/- 270-->
    <!--safety_controller k_position="20" k_velocity="50" soft_lower_limit="${-M_PI + 0.01}" soft_upper_limit="${M_PI - 0.01}" /-->
  </joint>
  <!-- prl100 rotor + shoulder flansh -->
  <link name="arm_1_link">
    <inertial>
      <mass value="0.01"/>
      <origin xyz="0 0 0"/>
      <inertia ixx="0.001" ixy="0.0" ixz="0.0" iyy="0.001" iyz="0.0" izz="0.001"/>
    </inertial>
    <!--
      <inertial>
        <origin xyz="0.0 0.0662 0.0473" rpy="0 0 0"/>
        <mass value="0.8"/>
        <inertia ixx="0.002034" ixy="0.0" ixz="0.0" iyy="0.001437" iyz="0.000784" izz="0.00161" />
      </inertial>
-->
    <visual>
      <origin rpy="0 0 0" xyz="0 0 0"/>
      <geometry>
        <mesh filename="package://schunk_description/meshes/lwa4p_extended/arm_1_link.dae"/>
      </geometry>
    </visual>
    <collision>
      <origin rpy="0 0 0" xyz="0 0 0"/>
      <geometry>
        <mesh filename="package://schunk_description/meshes/lwa4p_extended/arm_1_collision.stl"/>
      </geometry>
    </collision>
  </link>
  <!-- joint between arm_1_link and arm_2_link -->
  <joint name="arm_2_joint" type="revolute">
    <origin rpy="1.5707963267948966 0 0" xyz="0 0 0.0915"/>
    <parent link="arm_1_link"/>
    <child link="arm_2_link"/>
    <axis xyz="0 0 1"/>
    <dynamics damping="0" friction="0"/>
    <limit effort="48" lower="-1.89" upper="1.89" velocity="1.57"/>
    <!--Theoretical limit +/-170 , Real Limit +/- 110 (self collision)-->
    <!--safety_controller k_position="20" k_velocity="50" soft_lower_limit="${-2.0943 + 0.01}" soft_upper_limit="${2.0943 - 0.01}" /-->
  </joint>
  <link name="arm_2_link">
    <inertial>
      <mass value="0.01"/>
      <origin xyz="0 0 0"/>
      <inertia ixx="0.001" ixy="0.0" ixz="0.0" iyy="0.001" iyz="0.0" izz="0.001"/>
    </inertial>
    <!--
      <inertial>
        <origin xyz="0 0.018 -0.018" rpy="0 0 0"/>
        <mass value="3.9"/>
        <inertia ixx="0.009780" ixy="0.0" ixz="0.0" iyy="0.013300" iyz="0.0" izz="0.009780" />
      </inertial>
-->
    <visual>
      <origin rpy="0 0 0" xyz="0 0 0"/>
      <geometry>
        <mesh filename="package://schunk_description/meshes/lwa4p_extended/arm_2_link.dae"/>
      </geometry>
    </visual>
    <collision>
      <origin rpy="0 0 0" xyz="0 0 0"/>
      <geometry>
        <mesh filename="package://schunk_description/meshes/lwa4p_extended/arm_2_collision.stl"/>
      </geometry>
    </collision>
  </link>
  <!-- joint between arm_2_link and arm_3_link -->
  <joint name="arm_3_joint" type="revolute">
    <origin rpy="-1.5707963267948966 0 0" xyz="0 0 0"/>
    <parent link="arm_2_link"/>
    <child link="arm_3_link"/>
    <axis xyz="0 0 1"/>
    <dynamics damping="0" friction="0"/>
    <limit effort="48" lower="-2.94" upper="2.94" velocity="1.57"/>
    <!--Theoretical limit +/-170 , Real Limit +/- 170-->
    <!--safety_controller k_position="20" k_velocity="25" soft_lower_limit="${-M_PI + 0.01}" soft_upper_limit="${M_PI - 0.01}" /-->
  </joint>
  <link name="arm_3_link">
    <inertial>
      <mass value="0.01"/>
      <origin xyz="0 0 0"/>
      <inertia ixx="0.001" ixy="0.0" ixz="0.0" iyy="0.001" iyz="0.0" izz="0.001"/>
    </inertial>
    <!--
      <inertial>
        <origin xyz="0.0 0.06247 0.23425" rpy="0 0 0"/>
        <mass value="1.94533"/>
        <inertia ixx="0.0344" ixy="0.0" ixz="0.0077" iyy="0.0362" iyz="0.0" izz="0.0052" />
      </inertial>
-->
    <visual>
      <origin rpy="0 0 0" xyz="0 0 0"/>
      <geometry>
        <mesh filename="package://schunk_description/meshes/lwa4p_extended/arm_3_link.dae"/>
      </geometry>
    </visual>
    <collision>
      <origin rpy="0 0 0" xyz="0 0 0"/>
      <geometry>
        <mesh filename="package://schunk_description/meshes/lwa4p_extended/arm_3_collision.stl"/>
      </geometry>
    </collision>
  </link>
  <!-- joint between arm_3_link and arm_4_link -->
  <joint name="arm_4_joint" type="revolute">
    <origin rpy="1.5707963267948966 0 0" xyz="0 0 0.45360"/>
    <parent link="arm_3_link"/>
    <child link="arm_4_link"/>
    <axis xyz="0 0 1"/>
    <dynamics damping="0" friction="0"/>
    <limit effort="48" lower="-2.59" upper="2.59" velocity="1.57"/>
    <!--Theoretical limit +/-170 , Real Limit +/- 150 (self collision)-->
    <!--safety_controller k_position="20" k_velocity="25" soft_lower_limit="${-2.0943951 + 0.01}" soft_upper_limit="${2.0943951 - 0.01}" /-->
  </joint>
  <link name="arm_4_link">
    <inertial>
      <mass value="0.01"/>
      <origin xyz="0 0 0"/>
      <inertia ixx="0.001" ixy="0.0" ixz="0.0" iyy="0.001" iyz="0.0" izz="0.001"/>
    </inertial>
    <!--
      <inertial>
        <origin xyz="0 0.018 -0.018" rpy="0 0 0"/>
        <mass value="3.9"/>
        <inertia ixx="0.009780" ixy="0.0" ixz="0.0" iyy="0.013300" iyz="0.0" izz="0.009780" />
      </inertial>
-->
    <visual>
      <origin rpy="0 0 0" xyz="0 0 0"/>
      <geometry>
        <mesh filename="package://schunk_description/meshes/lwa4p_extended/arm_4_link.dae"/>
      </geometry>
    </visual>
    <collision>
      <origin rpy="0 0 0" xyz="0 0 0"/>
      <geometry>
        <mesh filename="package://schunk_description/meshes/lwa4p_extended/arm_4_collision.stl"/>
      </geometry>
    </collision>
  </link>
  <!-- joint between arm_4_link and arm_5_link -->
  <joint name="arm_5_joint" type="revolute">
    <origin rpy="-1.5707963267948966 0 0" xyz="0 0 0"/>
    <parent link="arm_4_link"/>
    <child link="arm_5_link"/>
    <axis xyz="0 0 1"/>
    <dynamics damping="0" friction="0"/>
    <limit effort="48" lower="-2.94" upper="2.94" velocity="1.57"/>
    <!--Theoretical limit +/-170 , Real Limit +/- 170-->
    <!--safety_controller k_position="20" k_velocity="25" soft_lower_limit="${-M_PI + 0.01}" soft_upper_limit="${M_PI - 0.01}" /-->
  </joint>
  <link name="arm_5_link">
    <inertial>
      <mass value="0.01"/>
      <origin xyz="0 0 0"/>
      <inertia ixx="0.001" ixy="0.0" ixz="0.0" iyy="0.001" iyz="0.0" izz="0.001"/>
    </inertial>
    <!--
      <inertial>
        <origin xyz="0.0 0.04175 0.17026" rpy="0 0 0"/>
        <mass value="1.3297"/>
        <inertia ixx="0.01" ixy="0.0" ixz="-0.0031" iyy="0.0111" iyz="0.0" izz="0.0031" />
      </inertial>
-->
    <visual>
      <origin rpy="0 0 0" xyz="0 0 0"/>
      <geometry>
        <mesh filename="package://schunk_description/meshes/lwa4p_extended/arm_5_link.dae"/>
      </geometry>
    </visual>
    <collision>
      <origin rpy="0 0 0" xyz="0 0 0"/>
      <geometry>
        <mesh filename="package://schunk_description/meshes/lwa4p_extended/arm_5_collision.stl"/>
      </geometry>
    </collision>
  </link>
  <!-- joint between arm_5_link and arm_6_link -->
  <joint name="arm_6_joint" type="revolute">
    <origin rpy="1.5707963267948966 0 0" xyz="0 0 0.2986"/>
    <parent link="arm_5_link"/>
    <child link="arm_6_link"/>
    <axis xyz="0 0 1"/>
    <dynamics damping="0" friction="0"/>
    <limit effort="15" lower="-2.94" upper="2.94" velocity="2.09"/>
    <!--Theoretical limit +/-170 , Real Limit -140/+170 (self collision)-->
    <!--safety_controller k_position="20" k_velocity="25" soft_lower_limit="${-2.0943951 + 0.01}" soft_upper_limit="${2.0943951 - 0.01}" /-->
  </joint>
  <link name="arm_6_link">
    <inertial>
      <mass value="0.01"/>
      <origin xyz="0 0 0"/>
      <inertia ixx="0.001" ixy="0.0" ixz="0.0" iyy="0.001" iyz="0.0" izz="0.001"/>
    </inertial>
    <!--
      <inertial>
        <origin xyz="0 0.012 -0.012" rpy="0 0 0"/>
        <mass value="1.9"/>
        <inertia ixx="0.002750" ixy="0.0" ixz="0.0" iyy="0.004002" iyz="0.0" izz="0.002830" />
      </inertial>
-->
    <visual>
      <origin rpy="0 0 0" xyz="0 0 0"/>
      <geometry>
        <mesh filename="package://schunk_description/meshes/lwa4p_extended/arm_6_link.dae"/>
      </geometry>
    </visual>
    <collision>
      <origin rpy="0 0 0" xyz="0 0 0"/>
      <geometry>
        <mesh filename="package://schunk_description/meshes/lwa4p_extended/arm_6_collision.stl"/>
      </geometry>
    </collision>
  </link>
  <!-- joint between arm_6_link and arm_7_link -->
  <joint name="arm_7_joint" type="revolute">
    <origin rpy="-1.5707963267948966 0 0" xyz="0 0 0"/>
    <parent link="arm_6_link"/>
    <child link="arm_7_link"/>
    <axis xyz="0 0 1"/>
    <dynamics damping="0" friction="0"/>
    <limit effort="15" lower="-3.73" upper="2.16" velocity="2.09"/>
    <!--Theoretical limit +127/-215 , Real Limit +127/-215-->
    <!--safety_controller k_position="20" k_velocity="25" soft_lower_limit="${-2.0943951 + 0.01}" soft_upper_limit="${2.0943951 - 0.01}" /-->
  </joint>
  <link name="arm_7_link">
    <inertial>
      <mass value="0.01"/>
      <origin xyz="0 0 0"/>
      <inertia ixx="0.001" ixy="0.0" ixz="0.0" iyy="0.001" iyz="0.0" izz="0.001"/>
    </inertial>
    <!--
      <xacro:cylinder_inertial radius="0.03" length="0.035" mass="0.05">
        <origin xyz="0 0 0.06" rpy="0 0 0"/>
      </xacro:cylinder_inertial>
-->
    <visual>
      <origin rpy="0 0 0" xyz="0 0 0.06"/>
      <geometry>
        <cylinder length="0.035" radius="0.03"/>
      </geometry>
      <material name="Schunk/LightGrey"/>
    </visual>
    <collision>
      <origin rpy="0 0 0" xyz="0 0 0.06"/>
      <geometry>
        <cylinder length="0.035" radius="0.03"/>
      </geometry>
    </collision>
  </link>
  <!--
    <gazebo reference="${name}_base_link">
      <gravity>true</gravity>
      <self_collide>false</self_collide>
    </gazebo>

    <gazebo reference="${name}_1_link">
      <gravity>true</gravity>
      <self_collide>false</self_collide>
    </gazebo>

    <gazebo reference="${name}_2_link">
      <gravity>true</gravity>
      <self_collide>false</self_collide>
    </gazebo>

    <gazebo reference="${name}_3_link">
      <gravity>true</gravity>
      <self_collide>false</self_collide>
    </gazebo>

    <gazebo reference="${name}_4_link">
      <gravity>true</gravity>
      <self_collide>false</self_collide>
    </gazebo>

    <gazebo reference="${name}_5_link">
      <gravity>true</gravity>
      <self_collide>false</self_collide>
    </gazebo>

    <gazebo reference="${name}_6_link">
      <gravity>true</gravity>
      <self_collide>false</self_collide>
    </gazebo>

    <gazebo reference="${name}_7_link">
      <gravity>true</gravity>
      <self_collide>false</self_collide>
      <material value="Schunk/LightGrey" />
    </gazebo>
-->
  <transmission name="arm_1_trans">
    <type>transmission_interface/SimpleTransmission</type>
    <joint name="arm_1_joint">
      <hardwareInterface>hardware_interface/PositionJointInterface</hardwareInterface>
      <hardwareInterface>hardware_interface/VelocityJointInterface</hardwareInterface>
      <!--hardwareInterface>EffortJointInterface</hardwareInterface-->
    </joint>
    <actuator name="arm_1_motor">
      <mechanicalReduction>1</mechanicalReduction>
    </actuator>
  </transmission>
  <transmission name="arm_2_trans">
    <type>transmission_interface/SimpleTransmission</type>
    <joint name="arm_2_joint">
      <hardwareInterface>hardware_interface/PositionJointInterface</hardwareInterface>
      <hardwareInterface>hardware_interface/VelocityJointInterface</hardwareInterface>
      <!--hardwareInterface>EffortJointInterface</hardwareInterface-->
    </joint>
    <actuator name="arm_2_motor">
      <mechanicalReduction>1</mechanicalReduction>
    </actuator>
  </transmission>
  <transmission name="arm_3_trans">
    <type>transmission_interface/SimpleTransmission</type>
    <joint name="arm_3_joint">
      <hardwareInterface>hardware_interface/PositionJointInterface</hardwareInterface>
      <hardwareInterface>hardware_interface/VelocityJointInterface</hardwareInterface>
      <!--hardwareInterface>EffortJointInterface</hardwareInterface-->
    </joint>
    <actuator name="arm_3_motor">
      <mechanicalReduction>1</mechanicalReduction>
    </actuator>
  </transmission>
  <transmission name="arm_4_trans">
    <type>transmission_interface/SimpleTransmission</type>
    <joint name="arm_4_joint">
      <hardwareInterface>hardware_interface/PositionJointInterface</hardwareInterface>
      <hardwareInterface>hardware_interface/VelocityJointInterface</hardwareInterface>
      <!--hardwareInterface>EffortJointInterface</hardwareInterface-->
    </joint>
    <actuator name="arm_4_motor">
      <mechanicalReduction>1</mechanicalReduction>
    </actuator>
  </transmission>
  <transmission name="arm_5_trans">
    <type>transmission_interface/SimpleTransmission</type>
    <joint name="arm_5_joint">
      <hardwareInterface>hardware_interface/PositionJointInterface</hardwareInterface>
      <hardwareInterface>hardware_interface/VelocityJointInterface</hardwareInterface>
      <!--hardwareInterface>EffortJointInterface</hardwareInterface-->
    </joint>
    <actuator name="arm_5_motor">
      <mechanicalReduction>1</mechanicalReduction>
    </actuator>
  </transmission>
  <transmission name="arm_6_trans">
    <type>transmission_interface/SimpleTransmission</type>
    <joint name="arm_6_joint">
      <hardwareInterface>hardware_interface/PositionJointInterface</hardwareInterface>
      <hardwareInterface>hardware_interface/VelocityJointInterface</hardwareInterface>
      <!--hardwareInterface>EffortJointInterface</hardwareInterface-->
    </joint>
    <actuator name="arm_6_motor">
      <mechanicalReduction>1</mechanicalReduction>
    </actuator>
  </transmission>
  <transmission name="arm_7_trans">
    <type>transmission_interface/SimpleTransmission</type>
    <joint name="arm_7_joint">
      <hardwareInterface>hardware_interface/PositionJointInterface</hardwareInterface>
      <hardwareInterface>hardware_interface/VelocityJointInterface</hardwareInterface>
      <!--hardwareInterface>EffortJointInterface</hardwareInterface-->
    </joint>
    <actuator name="arm_7_motor">
      <mechanicalReduction>1</mechanicalReduction>
    </actuator>
  </transmission>
  <!-- ros_control plugin -->
  <gazebo>
    <plugin filename="libhwi_switch_gazebo_ros_control.so" name="ros_control">
      <robotNamespace>arm</robotNamespace>
      <filterJointsParam>joint_names</filterJointsParam>
    </plugin>
  </gazebo>
</robot>

