<?xml version="1.0" ?>
<!-- =================================================================================== -->
<!-- |    This document was autogenerated by xacro from urdf/robot.urdf.xacro          | -->
<!-- |    EDITING THIS FILE BY HAND IS NOT RECOMMENDED                                 | -->
<!-- =================================================================================== -->
<robot name="pw70">
  <material name="Schunk/LightGrey">
    <color rgba="0.7 0.7 0.7 1.0"/>
  </material>
  <material name="Schunk/DarkGrey">
    <color rgba="0.4 0.4 0.4 1.0"/>
  </material>
  <material name="Schunk/Black">
    <color rgba="0.0 0.0 0.0 1.0"/>
  </material>
  <material name="Schunk/DarkGolden">
    <color rgba="0.4 0.4 0.3 1.0"/>
  </material>
  <material name="Schunk/Blue">
    <color rgba="0.0 0.0 0.8 1.0"/>
  </material>
  <!-- Used for fixing robot to Gazebo -->
  <link name="world"/>
  <joint name="pw70_joint" type="fixed">
    <origin rpy="0 0 0" xyz="0 0 0.026"/>
    <parent link="world"/>
    <child link="pw70_link"/>
  </joint>
  <link name="pw70_link">
    <inertial>
      <mass value="0.01"/>
      <origin xyz="0 0 0"/>
      <inertia ixx="0.001" ixy="0.0" ixz="0.0" iyy="0.001" iyz="0.0" izz="0.001"/>
    </inertial>
    <visual>
      <origin rpy="3.141592653589793 0 0" xyz="0 0 0.095"/>
      <geometry>
        <mesh filename="package://schunk_description/meshes/pw70/pw70_round_holder.stl"/>
      </geometry>
    </visual>
    <collision>
      <geometry>
        <mesh filename="package://schunk_description/meshes/pw70/pw70_round_holder.stl"/>
      </geometry>
    </collision>
  </link>
  <joint name="pw70_pan_joint" type="revolute">
    <origin rpy="0 0 0" xyz="0 0 0.095"/>
    <parent link="pw70_link"/>
    <child link="pw70_pan_link"/>
    <axis xyz="0 0 -1"/>
    <limit effort="200" lower="-7.3303828583761845" upper="7.3303828583761845" velocity="6.283185307179586"/>
    <calibration rising="0.0"/>
  </joint>
  <link name="pw70_pan_link">
    <inertial>
      <mass value="0.01"/>
      <origin xyz="0 0 0"/>
      <inertia ixx="0.001" ixy="0.0" ixz="0.0" iyy="0.001" iyz="0.0" izz="0.001"/>
    </inertial>
    <visual>
      <origin rpy="3.141592653589793 0 0" xyz="0 0 0"/>
      <geometry>
        <mesh filename="package://schunk_description/meshes/pw70/pw70_body.stl"/>
      </geometry>
    </visual>
    <collision>
      <geometry>
        <mesh filename="package://schunk_description/meshes/pw70/pw70_body.stl"/>
      </geometry>
    </collision>
  </link>
  <joint name="pw70_tilt_joint" type="revolute">
    <origin rpy="0 0 0" xyz="0 0 0"/>
    <parent link="pw70_pan_link"/>
    <child link="pw70_tilt_link"/>
    <axis xyz="-1 0 0"/>
    <limit effort="12.0" lower="-2.0943951023931953" upper="2.0943951023931953" velocity="4.1"/>
    <calibration rising="0.0"/>
  </joint>
  <link name="pw70_tilt_link">
    <inertial>
      <mass value="0.01"/>
      <origin xyz="0 0 0"/>
      <inertia ixx="0.001" ixy="0.0" ixz="0.0" iyy="0.001" iyz="0.0" izz="0.001"/>
    </inertial>
    <visual>
      <origin rpy="3.141592653589793 0 0" xyz="0 0 0"/>
      <geometry>
        <mesh filename="package://schunk_description/meshes/pw70/pw70_square_holder.stl"/>
      </geometry>
    </visual>
    <collision>
      <geometry>
        <mesh filename="package://schunk_description/meshes/pw70/pw70_square_holder.stl"/>
      </geometry>
    </collision>
  </link>
  <joint name="pw70_tool_joint" type="fixed">
    <origin rpy="0 0 0" xyz="0 0 0.07"/>
    <parent link="pw70_tilt_link"/>
    <child link="pw70_tool_link"/>
  </joint>
  <link name="pw70_tool_link">
    <inertial>
      <mass value="0.01"/>
      <origin xyz="0 0 0"/>
      <inertia ixx="0.001" ixy="0.0" ixz="0.0" iyy="0.001" iyz="0.0" izz="0.001"/>
    </inertial>
  </link>
  <gazebo reference="pw70_pan_link">
    <gravity>true</gravity>
    <self_collide>false</self_collide>
  </gazebo>
  <gazebo reference="pw70_tilt_link">
    <gravity>true</gravity>
    <self_collide>false</self_collide>
  </gazebo>
  <transmission name="pw70_pan_trans">
    <type>transmission_interface/SimpleTransmission</type>
    <joint name="pw70_pan_joint">
      <hardwareInterface>hardware_interface/PositionJointInterface</hardwareInterface>
      <hardwareInterface>hardware_interface/VelocityJointInterface</hardwareInterface>
      <!--hardwareInterface>EffortJointInterface</hardwareInterface-->
    </joint>
    <actuator name="pw70_pan_motor">
      <mechanicalReduction>1</mechanicalReduction>
    </actuator>
  </transmission>
  <transmission name="pw70_tilt_trans">
    <type>transmission_interface/SimpleTransmission</type>
    <joint name="pw70_tilt_joint">
      <hardwareInterface>hardware_interface/PositionJointInterface</hardwareInterface>
      <hardwareInterface>hardware_interface/VelocityJointInterface</hardwareInterface>
      <!--hardwareInterface>EffortJointInterface</hardwareInterface-->
    </joint>
    <actuator name="pw70_tilt_motor">
      <mechanicalReduction>1</mechanicalReduction>
    </actuator>
  </transmission>
  <!-- ros_control plugin -->
  <gazebo>
    <plugin filename="libhwi_switch_gazebo_ros_control.so" name="ros_control">
      <robotNamespace>pw70</robotNamespace>
      <filterJointsParam>joint_names</filterJointsParam>
    </plugin>
  </gazebo>
</robot>

