<?xml version="1.0" ?>
<!-- =================================================================================== -->
<!-- |    This document was autogenerated by xacro from urdf/kr150_2.xacro             | -->
<!-- |    EDITING THIS FILE BY HAND IS NOT RECOMMENDED                                 | -->
<!-- =================================================================================== -->
<robot name="kuka_kr150_2">
  <!-- LINKS -->
  <!-- base link -->
  <link name="base_link">
    <visual>
      <origin rpy="0 0 0" xyz="0 0 0"/>
      <geometry>
        <mesh filename="package://kuka_kr150_support/meshes/kr150_2/visual/base_link.dae"/>
      </geometry>
    </visual>
    <collision>
      <origin rpy="0 0 0" xyz="0 0 0"/>
      <geometry>
        <mesh filename="package://kuka_kr150_support/meshes/kr150_2/collision/base_link.stl"/>
      </geometry>
    </collision>
  </link>
  <!-- link 1 (A1) -->
  <link name="link_1">
    <visual>
      <origin rpy="0 0 0" xyz="0 0 0"/>
      <geometry>
        <mesh filename="package://kuka_kr150_support/meshes/kr150_2/visual/link_1.dae"/>
      </geometry>
    </visual>
    <collision>
      <origin rpy="0 0 0" xyz="0 0 0"/>
      <geometry>
        <mesh filename="package://kuka_kr150_support/meshes/kr150_2/collision/link_1.stl"/>
      </geometry>
    </collision>
  </link>
  <!-- link 2 -->
  <link name="link_2">
    <visual>
      <origin rpy="0 0 0" xyz="0 0 0"/>
      <geometry>
        <mesh filename="package://kuka_kr150_support/meshes/kr150_2/visual/link_2.dae"/>
      </geometry>
    </visual>
    <collision>
      <origin rpy="0 0 0" xyz="0 0 0"/>
      <geometry>
        <mesh filename="package://kuka_kr150_support/meshes/kr150_2/collision/link_2.stl"/>
      </geometry>
    </collision>
  </link>
  <!-- link 3 -->
  <link name="link_3">
    <visual>
      <origin rpy="0 0 0" xyz="0 0 0"/>
      <geometry>
        <mesh filename="package://kuka_kr150_support/meshes/kr150_2/visual/link_3.dae"/>
      </geometry>
    </visual>
    <collision>
      <origin rpy="0 0 0" xyz="0 0 0"/>
      <geometry>
        <mesh filename="package://kuka_kr150_support/meshes/kr150_2/collision/link_3.stl"/>
      </geometry>
    </collision>
  </link>
  <!-- link 4 -->
  <link name="link_4">
    <visual>
      <origin rpy="0 0 0" xyz="0 0 0"/>
      <geometry>
        <mesh filename="package://kuka_kr150_support/meshes/kr150_2/visual/link_4.dae"/>
      </geometry>
    </visual>
    <collision>
      <origin rpy="0 0 0" xyz="0 0 0"/>
      <geometry>
        <mesh filename="package://kuka_kr150_support/meshes/kr150_2/collision/link_4.stl"/>
      </geometry>
    </collision>
  </link>
  <!-- link 5 -->
  <link name="link_5">
    <visual>
      <origin rpy="0 0 0" xyz="0 0 0"/>
      <geometry>
        <mesh filename="package://kuka_kr150_support/meshes/kr150_2/visual/link_5.dae"/>
      </geometry>
    </visual>
    <collision>
      <origin rpy="0 0 0" xyz="0 0 0"/>
      <geometry>
        <mesh filename="package://kuka_kr150_support/meshes/kr150_2/collision/link_5.stl"/>
      </geometry>
    </collision>
  </link>
  <!-- link 6 -->
  <link name="link_6">
    <visual>
      <origin rpy="0 0 0" xyz="0 0 0"/>
      <geometry>
        <mesh filename="package://kuka_kr150_support/meshes/kr150_2/visual/link_6.dae"/>
      </geometry>
    </visual>
    <collision>
      <origin rpy="0 0 0" xyz="0 0 0"/>
      <geometry>
        <mesh filename="package://kuka_kr150_support/meshes/kr150_2/collision/link_6.stl"/>
      </geometry>
    </collision>
  </link>
  <!-- tool link -->
  <!-- This frame corresponds to the $TOOL coordinate system in KUKA KRC controllers. -->
  <link name="flange"/>
  <!-- END LINKS -->
  <!-- JOINTS -->
  <!-- joint 1 (A1) -->
  <joint name="joint_a1" type="revolute">
    <origin rpy="0 0 0" xyz="0 0 0.75"/>
    <parent link="base_link"/>
    <child link="link_1"/>
    <axis xyz="0 0 -1"/>
    <limit effort="0" lower="-3.2288591161895095" upper="3.2288591161895095" velocity="1.9198621771937625"/>
  </joint>
  <!-- joint 2 (A2) -->
  <joint name="joint_a2" type="revolute">
    <origin rpy="0 0 0" xyz="0.35 0 0"/>
    <parent link="link_1"/>
    <child link="link_2"/>
    <axis xyz="0 1 0"/>
    <limit effort="0" lower="-2.548180707911721" upper="0.0" velocity="1.9198621771937625"/>
  </joint>
  <!-- joint 3 (A3) -->
  <joint name="joint_a3" type="revolute">
    <origin rpy="0 0 0" xyz="1.25 0 0"/>
    <parent link="link_2"/>
    <child link="link_3"/>
    <axis xyz="0 1 0"/>
    <limit effort="0" lower="-2.076941809873252" upper="2.705260340591211" velocity="1.7453292519943295"/>
  </joint>
  <!-- joint 4 (A4) -->
  <joint name="joint_a4" type="revolute">
    <origin rpy="0 0 0" xyz="0 0 -0.055"/>
    <parent link="link_3"/>
    <child link="link_4"/>
    <axis xyz="-1 0 0"/>
    <limit effort="0" lower="-6.1086523819801535" upper="6.1086523819801535" velocity="2.9670597283903604"/>
  </joint>
  <!-- joint 5 (A5) -->
  <joint name="joint_a5" type="revolute">
    <origin rpy="0 0 0" xyz="1.1 0 0"/>
    <parent link="link_4"/>
    <child link="link_5"/>
    <axis xyz="0 1 0"/>
    <limit effort="0" lower="-2.181661564992912" upper="2.181661564992912" velocity="2.9670597283903604"/>
  </joint>
  <!-- joint 6 (A6) -->
  <joint name="joint_a6" type="revolute">
    <origin rpy="0 0 0" xyz="0.23 0 0"/>
    <parent link="link_5"/>
    <child link="link_6"/>
    <axis xyz="-1 0 0"/>
    <limit effort="0" lower="-6.1086523819801535" upper="6.1086523819801535" velocity="4.153883619746504"/>
  </joint>
  <!-- tool frame - fixed frame -->
  <joint name="joint_a6-flange" type="fixed">
    <parent link="link_6"/>
    <child link="flange"/>
    <origin rpy="0 0 0" xyz="0 0 0"/>
  </joint>
  <!-- END JOINTS -->
  <!-- ROS base_link to KUKA $ROBROOT coordinate system transform -->
  <link name="base"/>
  <joint name="base_link-base" type="fixed">
    <origin rpy="0 0 0" xyz="0 0 0"/>
    <parent link="base_link"/>
    <child link="base"/>
  </joint>
  <!-- This frame corresponds to the $TOOL coordinate system in KUKA KRC controllers -->
  <link name="tool0"/>
  <joint name="flange-tool0" type="fixed">
    <parent link="flange"/>
    <child link="tool0"/>
    <origin rpy="0 1.5707963267948966 0" xyz="0 0 0"/>
  </joint>
</robot>

