<?xml version="1.0" ?>
<!-- =================================================================================== -->
<!-- |    This document was autogenerated by xacro from urdf/kr150r3100_2.xacro        | -->
<!-- |    EDITING THIS FILE BY HAND IS NOT RECOMMENDED                                 | -->
<!-- =================================================================================== -->
<robot name="kuka_kr150r3100_2">
  <!-- colours based on RAL values given in "FAQ - Colours of robot and robot
       controller", version "KUKA.Tifs | 2010-01-21 |YM| DefaultColorsRobotAndController.doc",
       downloaded 2015-07-18 from
       http://www.kuka.be/main/cservice/faqs/hardware/DefaultColorsRobotAndController.pdf

       all RAL colours converted using http://www.visual-graphics.de/en/customer-care/ral-colours
  -->
  <!-- LINKS -->
  <!-- base link -->
  <link name="base_link">
    <visual>
      <origin rpy="0 0 0" xyz="0 0 0"/>
      <geometry>
        <mesh filename="package://kuka_kr150_support/meshes/kr150r3100_2/visual/base_link.stl"/>
      </geometry>
      <material name="">
        <color rgba="0.5058823529411764 0.47058823529411764 0.38823529411764707 1.0"/>
      </material>
    </visual>
    <collision>
      <origin rpy="0 0 0" xyz="0 0 0"/>
      <geometry>
        <mesh filename="package://kuka_kr150_support/meshes/kr150r3100_2/collision/base_link.stl"/>
      </geometry>
    </collision>
  </link>
  <!-- link 1 (A1) -->
  <link name="link_1">
    <visual>
      <origin rpy="0 0 0" xyz="0 0 0"/>
      <geometry>
        <mesh filename="package://kuka_kr150_support/meshes/kr150r3100_2/visual/link_1.stl"/>
      </geometry>
      <material name="">
        <color rgba="0.9647058823529412 0.47058823529411764 0.1568627450980392 1.0"/>
      </material>
    </visual>
    <collision>
      <origin rpy="0 0 0" xyz="0 0 0"/>
      <geometry>
        <mesh filename="package://kuka_kr150_support/meshes/kr150r3100_2/collision/link_1.stl"/>
      </geometry>
    </collision>
  </link>
  <!-- link 2 -->
  <link name="link_2">
    <visual>
      <origin rpy="0 0 0" xyz="0 0 0"/>
      <geometry>
        <mesh filename="package://kuka_kr150_support/meshes/kr150r3100_2/visual/link_2.stl"/>
      </geometry>
      <material name="">
        <color rgba="0.9647058823529412 0.47058823529411764 0.1568627450980392 1.0"/>
      </material>
    </visual>
    <collision>
      <origin rpy="0 0 0" xyz="0 0 0"/>
      <geometry>
        <mesh filename="package://kuka_kr150_support/meshes/kr150r3100_2/collision/link_2.stl"/>
      </geometry>
    </collision>
  </link>
  <!-- link 3 -->
  <link name="link_3">
    <visual>
      <origin rpy="0 0 0" xyz="0 0 0"/>
      <geometry>
        <mesh filename="package://kuka_kr150_support/meshes/kr150r3100_2/visual/link_3.stl"/>
      </geometry>
      <material name="">
        <color rgba="0.9647058823529412 0.47058823529411764 0.1568627450980392 1.0"/>
      </material>
    </visual>
    <collision>
      <origin rpy="0 0 0" xyz="0 0 0"/>
      <geometry>
        <mesh filename="package://kuka_kr150_support/meshes/kr150r3100_2/collision/link_3.stl"/>
      </geometry>
    </collision>
  </link>
  <!-- link 4 -->
  <link name="link_4">
    <visual>
      <origin rpy="0 0 0" xyz="0 0 0"/>
      <geometry>
        <mesh filename="package://kuka_kr150_support/meshes/kr150r3100_2/visual/link_4.stl"/>
      </geometry>
      <material name="">
        <color rgba="0.9647058823529412 0.47058823529411764 0.1568627450980392 1.0"/>
      </material>
    </visual>
    <collision>
      <origin rpy="0 0 0" xyz="0 0 0"/>
      <geometry>
        <mesh filename="package://kuka_kr150_support/meshes/kr150r3100_2/collision/link_4.stl"/>
      </geometry>
    </collision>
  </link>
  <!-- link 5 -->
  <link name="link_5">
    <visual>
      <origin rpy="0 0 0" xyz="0 0 0"/>
      <geometry>
        <mesh filename="package://kuka_kr150_support/meshes/kr150r3100_2/visual/link_5.stl"/>
      </geometry>
      <material name="">
        <color rgba="0.9647058823529412 0.47058823529411764 0.1568627450980392 1.0"/>
      </material>
    </visual>
    <collision>
      <origin rpy="0 0 0" xyz="0 0 0"/>
      <geometry>
        <mesh filename="package://kuka_kr150_support/meshes/kr150r3100_2/collision/link_5.stl"/>
      </geometry>
    </collision>
  </link>
  <!-- link 6 -->
  <link name="link_6">
    <visual>
      <origin rpy="0 0 0" xyz="0 0 0"/>
      <geometry>
        <mesh filename="package://kuka_kr150_support/meshes/kr150r3100_2/visual/link_6.stl"/>
      </geometry>
      <material name="">
        <color rgba="0.9647058823529412 0.47058823529411764 0.1568627450980392 1.0"/>
      </material>
    </visual>
    <collision>
      <origin rpy="0 0 0" xyz="0 0 0"/>
      <geometry>
        <mesh filename="package://kuka_kr150_support/meshes/kr150r3100_2/collision/link_6.stl"/>
      </geometry>
    </collision>
  </link>
  <!-- END LINKS -->
  <!-- JOINTS -->
  <!-- joint 1 (A1) -->
  <joint name="joint_a1" type="revolute">
    <origin rpy="0 0 0" xyz="0 0 0.645"/>
    <parent link="base_link"/>
    <child link="link_1"/>
    <axis xyz="0 0 -1"/>
    <limit effort="0" lower="-3.2288591161895095" upper="3.2288591161895095" velocity="1.8325957145940461"/>
  </joint>
  <!-- joint 2 (A2) -->
  <joint name="joint_a2" type="revolute">
    <origin rpy="0 0 0" xyz="0.33 0 0"/>
    <parent link="link_1"/>
    <child link="link_2"/>
    <axis xyz="0 1 0"/>
    <limit effort="0" lower="-2.443460952792061" upper="-0.08726646259971647" velocity="1.8675022996339325"/>
  </joint>
  <!-- joint 3 (A3) -->
  <joint name="joint_a3" type="revolute">
    <origin rpy="0 0 0" xyz="1.350 0 0"/>
    <parent link="link_2"/>
    <child link="link_3"/>
    <axis xyz="0 1 0"/>
    <limit effort="0" lower="-2.0943951023931953" upper="2.9321531433504737" velocity="1.9896753472735358"/>
  </joint>
  <!-- joint 4 (A4) -->
  <joint name="joint_a4" type="revolute">
    <origin rpy="0 0 0" xyz="1.420 0 0.115"/>
    <parent link="link_3"/>
    <child link="link_4"/>
    <axis xyz="-1 0 0"/>
    <limit effort="0" lower="-6.1086523819801535" upper="6.1086523819801535" velocity="3.3161255787892263"/>
  </joint>
  <!-- joint 5 (A5) -->
  <joint name="joint_a5" type="revolute">
    <origin rpy="0 0 0" xyz="0 0 0"/>
    <parent link="link_4"/>
    <child link="link_5"/>
    <axis xyz="0 1 0"/>
    <limit effort="0" lower="-2.181661564992912" upper="2.181661564992912" velocity="3.141592653589793"/>
  </joint>
  <!-- joint 6 (A6) -->
  <joint name="joint_a6" type="revolute">
    <origin rpy="0 0 0" xyz="0.215 0 0"/>
    <parent link="link_5"/>
    <child link="link_6"/>
    <axis xyz="-1 0 0"/>
    <limit effort="0" lower="-6.1086523819801535" upper="6.1086523819801535" velocity="4.537856055185257"/>
  </joint>
  <!-- ROS-Industrial 'base' frame: base_link to KUKA $ROBROOT coordinate system transform -->
  <link name="base"/>
  <joint name="base_link-base" type="fixed">
    <origin rpy="0 0 0" xyz="0 0 0"/>
    <parent link="base_link"/>
    <child link="base"/>
  </joint>
  <!-- ROS-Industrial 'flange' frame: attachment point for EEF models -->
  <link name="flange"/>
  <joint name="joint_6-flange" type="fixed">
    <origin rpy="0 0 0" xyz="0 0 0"/>
    <parent link="link_6"/>
    <child link="flange"/>
  </joint>
  <!-- ROS-Industrial 'tool0' frame: all-zeros tool frame -->
  <!-- This frame corresponds to the $FLANGE coordinate system in KUKA KRC controllers. -->
  <link name="tool0"/>
  <joint name="flange-tool0" type="fixed">
    <parent link="flange"/>
    <child link="tool0"/>
    <origin rpy="0 1.5707963267948966 0" xyz="0 0 0"/>
  </joint>
</robot>

