<?xml version="1.0" ?>
<!-- =================================================================================== -->
<!-- |    This document was autogenerated by xacro from urdf/onrobot_2fg7_upload.xacro | -->
<!-- |    EDITING THIS FILE BY HAND IS NOT RECOMMENDED                                 | -->
<!-- =================================================================================== -->
<robot name="2fg7_outwards">
  <material name="silver">
    <color rgba="0.700 0.700 0.700 1.000"/>
  </material>
  <gazebo reference="gripper_base_link">
    <material>Gazebo/Grey</material>
    <implicitSpringDamper>1</implicitSpringDamper>
    <mu1>0.2</mu1>
    <mu2>0.2</mu2>
    <kp>100000000.0</kp>
    <kd>1.0</kd>
    <selfCollide>true</selfCollide>
    <gravity>true</gravity>
  </gazebo>
  <gazebo reference="right_finger_link">
    <material>Gazebo/Grey</material>
    <implicitSpringDamper>1</implicitSpringDamper>
    <mu1>0.2</mu1>
    <mu2>0.2</mu2>
    <kp>100000000.0</kp>
    <kd>1.0</kd>
    <selfCollide>true</selfCollide>
  </gazebo>
  <gazebo reference="left_finger_link">
    <material>Gazebo/Grey</material>
    <implicitSpringDamper>1</implicitSpringDamper>
    <mu1>0.2</mu1>
    <mu2>0.2</mu2>
    <kp>100000000.0</kp>
    <kd>1.0</kd>
    <selfCollide>true</selfCollide>
  </gazebo>
  <transmission name="left_finger_joint_tran">
    <type>transmission_interface/SimpleTransmission</type>
    <joint name="left_finger_joint">
      <hardwareInterface>hardware_interface/PositionJointInterface</hardwareInterface>
    </joint>
    <actuator name="left_finger_joint_motor">
      <hardwareInterface>hardware_interface/PositionJointInterface</hardwareInterface>
      <mechanicalReduction>1</mechanicalReduction>
    </actuator>
  </transmission>
  <link name="base_link">
    <inertial>
      <origin rpy="0 0 0" xyz="-4.898915958379213e-05 2.84756960271082e-06 0.06811082379774974"/>
      <mass value="1.2646523179240972"/>
      <inertia ixx="0.001504" ixy="-0.0" ixz="-3e-06" iyy="0.001812" iyz="0.0" izz="0.001053"/>
    </inertial>
    <visual>
      <origin rpy="0 0 0" xyz="0 0 0"/>
      <geometry>
        <mesh filename="package://onrobot_2fg7_description/meshes/base_link.stl" scale="0.001 0.001 0.001"/>
      </geometry>
      <material name="silver"/>
    </visual>
    <collision>
      <origin rpy="0 0 0" xyz="0 0 0"/>
      <geometry>
        <mesh filename="package://onrobot_2fg7_description/meshes/base_link.stl" scale="0.001 0.001 0.001"/>
      </geometry>
    </collision>
  </link>
  <link name="right_finger_link">
    <inertial>
      <origin rpy="0 0 0" xyz="0.017874296677847158 0.02949104051991925 0.01523421548622829"/>
      <mass value="0.023219383355922288"/>
      <inertia ixx="6e-06" ixy="-0.0" ixz="1e-06" iyy="5e-06" iyz="-0.0" izz="2e-06"/>
    </inertial>
    <visual>
      <origin rpy="0 0 0" xyz="0.054361 0.029494 -0.12005"/>
      <geometry>
        <mesh filename="package://onrobot_2fg7_description/meshes/right_finger_link.stl" scale="0.001 0.001 0.001"/>
      </geometry>
      <material name="silver"/>
    </visual>
    <collision name="right_finger_collision">
      <origin rpy="0 0 0" xyz="0.054361 0.029494 -0.12005"/>
      <geometry>
        <mesh filename="package://onrobot_2fg7_description/meshes/right_finger_link.stl" scale="0.001 0.001 0.001"/>
      </geometry>
    </collision>
  </link>
  <link name="left_finger_link">
    <inertial>
      <origin rpy="0 0 0" xyz="0.004247703322119739 0.029496959480080673 0.015234215486237948"/>
      <mass value="0.023219383355922288"/>
      <inertia ixx="6e-06" ixy="-0.0" ixz="-1e-06" iyy="5e-06" iyz="0.0" izz="2e-06"/>
    </inertial>
    <visual>
      <origin rpy="0 0 0" xyz="-0.032239 0.029494 -0.12005"/>
      <geometry>
        <mesh filename="package://onrobot_2fg7_description/meshes/left_finger_link.stl" scale="0.001 0.001 0.001"/>
      </geometry>
      <material name="silver"/>
    </visual>
    <collision name="left_finger_collision">
      <origin rpy="0 0 0" xyz="-0.032239 0.029494 -0.12005"/>
      <geometry>
        <mesh filename="package://onrobot_2fg7_description/meshes/left_finger_link.stl" scale="0.001 0.001 0.001"/>
      </geometry>
    </collision>
  </link>
  <joint name="left_finger_joint" type="prismatic">
    <origin rpy="0 0 0" xyz="0.032239 -0.029494 0.12005"/>
    <parent link="base_link"/>
    <child link="left_finger_link"/>
    <axis xyz="-1.0 0.0 0.0"/>
    <limit effort="140" lower="0.0" upper="0.019" velocity="0.45"/>
    <!-- total 0.38 -->
  </joint>
  <joint name="right_finger_joint" type="prismatic">
    <origin rpy="0 0 0" xyz="-0.054361 -0.029494 0.12005"/>
    <parent link="base_link"/>
    <child link="right_finger_link"/>
    <axis xyz="1.0 0.0 0.0"/>
    <limit effort="140" lower="-0.019" upper="0.019" velocity="0.45"/>
    <mimic joint="left_finger_joint" multiplier="1.0"/>
  </joint>
  <link name="world"/>
  <joint name="world_joint" type="fixed">
    <parent link="world"/>
    <child link="base_link"/>
    <origin rpy="0.0 0.0 0.0" xyz="0.0 0.0 0.0"/>
  </joint>
  <gazebo>
    <plugin filename="libgazebo_grasp_fix.so" name="gazebo_grasp_fix">
      <arm>
        <arm_name>2FG7</arm_name>
        <palm_link>base_link</palm_link>
        <gripper_link>left_finger_link</gripper_link>
        <gripper_link>right_finger_link</gripper_link>
      </arm>
      <forces_angle_tolerance>80</forces_angle_tolerance>
      <update_rate>10</update_rate>
      <grip_count_threshold>1</grip_count_threshold>
      <max_grip_count>3</max_grip_count>
      <release_tolerance>0.01</release_tolerance>
      <disable_collisions_on_attach>false</disable_collisions_on_attach>
      <contact_topic>__default_topic__</contact_topic>
    </plugin>
  </gazebo>
  <gazebo>
    <!-- loading plugin: mimic joints works in gazebo now -->
    <plugin filename="libroboticsgroup_upatras_gazebo_mimic_joint_plugin.so" name="mimic_2FG7">
      <joint>left_finger_joint</joint>
      <mimicJoint>right_finger_joint</mimicJoint>
      <!--multiplier>1.0</multiplier>
              <offset>0.0</offset-->
    </plugin>
  </gazebo>
</robot>

