<?xml version="1.0" ?>
<!-- =================================================================================== -->
<!-- |    This document was autogenerated by xacro from pioneer-lx-devil.urdf.xacro    | -->
<!-- |    EDITING THIS FILE BY HAND IS NOT RECOMMENDED                                 | -->
<!-- =================================================================================== -->
<robot name="pioneer-lx-devil" xmlns:body="http://playerstage.sourceforge.net/gazebo/xmlschema/#body" xmlns:controller="http://playerstage.sourceforge.net/gazebo/xmlschema/#controller" xmlns:gazebo="http://playerstage.sourceforge.net/gazebo/xmlschema/#gz" xmlns:geom="http://playerstage.sourceforge.net/gazebo/xmlschema/#geom" xmlns:interface="http://playerstage.sourceforge.net/gazebo/xmlschema/#interface" xmlns:joint="http://playerstage.sourceforge.net/gazebo/xmlschema/#joint" xmlns:model="http://playerstage.sourceforge.net/gazebo/xmlschema/#model" xmlns:physics="http://playerstage.sourceforge.net/gazebo/xmlschema/#physics" xmlns:renderable="http://playerstage.sourceforge.net/gazebo/xmlschema/#renderable" xmlns:rendering="http://playerstage.sourceforge.net/gazebo/xmlschema/#rendering" xmlns:sensor="http://playerstage.sourceforge.net/gazebo/xmlschema/#sensor" xmlns:xacro="http://www.ros.org/wiki/xacro" xmlns:xi="http://www.w3.org/2001/XInclude">
  <!-- TODO share pioneer lx mobile robot components with pioneer-lx urdf by
including macro. -->
  <link name="base_link">
    <!-- base_link origin point is center of rotation, on the floor. -->
    <visual name="base_link_visual">
      <geometry name="base_link_visual_geom">
        <mesh filename="package://meshes/pioneer-lx/pioneer-lx_visual.stl" scale="0.001 0.001 0.001"/>
        <!-- box size="0.697 0.5 0.333" / -->
      </geometry>
      <origin rpy="0 0 1.570796" xyz="0 0 0"/>
      <material name="lx_red_mat">
        <color rgba="0.8 0.1 0.1 1.0"/>
      </material>
    </visual>
    <collision name="base_link_collision">
      <geometry name="base_link_collision_geom">
        <box size="0.697 0.5 0.35"/>
        <!-- box size="0.697 0.5 0.35" / -->
      </geometry>
      <origin rpy="0 0 0" xyz="0 0 0.200"/>
    </collision>
  </link>
  <!-- for some reason KDL wants this to be a separate link -->
  <link name="robot_mass">
    <inertial>
      <mass value="57.8"/>
      <!-- 60 kg minus each wheel -->
      <inertia ixx="1" ixy="0" ixz="0" iyy="1" iyz="0" izz="1"/>
    </inertial>
  </link>
  <joint name="robot_mass_attach" type="fixed">
    <parent link="base_link"/>
    <child link="robot_mass"/>
  </joint>
  <!-- right wheel -->
  <link name="r_wheel">
    <inertial>
      <mass value="1.1"/>
      <!-- kg -->
      <inertia ixx="0.02" ixy="0" ixz="0" iyy="0.02" iyz="0" izz="0.01"/>
    </inertial>
    <!--
TODO separate out pioner lx wheels in visual model 
    <visual name="r_wheel_dumb_visual">
      <geometry name="r_wheel_dumb_visual_geom">
        <cylinder radius="0.100" length="0.05" />
      </geometry>
      <origin rpy="1.570796 0 0" />
      <material name="lx_grey_mat">
        <color rgba="0.8 0.8 0.8 1.0" />
      </material>
    </visual>
-->
    <collision name="r_wheel_collision">
      <geometry name="r_wheel_collision_geom">
        <cylinder length="0.05" radius="0.100"/>
      </geometry>
      <origin rpy="1.570796 0 0"/>
    </collision>
  </link>
  <!-- left wheel -->
  <link name="l_wheel">
    <inertial>
      <mass value="1.1"/>
      <!-- kg -->
      <inertia ixx="0.02" ixy="0" ixz="0" iyy="0.02" iyz="0" izz="0.01"/>
    </inertial>
    <!--
    <visual name="l_wheel_dumb_visual">
      <geometry name="l_wheel_dumb_visual_geom">
        <cylinder radius="0.100" length="0.05" />
      </geometry>
      <origin rpy="1.570796 0 0" />
      <material name="lx_grey_mat">
        <color rgba="0.8 0.8 0.8 1.0" />
      </material>
    </visual>
   -->
    <collision name="l_wheel_collision">
      <geometry name="l_wheel_collision_geom">
        <cylinder length="0.05" radius="0.100"/>
      </geometry>
      <origin rpy="1.570796 0 0"/>
    </collision>
  </link>
  <!-- wheel joints. only used in gazebo, real robot velocity is controlled as a unit, not individual wheel motion. -->
  <joint name="r_wheel_joint" type="fixed">
    <!--  type="continuous" -->
    <origin rpy="0 0 0" xyz="0 0.2 0.1"/>
    <parent link="base_link"/>
    <child link="r_wheel"/>
  </joint>
  <joint name="l_wheel_joint" type="fixed">
    <!-- type="continuous" -->
    <origin rpy="0 0 0" xyz="0 -0.2 0.1"/>
    <parent link="base_link"/>
    <child link="l_wheel"/>
  </joint>
  <!-- pioneer lx deck -->
  <link name="deck">
    <visual name="deck_visual">
      <geometry name="deck_visual_geom">
        <box size="0.407 0.437 0.076"/>
      </geometry>
      <material name="lx_deck_mat">
        <color rgba="0 0 0 1"/>
      </material>
    </visual>
    <collision name="deck_collision">
      <geometry name="deck_collision_geom">
        <box size="0.407 0.437 0.076"/>
        <!-- box size="0.407 0.437 0.076" / -->
      </geometry>
    </collision>
  </link>
  <joint name="deck_joint" type="fixed">
    <origin rpy="0 0 0" xyz="0.075 0 0.410"/>
    <parent link="base_link"/>
    <child link="deck"/>
  </joint>
  <!-- "plinth" -->
  <link name="plinth">
    <visual name="plinth_visual">
      <geometry name="plinth_visual_geom">
        <mesh filename="package://meshes/pioneer-lx/pioneer-lx-plinth.stl" scale="0.001 0.001 0.001"/>
        <!-- box size="0.18 0.2476 0.99" / -->
      </geometry>
      <material name="plinth_darkgrey_mat">
        <color rgba="0.2 0.2 0.2 1.0"/>
      </material>
    </visual>
    <collision name="plinth_collision">
      <geometry name="plinth_collision_geom">
        <mesh filename="package://meshes/pioneer-lx/pioneer-lx-plinth.stl" scale="0.001 0.001 0.001"/>
        <!-- box size="0.18 0.2476 0.99" / -->
        <origin xyz="-0.02 0 0.867"/>
      </geometry>
    </collision>
  </link>
  <joint name="plinth_joint" type="fixed">
    <parent link="base_link"/>
    <child link="plinth"/>
    <origin xyz="-0.11 0 0.448"/>
  </joint>
  <!-- Jaco2 arms, using lower upward-pointing mounting option.

       The kinova_description package is contained in the
       Kinovarobotics jaco_ros repository. As of 2/4/2015, you must 
       check out the "jaco2_import" branch.
        https://github.com/Kinovarobotics/jaco-ros/tree/jaco2_import
   -->
  <link name="left_arm_mount">
  </link>
  <link name="right_arm_mount">
  </link>
  <link name="left_jaco2_link_base">
    <visual>
      <geometry>
        <mesh filename="package://kinova_description/meshes/jaco2_link_base.dae"/>
      </geometry>
      <material name="carbon_fiber">
        <color rgba="0.792156862745098 0.819607843137255 0.933333333333333 1"/>
      </material>
    </visual>
    <collision>
      <geometry>
        <mesh filename="package://kinova_description/meshes/jaco2_link_base.dae"/>
      </geometry>
    </collision>
  </link>
  <joint name="left_jaco2_joint_base" type="fixed">
    <parent link="left_arm_mount"/>
    <child link="left_jaco2_link_base"/>
    <axis xyz="0 0 0"/>
    <limit effort="30" lower="0" upper="0" velocity="0.35"/>
    <origin rpy="0 0 0" xyz="0 0 0"/>
  </joint>
  <link name="left_jaco2_link_1">
    <visual>
      <geometry>
        <mesh filename="package://kinova_description/meshes/jaco2_link_1.dae"/>
      </geometry>
      <material name="carbon_fiber">
        <color rgba="0.792156862745098 0.819607843137255 0.933333333333333 1"/>
      </material>
    </visual>
    <collision>
      <geometry>
        <mesh filename="package://kinova_description/meshes/jaco2_link_1.dae"/>
      </geometry>
    </collision>
  </link>
  <joint name="left_jaco2_joint_1" type="continuous">
    <parent link="left_jaco2_link_base"/>
    <child link="left_jaco2_link_1"/>
    <axis xyz="0 0 -1"/>
    <limit effort="30" lower="-6.28318530718" upper="6.28318530718" velocity="0.35"/>
    <origin rpy="3.14159265359 0 3.14159265359" xyz="0 0 0.1535"/>
  </joint>
  <link name="left_jaco2_link_2">
    <visual>
      <geometry>
        <mesh filename="package://kinova_description/meshes/jaco2_link_2.dae"/>
      </geometry>
      <material name="carbon_fiber">
        <color rgba="0.792156862745098 0.819607843137255 0.933333333333333 1"/>
      </material>
    </visual>
    <collision>
      <geometry>
        <mesh filename="package://kinova_description/meshes/jaco2_link_2.dae"/>
      </geometry>
    </collision>
  </link>
  <joint name="left_jaco2_joint_2" type="revolute">
    <parent link="left_jaco2_link_1"/>
    <child link="left_jaco2_link_2"/>
    <axis xyz="0 0 1"/>
    <limit effort="30" lower="-3.14159265359" upper="0" velocity="0.35"/>
    <origin rpy="-1.57079632679 3.14159265359 0" xyz="0 0 -0.1185"/>
  </joint>
  <link name="left_jaco2_link_3">
    <visual>
      <geometry>
        <mesh filename="package://kinova_description/meshes/jaco2_link_3.dae"/>
      </geometry>
      <material name="carbon_fiber">
        <color rgba="0.792156862745098 0.819607843137255 0.933333333333333 1"/>
      </material>
    </visual>
    <collision>
      <geometry>
        <mesh filename="package://kinova_description/meshes/jaco2_link_3.dae"/>
      </geometry>
    </collision>
  </link>
  <joint name="left_jaco2_joint_3" type="revolute">
    <parent link="left_jaco2_link_2"/>
    <child link="left_jaco2_link_3"/>
    <axis xyz="0 0 -1"/>
    <limit effort="30" lower="-3.92699081699" upper="0.785398163397" velocity="0.35"/>
    <origin rpy="3.14159265359 0 1.57079632679" xyz="0.41 0 0"/>
  </joint>
  <link name="left_jaco2_link_4">
    <visual>
      <geometry>
        <mesh filename="package://kinova_description/meshes/jaco2_link_4.dae"/>
      </geometry>
      <material name="carbon_fiber">
        <color rgba="0.792156862745098 0.819607843137255 0.933333333333333 1"/>
      </material>
    </visual>
    <collision>
      <geometry>
        <mesh filename="package://kinova_description/meshes/jaco2_link_4.dae"/>
      </geometry>
    </collision>
  </link>
  <joint name="left_jaco2_joint_4" type="continuous">
    <parent link="left_jaco2_link_3"/>
    <child link="left_jaco2_link_4"/>
    <axis xyz="0 0 -1"/>
    <limit effort="30" lower="-6.28318530718" upper="6.28318530718" velocity="0.35"/>
    <origin rpy="3.14159265359 1.57079632679 0" xyz="0.207 0 -0.01125"/>
  </joint>
  <link name="left_jaco2_link_5">
    <visual>
      <geometry>
        <mesh filename="package://kinova_description/meshes/jaco2_link_5.dae"/>
      </geometry>
      <material name="carbon_fiber">
        <color rgba="0.792156862745098 0.819607843137255 0.933333333333333 1"/>
      </material>
    </visual>
    <collision>
      <geometry>
        <mesh filename="package://kinova_description/meshes/jaco2_link_5.dae"/>
      </geometry>
    </collision>
  </link>
  <joint name="left_jaco2_joint_5" type="continuous">
    <parent link="left_jaco2_link_4"/>
    <child link="left_jaco2_link_5"/>
    <axis xyz="0 0 -1"/>
    <limit effort="30" lower="-6.28318530718" upper="6.28318530718" velocity="0.35"/>
    <origin rpy="0 -1.0471975512 0" xyz="0.03700 0 -0.06408"/>
  </joint>
  <link name="left_jaco2_link_hand">
    <visual>
      <geometry>
        <mesh filename="package://kinova_description/meshes/jaco2_link_hand.dae"/>
      </geometry>
      <material name="carbon_fiber">
        <color rgba="0.792156862745098 0.819607843137255 0.933333333333333 1"/>
      </material>
    </visual>
    <collision>
      <geometry>
        <mesh filename="package://kinova_description/meshes/jaco2_link_hand.dae"/>
      </geometry>
    </collision>
  </link>
  <joint name="left_jaco2_joint_6" type="continuous">
    <parent link="left_jaco2_link_5"/>
    <child link="left_jaco2_link_hand"/>
    <axis xyz="0 0 -1"/>
    <limit effort="30" lower="-6.28318530718" upper="6.28318530718" velocity="0.35"/>
    <origin rpy="-1.0471975512 0 1.57079632679" xyz="0.03700 0 -0.06408"/>
  </joint>
  <joint name="left_jaco2_link_base_to_api_origin" type="fixed">
    <parent link="left_jaco2_link_base"/>
    <child link="left_jaco2_api_origin"/>
    <origin rpy="0 0 0" xyz="0 0 0.028"/>
  </joint>
  <link name="left_jaco2_api_origin">
    <!--
         <visual>
           <geometry>
             <box xyz="0 0 0" size="0.1 0.1 0.1"/>
           </geometry>
         </visual>
         <collision>
           <geometry>
             <box xyz="0 0 0" size="0.1 0.1 0.1"/>
           </geometry>
         </collision>
         -->
  </link>
  <joint name="left_jaco2_link_hand_to_end_effector" type="fixed">
    <parent link="left_jaco2_link_hand"/>
    <child link="left_jaco2_end_effector"/>
    <origin rpy="0 3.14159265359 0" xyz="0 0 -0.1687"/>
  </joint>
  <link name="left_jaco2_end_effector"/>
  <link name="left_jaco2_link_finger_1">
    <visual>
      <geometry>
        <mesh filename="package://kinova_description/meshes/jaco2_link_finger_1.dae"/>
      </geometry>
      <material name="carbon_fiber">
        <color rgba="0.792156862745098 0.819607843137255 0.933333333333333 1"/>
      </material>
    </visual>
    <collision>
      <geometry>
        <mesh filename="package://kinova_description/meshes/jaco2_link_finger_1.dae"/>
      </geometry>
    </collision>
  </link>
  <joint name="left_jaco2_joint_finger_1" type="revolute">
    <parent link="left_jaco2_link_hand"/>
    <child link="left_jaco2_link_finger_1"/>
    <axis xyz="0 0 1"/>
    <origin rpy="-1.7983 1.117 3.1416" xyz="-0.03978 0 -0.10071"/>
    <limit effort="30" lower="0" upper="0.698131700798" velocity="5"/>
  </joint>
  <link name="left_jaco2_link_finger_2">
    <visual>
      <geometry>
        <mesh filename="package://kinova_description/meshes/jaco2_link_finger_2.dae"/>
      </geometry>
      <material name="carbon_fiber">
        <color rgba="0.792156862745098 0.819607843137255 0.933333333333333 1"/>
      </material>
    </visual>
    <collision>
      <geometry>
        <mesh filename="package://kinova_description/meshes/jaco2_link_finger_2.dae"/>
      </geometry>
    </collision>
  </link>
  <joint name="left_jaco2_joint_finger_2" type="revolute">
    <parent link="left_jaco2_link_hand"/>
    <child link="left_jaco2_link_finger_2"/>
    <axis xyz="0 0 1"/>
    <origin rpy="-1.6222 1.117 -0.23615" xyz="0.03569 -0.0216 -0.10071"/>
    <limit effort="30" lower="0" upper="0.698131700798" velocity="5"/>
  </joint>
  <link name="left_jaco2_link_finger_3">
    <visual>
      <geometry>
        <mesh filename="package://kinova_description/meshes/jaco2_link_finger_3.dae"/>
      </geometry>
      <material name="carbon_fiber">
        <color rgba="0.792156862745098 0.819607843137255 0.933333333333333 1"/>
      </material>
    </visual>
    <collision>
      <geometry>
        <mesh filename="package://kinova_description/meshes/jaco2_link_finger_3.dae"/>
      </geometry>
    </collision>
  </link>
  <joint name="left_jaco2_joint_finger_3" type="revolute">
    <parent link="left_jaco2_link_hand"/>
    <child link="left_jaco2_link_finger_3"/>
    <axis xyz="0 0 1"/>
    <origin rpy="-1.5161 1.1459 0.23978" xyz="0.03569 0.0216 -0.10071"/>
    <limit effort="30" lower="0" upper="0.698131700798" velocity="5"/>
  </joint>
  <link name="right_jaco2_link_base">
    <visual>
      <geometry>
        <mesh filename="package://kinova_description/meshes/jaco2_link_base.dae"/>
      </geometry>
      <material name="carbon_fiber">
        <color rgba="0.792156862745098 0.819607843137255 0.933333333333333 1"/>
      </material>
    </visual>
    <collision>
      <geometry>
        <mesh filename="package://kinova_description/meshes/jaco2_link_base.dae"/>
      </geometry>
    </collision>
  </link>
  <joint name="right_jaco2_joint_base" type="fixed">
    <parent link="right_arm_mount"/>
    <child link="right_jaco2_link_base"/>
    <axis xyz="0 0 0"/>
    <limit effort="30" lower="0" upper="0" velocity="0.35"/>
    <origin rpy="0 0 0" xyz="0 0 0"/>
  </joint>
  <link name="right_jaco2_link_1">
    <visual>
      <geometry>
        <mesh filename="package://kinova_description/meshes/jaco2_link_1.dae"/>
      </geometry>
      <material name="carbon_fiber">
        <color rgba="0.792156862745098 0.819607843137255 0.933333333333333 1"/>
      </material>
    </visual>
    <collision>
      <geometry>
        <mesh filename="package://kinova_description/meshes/jaco2_link_1.dae"/>
      </geometry>
    </collision>
  </link>
  <joint name="right_jaco2_joint_1" type="continuous">
    <parent link="right_jaco2_link_base"/>
    <child link="right_jaco2_link_1"/>
    <axis xyz="0 0 -1"/>
    <limit effort="30" lower="-6.28318530718" upper="6.28318530718" velocity="0.35"/>
    <origin rpy="3.14159265359 0 3.14159265359" xyz="0 0 0.1535"/>
  </joint>
  <link name="right_jaco2_link_2">
    <visual>
      <geometry>
        <mesh filename="package://kinova_description/meshes/jaco2_link_2.dae"/>
      </geometry>
      <material name="carbon_fiber">
        <color rgba="0.792156862745098 0.819607843137255 0.933333333333333 1"/>
      </material>
    </visual>
    <collision>
      <geometry>
        <mesh filename="package://kinova_description/meshes/jaco2_link_2.dae"/>
      </geometry>
    </collision>
  </link>
  <joint name="right_jaco2_joint_2" type="revolute">
    <parent link="right_jaco2_link_1"/>
    <child link="right_jaco2_link_2"/>
    <axis xyz="0 0 1"/>
    <limit effort="30" lower="-3.14159265359" upper="0" velocity="0.35"/>
    <origin rpy="-1.57079632679 3.14159265359 0" xyz="0 0 -0.1185"/>
  </joint>
  <link name="right_jaco2_link_3">
    <visual>
      <geometry>
        <mesh filename="package://kinova_description/meshes/jaco2_link_3.dae"/>
      </geometry>
      <material name="carbon_fiber">
        <color rgba="0.792156862745098 0.819607843137255 0.933333333333333 1"/>
      </material>
    </visual>
    <collision>
      <geometry>
        <mesh filename="package://kinova_description/meshes/jaco2_link_3.dae"/>
      </geometry>
    </collision>
  </link>
  <joint name="right_jaco2_joint_3" type="revolute">
    <parent link="right_jaco2_link_2"/>
    <child link="right_jaco2_link_3"/>
    <axis xyz="0 0 -1"/>
    <limit effort="30" lower="-3.92699081699" upper="0.785398163397" velocity="0.35"/>
    <origin rpy="3.14159265359 0 1.57079632679" xyz="0.41 0 0"/>
  </joint>
  <link name="right_jaco2_link_4">
    <visual>
      <geometry>
        <mesh filename="package://kinova_description/meshes/jaco2_link_4.dae"/>
      </geometry>
      <material name="carbon_fiber">
        <color rgba="0.792156862745098 0.819607843137255 0.933333333333333 1"/>
      </material>
    </visual>
    <collision>
      <geometry>
        <mesh filename="package://kinova_description/meshes/jaco2_link_4.dae"/>
      </geometry>
    </collision>
  </link>
  <joint name="right_jaco2_joint_4" type="continuous">
    <parent link="right_jaco2_link_3"/>
    <child link="right_jaco2_link_4"/>
    <axis xyz="0 0 -1"/>
    <limit effort="30" lower="-6.28318530718" upper="6.28318530718" velocity="0.35"/>
    <origin rpy="3.14159265359 1.57079632679 0" xyz="0.207 0 -0.01125"/>
  </joint>
  <link name="right_jaco2_link_5">
    <visual>
      <geometry>
        <mesh filename="package://kinova_description/meshes/jaco2_link_5.dae"/>
      </geometry>
      <material name="carbon_fiber">
        <color rgba="0.792156862745098 0.819607843137255 0.933333333333333 1"/>
      </material>
    </visual>
    <collision>
      <geometry>
        <mesh filename="package://kinova_description/meshes/jaco2_link_5.dae"/>
      </geometry>
    </collision>
  </link>
  <joint name="right_jaco2_joint_5" type="continuous">
    <parent link="right_jaco2_link_4"/>
    <child link="right_jaco2_link_5"/>
    <axis xyz="0 0 -1"/>
    <limit effort="30" lower="-6.28318530718" upper="6.28318530718" velocity="0.35"/>
    <origin rpy="0 -1.0471975512 0" xyz="0.03700 0 -0.06408"/>
  </joint>
  <link name="right_jaco2_link_hand">
    <visual>
      <geometry>
        <mesh filename="package://kinova_description/meshes/jaco2_link_hand.dae"/>
      </geometry>
      <material name="carbon_fiber">
        <color rgba="0.792156862745098 0.819607843137255 0.933333333333333 1"/>
      </material>
    </visual>
    <collision>
      <geometry>
        <mesh filename="package://kinova_description/meshes/jaco2_link_hand.dae"/>
      </geometry>
    </collision>
  </link>
  <joint name="right_jaco2_joint_6" type="continuous">
    <parent link="right_jaco2_link_5"/>
    <child link="right_jaco2_link_hand"/>
    <axis xyz="0 0 -1"/>
    <limit effort="30" lower="-6.28318530718" upper="6.28318530718" velocity="0.35"/>
    <origin rpy="-1.0471975512 0 1.57079632679" xyz="0.03700 0 -0.06408"/>
  </joint>
  <joint name="right_jaco2_link_base_to_api_origin" type="fixed">
    <parent link="right_jaco2_link_base"/>
    <child link="right_jaco2_api_origin"/>
    <origin rpy="0 0 0" xyz="0 0 0.028"/>
  </joint>
  <link name="right_jaco2_api_origin">
    <!--
         <visual>
           <geometry>
             <box xyz="0 0 0" size="0.1 0.1 0.1"/>
           </geometry>
         </visual>
         <collision>
           <geometry>
             <box xyz="0 0 0" size="0.1 0.1 0.1"/>
           </geometry>
         </collision>
         -->
  </link>
  <joint name="right_jaco2_link_hand_to_end_effector" type="fixed">
    <parent link="right_jaco2_link_hand"/>
    <child link="right_jaco2_end_effector"/>
    <origin rpy="0 3.14159265359 0" xyz="0 0 -0.1687"/>
  </joint>
  <link name="right_jaco2_end_effector"/>
  <link name="right_jaco2_link_finger_1">
    <visual>
      <geometry>
        <mesh filename="package://kinova_description/meshes/jaco2_link_finger_1.dae"/>
      </geometry>
      <material name="carbon_fiber">
        <color rgba="0.792156862745098 0.819607843137255 0.933333333333333 1"/>
      </material>
    </visual>
    <collision>
      <geometry>
        <mesh filename="package://kinova_description/meshes/jaco2_link_finger_1.dae"/>
      </geometry>
    </collision>
  </link>
  <joint name="right_jaco2_joint_finger_1" type="revolute">
    <parent link="right_jaco2_link_hand"/>
    <child link="right_jaco2_link_finger_1"/>
    <axis xyz="0 0 1"/>
    <origin rpy="-1.7983 1.117 3.1416" xyz="-0.03978 0 -0.10071"/>
    <limit effort="30" lower="0" upper="0.698131700798" velocity="5"/>
  </joint>
  <link name="right_jaco2_link_finger_2">
    <visual>
      <geometry>
        <mesh filename="package://kinova_description/meshes/jaco2_link_finger_2.dae"/>
      </geometry>
      <material name="carbon_fiber">
        <color rgba="0.792156862745098 0.819607843137255 0.933333333333333 1"/>
      </material>
    </visual>
    <collision>
      <geometry>
        <mesh filename="package://kinova_description/meshes/jaco2_link_finger_2.dae"/>
      </geometry>
    </collision>
  </link>
  <joint name="right_jaco2_joint_finger_2" type="revolute">
    <parent link="right_jaco2_link_hand"/>
    <child link="right_jaco2_link_finger_2"/>
    <axis xyz="0 0 1"/>
    <origin rpy="-1.6222 1.117 -0.23615" xyz="0.03569 -0.0216 -0.10071"/>
    <limit effort="30" lower="0" upper="0.698131700798" velocity="5"/>
  </joint>
  <link name="right_jaco2_link_finger_3">
    <visual>
      <geometry>
        <mesh filename="package://kinova_description/meshes/jaco2_link_finger_3.dae"/>
      </geometry>
      <material name="carbon_fiber">
        <color rgba="0.792156862745098 0.819607843137255 0.933333333333333 1"/>
      </material>
    </visual>
    <collision>
      <geometry>
        <mesh filename="package://kinova_description/meshes/jaco2_link_finger_3.dae"/>
      </geometry>
    </collision>
  </link>
  <joint name="right_jaco2_joint_finger_3" type="revolute">
    <parent link="right_jaco2_link_hand"/>
    <child link="right_jaco2_link_finger_3"/>
    <axis xyz="0 0 1"/>
    <origin rpy="-1.5161 1.1459 0.23978" xyz="0.03569 0.0216 -0.10071"/>
    <limit effort="30" lower="0" upper="0.698131700798" velocity="5"/>
  </joint>
  <joint name="left_arm_attach" type="fixed">
    <child link="left_arm_mount"/>
    <parent link="base_link"/>
    <origin rpy="0 0 1.5707" xyz="-0.02 0.184 1.086"/>
    <!-- old z was 1.1384 -->
  </joint>
  <joint name="right_arm_attach" type="fixed">
    <child link="right_arm_mount"/>
    <parent link="base_link"/>
    <origin rpy="0 0 1.5707" xyz="-0.02 -0.184 1.086"/>
    <!-- old z was 1.1384 -->
  </joint>
  <!-- PTU 
    The flir_ptu_description package is either from system packages in
    /opt/ros/... or from source repository
    https://github.com/ros-drivers/flir_ptu
  -->
  <link name="ptu_pan_link">
    <!-- <inertial>
        <mass value="0.65" />
        <inertia ... ? />
      </inertial> -->
    <visual>
      <material name="ptu_body_color">
        <color rgba="0.3 0.3 0.3 1.0"/>
      </material>
      <geometry>
        <box size="0.045 0.065 0.044"/>
      </geometry>
      <origin xyz="0 0.011 0"/>
    </visual>
    <visual>
      <geometry>
        <box size="0.046 0.044 0.044"/>
      </geometry>
      <origin xyz="-0.045 0.0215 0"/>
    </visual>
    <visual>
      <geometry>
        <cylinder length="0.015" radius="0.005"/>
      </geometry>
      <origin rpy="0 1.57 0" xyz="-0.074 0.021 0"/>
    </visual>
  </link>
  <link name="ptu_tilt_link">
    <!-- <inertial>
        <mass value="0.65" />
        <inertia ... ? />
      </inertial> -->
    <visual>
      <material name="ptu_body_color">
        <color rgba="0.3 0.3 0.3 1.0"/>
      </material>
      <geometry>
        <box size="0.045 0.065 0.044"/>
      </geometry>
      <origin xyz="0 0.011 0"/>
    </visual>
    <visual>
      <geometry>
        <box size="0.046 0.044 0.044"/>
      </geometry>
      <origin xyz="-0.045 0.0215 0"/>
    </visual>
    <visual>
      <geometry>
        <cylinder length="0.015" radius="0.005"/>
      </geometry>
      <origin rpy="0 1.57 0" xyz="-0.074 0.021 0"/>
    </visual>
  </link>
  <link name="ptu_base_link"/>
  <link name="ptu_tilted_link"/>
  <link name="ptu_mount_link"/>
  <!-- There's an offset between the origin of the pan joint and the origin of 
         the overall device, which is between the mounting screws on its base. -->
  <joint name="ptu_base" type="fixed">
    <parent link="ptu_base_link"/>
    <child link="ptu_pan_link"/>
    <origin xyz="0 -0.011 0.022"/>
  </joint>
  <!-- The pan joint -->
  <joint name="ptu_pan" type="revolute">
    <parent link="ptu_pan_link"/>
    <origin rpy="-1.5708 0 0" xyz="0 0 0.066"/>
    <child link="ptu_tilt_link"/>
    <axis rpy="0 0 0" xyz="0 1 0"/>
    <limit effort="30" lower="2.775" upper="-2.775" velocity="1.0"/>
  </joint>
  <!-- The tilt joint -->
  <joint name="ptu_tilt" type="revolute">
    <parent link="ptu_tilt_link"/>
    <origin rpy="-1.5708 0 0" xyz="0 0 0"/>
    <child link="ptu_tilted_link"/>
    <axis xyz="0 1 0"/>
    <limit effort="30" lower="-0.82" upper="0.52" velocity="1.0"/>
  </joint>
  <!-- Fixed joint to provide a convenient attachment point for accessories. -->
  <joint name="ptu_mount" type="fixed">
    <parent link="ptu_tilted_link"/>
    <child link="ptu_mount_link"/>
    <origin rpy="3.1416 0 0" xyz="0 0 -0.03912"/>
  </joint>
  <joint name="ptu_base_mount" type="fixed">
    <parent link="plinth"/>
    <child link="ptu_base_link"/>
    <origin xyz="0.152 0.03 0.91"/>
  </joint>
  <!-- kinect -->
  <link name="kinect">
    <visual name="kinect_visual">
      <geometry name="kinect_visual_geom">
        <box size="0.07 0.25 0.065"/>
        <origin xyz="0.03 0 0.035"/>
      </geometry>
      <material name="kinect_black_mat">
        <color rgba="0.0 0.0 0.0 1.0"/>
      </material>
    </visual>
    <collision name="kinect_collision">
      <geometry name="kinect_visual_geom">
        <box size="0.07 0.25 0.065"/>
        <origin xyz="0.03 0 0.035"/>
      </geometry>
    </collision>
  </link>
  <joint name="kinect_mount" type="fixed">
    <parent link="ptu_mount_link"/>
    <child link="kinect"/>
    <origin xyz="0 0 0.0325"/>
  </joint>
  <!-- hack for depthimage_to_laserscan (todo: configure depthimage_to_laserscan to use "kinect" as frame -->
  <link name="camera_depth_frame">
    <origin xyz="0 0 0"/>
    <inertial>
      <mass value="0.0"/>
      <inertia ixx="1" ixy="0" ixz="0" iyy="1" iyz="0" izz="1"/>
    </inertial>
  </link>
  <joint name="camera_depth_frame_joint" type="fixed">
    <parent link="kinect"/>
    <child link="camera_depth_frame"/>
    <origin xyz="0 0 0"/>
  </joint>
</robot>

