<?xml version="1.0" ?>
<!-- =================================================================================== -->
<!-- |    This document was autogenerated by xacro from ./robots/r2_left_forearm.xacro | -->
<!-- |    EDITING THIS FILE BY HAND IS NOT RECOMMENDED                                 | -->
<!-- =================================================================================== -->
<robot name="r2" xmlns:xacro="http://www.ros.org/wiki/xacro">
  <link name="r2/world_ref"/>
  <joint name="r2/fixed/world_ref/robot_world" type="fixed">
    <parent link="r2/world_ref"/>
    <child link="r2/robot_world"/>
    <origin rpy="0 0 0" xyz="0 0 0"/>
  </joint>
  <joint name="r2/fixed/robot_world/left_arm" type="fixed">
    <parent link="r2/robot_world"/>
    <child link="r2/left_lower_arm"/>
    <origin rpy="0 0 0" xyz="0.0 0.0 0.0"/>
  </joint>
  <link name="r2/robot_world">
    <inertial>
      <mass value="0.01"/>
      <inertia ixx="0.0001" ixy="0.0" ixz="0.0" iyy="0.0001" iyz="0.0" izz="0.0001"/>
    </inertial>
  </link>
  <joint name="r2/fixed/robot_world/robot_base" type="fixed">
    <parent link="r2/robot_world"/>
    <child link="r2/robot_base"/>
    <origin rpy="0.0 3.14159 3.14159" xyz="0.0 0.0 0.0"/>
  </joint>
  <link name="r2/robot_base">
    <inertial>
      <mass value="0.01"/>
      <inertia ixx="0.0001" ixy="0.0" ixz="0.0" iyy="0.0001" iyz="0.0" izz="0.0001"/>
    </inertial>
  </link>
  <material name="white">
    <color rgba="1.0 1.0 1.0 1.0"/>
  </material>
  <material name="dirty_white">
    <color rgba="0.322 0.322 0.322 1.0"/>
  </material>
  <material name="gold">
    <color rgba=".878 .49 0.008 1"/>
  </material>
  <material name="steel">
    <color rgba=".7 .7 .7 1"/>
  </material>
  <material name="blue">
    <color rgba="0 0 0.8 1"/>
  </material>
  <link name="r2/left_lower_arm">
    <visual>
      <geometry>
        <mesh filename="package://r2_description/meshes/r2_upperbody/Left_Forearm.dae"/>
      </geometry>
      <material name="dirty_white"/>
      <origin rpy="0 0 1.5708" xyz="0 0.0 0.0458777"/>
    </visual>
    <collision>
      <geometry>
        <mesh filename="package://r2_description/meshes/r2_upperbody/Left_Forearm.dae"/>
      </geometry>
      <origin rpy="0 0 1.5708" xyz="0 0.0 0.0458777"/>
    </collision>
    <inertial>
      <origin xyz="0.0039950818 0.00044312736  0.16275601"/>
      <mass value="8.1525875"/>
      <inertia ixx="0.10706156" ixy="0.00070538028" ixz="-0.0061176777" iyy="0.11007507" iyz="0.0020551081" izz="0.015240452"/>
    </inertial>
  </link>
  <joint name="r2/left_arm/wrist/pitch" type="revolute">
    <parent link="r2/left_lower_arm"/>
    <child link="r2/left_wrist_pitch"/>
    <origin rpy="0 -1.5708 0.0 " xyz="0.000616510 0 0.301768"/>
    <axis xyz="0 0 1"/>
    <dynamics damping="1.0" friction="0.0"/>
    <limit effort="100.0" lower="-0.8" upper="0.8" velocity="1000"/>
  </joint>
  <link name="r2/left_wrist_pitch">
    <inertial>
      <origin xyz="0.0 0.0 0.0"/>
      <mass value="0.01"/>
      <inertia ixx="0.0001" ixy="0.0" ixz="0.0" iyy="0.0001" iyz="0.0" izz="0.0001"/>
    </inertial>
  </link>
  <joint name="r2/left_arm/wrist/yaw" type="revolute">
    <parent link="r2/left_wrist_pitch"/>
    <child link="r2/left_wrist_yaw"/>
    <origin rpy="1.5708 0.0646 -0.0802" xyz="0.00635 0 0.00041451"/>
    <axis xyz="0 0 1"/>
    <dynamics damping="1.0" friction="0.0"/>
    <limit effort="100.0" lower="-0.75" upper="0.15" velocity="1000"/>
  </joint>
  <link name="r2/left_wrist_yaw">
    <inertial>
      <origin xyz="0.0 0.0 0.0"/>
      <mass value="0.01"/>
      <inertia ixx="0.0001" ixy="0.0" ixz="0.0" iyy="0.0001" iyz="0.0" izz="0.0001"/>
    </inertial>
  </link>
  <joint name="r2/fixed/left_wrist_yaw/left_palm" type="fixed">
    <parent link="r2/left_wrist_yaw"/>
    <child link="r2/left_palm"/>
    <origin rpy=" 0.0 0.0 0" xyz=" 0.0 0.0 0.0 "/>
  </joint>
  <link name="r2/left_palm">
    <visual>
      <geometry>
        <mesh filename="package://r2_description/meshes/r2_upperbody/Left_Palm.dae"/>
      </geometry>
      <origin rpy="3.1416 0 1.5708" xyz="0.0 0.0 0.0"/>
    </visual>
    <collision>
      <geometry>
        <mesh filename="package://r2_description/meshes/r2_upperbody/Left_Palm.dae"/>
      </geometry>
      <origin rpy="3.1416 0 1.5708" xyz="0.0 0.0 0.0"/>
    </collision>
    <inertial>
      <mass value="0.01"/>
      <inertia ixx="0.0001" ixy="0.0" ixz="0.0" iyy="0.0001" iyz="0.0" izz="0.0001"/>
    </inertial>
  </link>
  <!--
  <property name="left_arm_hand_index_j3_damping" value= "0.1" />
  <property name="left_arm_hand_index_j3_friction" value= "0.0" />
-->
  <!--
  <property name="left_arm_hand_middle_j3_damping" value= "0.1" />
  <property name="left_arm_hand_middle_j3_friction" value= "0.0" />
-->
  <!--
  <property name="left_arm_hand_ring_j1_damping" value= "0.1" />
  <property name="left_arm_hand_ring_j1_friction" value= "0.0" />
  <property name="left_arm_hand_ring_j2_damping" value= "0.1" />
  <property name="left_arm_hand_ring_j2_friction" value= "0.0" />
-->
  <!--
  <property name="left_arm_hand_little_j1_damping" value= "0.1" />
  <property name="left_arm_hand_little_j1_friction" value= "0.0" />
  <property name="left_arm_hand_little_j2_damping" value= "0.1" />
  <property name="left_arm_hand_little_j2_friction" value= "0.0" />
-->
  <joint name="r2/left_arm/hand/thumb/roll" type="revolute">
    <parent link="r2/left_wrist_yaw"/>
    <child link="r2/left_thumb_base"/>
    <origin rpy=" -1.5708 0.0 1.30899702752 " xyz=" 0.03302 0.03048 0.00635 "/>
    <axis xyz="0 0 1"/>
    <limit effort="10000000.0" lower="-4" upper="4" velocity="1000"/>
    <dynamics damping="0.1" friction="0.0"/>
  </joint>
  <joint name="r2/fixed/left_index_base/left_index_base" type="fixed">
    <parent link="r2/left_wrist_yaw"/>
    <child link="r2/left_index_base"/>
    <origin rpy=" 0.0 0.0 0.122172725275 " xyz=" 0.0994646728 0.0271119346 -0.0161544 "/>
  </joint>
  <joint name="r2/left_arm/hand/index/yaw" type="revolute">
    <parent link="r2/left_index_base"/>
    <child link="r2/left_index_yaw"/>
    <origin rpy="0.0 0.0 0.0" xyz="0.0 0.0 0.0"/>
    <axis xyz="0 0 1"/>
    <limit effort="10000000.0" lower="-4" upper="4" velocity="1000"/>
    <dynamics damping="0.1" friction="0.0"/>
  </joint>
  <joint name="r2/fixed/left_middle_base/left_middle_base" type="fixed">
    <parent link="r2/left_wrist_yaw"/>
    <child link="r2/left_middle_base"/>
    <origin rpy=" 0.0 0.0 0.0 " xyz=" 0.10646537 0.00254 -0.0161544 "/>
  </joint>
  <joint name="r2/left_arm/hand/middle/yaw" type="revolute">
    <parent link="r2/left_middle_base"/>
    <child link="r2/left_middle_yaw"/>
    <origin rpy="0.0 0.0 0.0" xyz="0.0 0.0 0.0"/>
    <axis xyz="0 0 1"/>
    <limit effort="10000000.0" lower="-4" upper="4" velocity="1000"/>
    <dynamics damping="0.1" friction="0.0"/>
  </joint>
  <joint name="r2/left_arm/hand/ringlittle/ring" type="revolute">
    <parent link="r2/left_wrist_yaw"/>
    <child link="r2/left_ring_proximal"/>
    <origin rpy=" 1.5708 -0.0 -0.122172725275 " xyz=" 0.1084570602 -0.0197673468 -0.012319 "/>
    <axis xyz="0 0 1"/>
    <limit effort="10000000.0" lower="-4" upper="4" velocity="1000"/>
    <dynamics damping="0.1" friction="0.0"/>
  </joint>
  <joint name="r2/left_arm/hand/ringlittle/little" type="revolute">
    <parent link="r2/left_wrist_yaw"/>
    <child link="r2/left_little_proximal"/>
    <origin rpy=" 1.60570321374 -0.0872667473393 -0.17453258148 " xyz=" 0.094635701 -0.0403792436 -0.0060878212 "/>
    <axis xyz="0 0 1"/>
    <limit effort="10000000.0" lower="-4" upper="4" velocity="1000"/>
    <dynamics damping="0.1" friction="0.0"/>
  </joint>
  <link name="r2/left_thumb_base">
    <inertial>
      <mass value=".05"/>
      <inertia ixx=".0010" ixy="0.0" ixz="0.0" iyy=".0010" iyz="0.0" izz=".0010"/>
    </inertial>
  </link>
  <joint name="r2/fixed/left_thumb_base/left_thumb_proximal" type="fixed">
    <parent link="r2/left_thumb_base"/>
    <child link="r2/left_thumb_proximal"/>
    <origin rpy=" -1.5708 -0.0 0.0 " xyz=" 0.011938 0.0 0.0 "/>
  </joint>
  <link name="r2/left_thumb_proximal">
    <inertial>
      <mass value=".0010"/>
      <inertia ixx=".0010" ixy="0.0" ixz="0.0" iyy=".0010" iyz="0.0" izz=".0010"/>
    </inertial>
    <visual>
      <geometry>
        <mesh filename="package://r2_description/meshes/r2_upperbody/Left_Thumb_Carp.dae"/>
      </geometry>
      <origin rpy="-1.5708 0 0" xyz="-0.01 0.0 0.0"/>
    </visual>
    <collision>
      <geometry>
        <mesh filename="package://r2_description/meshes/r2_upperbody/Left_Thumb_Carp.dae"/>
      </geometry>
      <origin rpy="-1.5708 0 0" xyz="-0.01 0.0 0.0"/>
    </collision>
  </link>
  <joint name="r2/left_arm/hand/thumb/proximal" type="revolute">
    <parent link="r2/left_thumb_proximal"/>
    <child link="r2/left_thumb_medial_prime"/>
    <origin rpy=" 0.0 0.0 0.0 " xyz=" 0.0 0.0 0.0 "/>
    <axis xyz="0 0 1"/>
    <limit effort="10000000.0" lower="-4" upper="4" velocity="1000"/>
    <dynamics damping="0.1" friction="0.0"/>
  </joint>
  <link name="r2/left_thumb_medial_prime">
    <inertial>
      <mass value=".0010"/>
      <inertia ixx=".0010" ixy="0.0" ixz="0.0" iyy=".0010" iyz="0.0" izz=".0010"/>
    </inertial>
    <visual>
      <geometry>
        <mesh filename="package://r2_description/meshes/r2_upperbody/Left_Thumb_MtCar.dae"/>
      </geometry>
      <origin rpy="-1.5708 -1.5708 0" xyz="-0.0 0 0.0"/>
    </visual>
    <collision>
      <geometry>
        <mesh filename="package://r2_description/meshes/r2_upperbody/Left_Thumb_MtCar.dae"/>
      </geometry>
      <origin rpy="-1.5708 -1.5708 0" xyz="0.0 0.0 0.0"/>
    </collision>
  </link>
  <joint name="r2/left_arm/hand/thumb/medial" type="revolute">
    <parent link="r2/left_thumb_medial_prime"/>
    <child link="r2/left_thumb_medial"/>
    <origin rpy=" -0.698132284627 -0.0 0.0 " xyz=" 0.030734 -0.001905 0.00254 "/>
    <axis xyz="0 0 1"/>
    <limit effort="10000000.0" lower="-4" upper="4" velocity="1000"/>
    <dynamics damping="0.1" friction="0.0"/>
  </joint>
  <link name="r2/left_thumb_medial">
    <inertial>
      <mass value=".0010"/>
      <inertia ixx=".0010" ixy="0.0" ixz="0.0" iyy=".0010" iyz="0.0" izz=".0010"/>
    </inertial>
    <visual>
      <geometry>
        <mesh filename="package://r2_description/meshes/r2_upperbody/Thumb_Proximal.dae"/>
      </geometry>
      <origin rpy="3.1416 0 1.5708" xyz="0.0 0.0 0.0"/>
    </visual>
    <collision>
      <geometry>
        <mesh filename="package://r2_description/meshes/r2_upperbody/Thumb_Proximal.dae"/>
      </geometry>
      <origin rpy="3.1416 0 1.5708" xyz="0.0 0.0 0.0"/>
    </collision>
  </link>
  <joint name="r2/left_arm/hand/thumb/distal" type="revolute">
    <parent link="r2/left_thumb_medial"/>
    <child link="r2/left_thumb_distal"/>
    <origin rpy=" 0.0 0.0 0.0 " xyz=" 0.03937 0.0 0.0 "/>
    <axis xyz="0 0 1"/>
    <limit effort="10000000.0" lower="-4" upper="4" velocity="1000"/>
    <dynamics damping="0.1" friction="0.0"/>
  </joint>
  <link name="r2/left_thumb_distal">
    <inertial>
      <mass value=".0010"/>
      <inertia ixx=".0010" ixy="0.0" ixz="0.0" iyy=".0010" iyz="0.0" izz=".0010"/>
    </inertial>
    <visual>
      <geometry>
        <mesh filename="package://r2_description/meshes/r2_upperbody/Thumb_Dist.dae"/>
      </geometry>
      <origin rpy="3.1416 3.1416 0" xyz="0.0 0.0 0.0"/>
    </visual>
    <collision>
      <geometry>
        <mesh filename="package://r2_description/meshes/r2_upperbody/Thumb_Dist.dae"/>
      </geometry>
      <origin rpy="3.1416 3.1416 0" xyz="0.0 0.0 0.0"/>
    </collision>
  </link>
  <joint name="r2/fixed/left_thumb_distal/left_thumb_tip" type="fixed">
    <parent link="r2/left_thumb_distal"/>
    <child link="r2/left_thumb_tip"/>
    <origin rpy=" 0.0 0.0 0.0 " xyz=" 0.03302 0.0 0.0 "/>
  </joint>
  <link name="r2/left_thumb_tip">
    <inertial>
      <mass value=".0010"/>
      <inertia ixx=".0010" ixy="0.0" ixz="0.0" iyy=".0010" iyz="0.0" izz=".0010"/>
    </inertial>
  </link>
  <link name="r2/left_index_base">
    <inertial>
      <mass value=".0010"/>
      <inertia ixx=".0010" ixy="0.0" ixz="0.0" iyy=".0010" iyz="0.0" izz=".0010"/>
    </inertial>
  </link>
  <link name="r2/left_index_yaw">
    <inertial>
      <mass value=".0010"/>
      <inertia ixx=".0010" ixy="0.0" ixz="0.0" iyy=".0010" iyz="0.0" izz=".0010"/>
    </inertial>
  </link>
  <joint name="r2/left_arm/hand/index/proximal" type="revolute">
    <parent link="r2/left_index_yaw"/>
    <child link="r2/left_index_proximal"/>
    <origin rpy=" 1.5708 0.0 0.0 " xyz=" 0.009652 0.0 0.0 "/>
    <axis xyz="0 0 1"/>
    <limit effort="10000000.0" lower="-4" upper="4" velocity="1000"/>
    <dynamics damping="0.1" friction="0.0"/>
  </joint>
  <link name="r2/left_index_proximal">
    <inertial>
      <mass value=".0010"/>
      <inertia ixx=".0010" ixy="0.0" ixz="0.0" iyy=".0010" iyz="0.0" izz=".0010"/>
    </inertial>
    <visual>
      <geometry>
        <mesh filename="package://r2_description/meshes/r2_upperbody/Finger_Proximal.dae"/>
      </geometry>
      <origin rpy="0 0 1.5708" xyz="0.0 0.0 0.0"/>
    </visual>
    <collision>
      <geometry>
        <mesh filename="package://r2_description/meshes/r2_upperbody/Finger_Proximal.dae"/>
      </geometry>
      <origin rpy="0 0 1.5708" xyz="0.0 0.0 0.0"/>
    </collision>
  </link>
  <joint name="r2/left_arm/hand/index/medial" type="revolute">
    <parent link="r2/left_index_proximal"/>
    <child link="r2/left_index_medial"/>
    <origin rpy=" 0.0 0.0 0.0 " xyz=" 0.04445 0.0 0.0 "/>
    <axis xyz="0 0 1"/>
    <limit effort="10000000.0" lower="-4" upper="4" velocity="1000"/>
    <dynamics damping="0.1" friction="0.0"/>
  </joint>
  <link name="r2/left_index_medial">
    <inertial>
      <mass value=".0010"/>
      <inertia ixx=".0010" ixy="0.0" ixz="0.0" iyy=".0010" iyz="0.0" izz=".0010"/>
    </inertial>
    <visual>
      <geometry>
        <mesh filename="package://r2_description/meshes/r2_upperbody/Finger_Mid.dae"/>
      </geometry>
      <origin rpy="3.1416 0 1.5708" xyz="0.0 0.0 0.0"/>
    </visual>
    <collision>
      <geometry>
        <mesh filename="package://r2_description/meshes/r2_upperbody/Finger_Mid.dae"/>
      </geometry>
      <origin rpy="3.1416 0 1.5708" xyz="0.0 0.0 0.0"/>
    </collision>
  </link>
  <link name="r2/left_middle_base">
    <inertial>
      <mass value=".0010"/>
      <inertia ixx=".0010" ixy="0.0" ixz="0.0" iyy=".0010" iyz="0.0" izz=".0010"/>
    </inertial>
  </link>
  <link name="r2/left_middle_yaw">
    <inertial>
      <mass value=".0010"/>
      <inertia ixx=".0010" ixy="0.0" ixz="0.0" iyy=".0010" iyz="0.0" izz=".0010"/>
    </inertial>
  </link>
  <joint name="r2/left_arm/hand/middle/proximal" type="revolute">
    <parent link="r2/left_middle_yaw"/>
    <child link="r2/left_middle_proximal"/>
    <origin rpy=" 1.5708 0.0 0.0 " xyz=" 0.009652 0.0 0.0 "/>
    <axis xyz="0 0 1"/>
    <limit effort="10000000.0" lower="-4" upper="4" velocity="1000"/>
    <dynamics damping="0.1" friction="0.0"/>
  </joint>
  <link name="r2/left_middle_proximal">
    <inertial>
      <mass value=".0010"/>
      <inertia ixx=".0010" ixy="0.0" ixz="0.0" iyy=".0010" iyz="0.0" izz=".0010"/>
    </inertial>
    <visual>
      <geometry>
        <mesh filename="package://r2_description/meshes/r2_upperbody/Finger_Proximal.dae"/>
      </geometry>
      <origin rpy="0 0 1.5708" xyz="0.0 0.0 0.0"/>
    </visual>
    <collision>
      <geometry>
        <mesh filename="package://r2_description/meshes/r2_upperbody/Finger_Proximal.dae"/>
      </geometry>
      <origin rpy="0 0 1.5708" xyz="0.0 0.0 0.0"/>
    </collision>
  </link>
  <joint name="r2/left_arm/hand/middle/medial" type="revolute">
    <parent link="r2/left_middle_proximal"/>
    <child link="r2/left_middle_medial"/>
    <origin rpy=" 0.0 0.0 0.0 " xyz=" 0.04445 0.0 0.0 "/>
    <axis xyz="0 0 1"/>
    <limit effort="10000000.0" lower="-4" upper="4" velocity="1000"/>
    <dynamics damping="0.1" friction="0.0"/>
  </joint>
  <link name="r2/left_middle_medial">
    <inertial>
      <mass value=".0010"/>
      <inertia ixx=".0010" ixy="0.0" ixz="0.0" iyy=".0010" iyz="0.0" izz=".0010"/>
    </inertial>
    <visual>
      <geometry>
        <mesh filename="package://r2_description/meshes/r2_upperbody/Finger_Mid.dae"/>
      </geometry>
      <origin rpy="3.1416 0 1.5708" xyz="0.0 0.0 0.0"/>
    </visual>
    <collision>
      <geometry>
        <mesh filename="package://r2_description/meshes/r2_upperbody/Finger_Mid.dae"/>
      </geometry>
      <origin rpy="3.1416 0 1.5708" xyz="0.0 0.0 0.0"/>
    </collision>
  </link>
  <link name="r2/left_ring_proximal">
    <inertial>
      <mass value=".0010"/>
      <inertia ixx=".0010" ixy="0.0" ixz="0.0" iyy=".0010" iyz="0.0" izz=".0010"/>
    </inertial>
    <visual>
      <geometry>
        <mesh filename="package://r2_description/meshes/r2_upperbody/Finger_Proximal.dae"/>
      </geometry>
      <origin rpy="0 0 1.5708" xyz="0.0 0.0 0.0"/>
    </visual>
    <collision>
      <geometry>
        <mesh filename="package://r2_description/meshes/r2_upperbody/Finger_Proximal.dae"/>
      </geometry>
      <origin rpy="0 0 1.5708" xyz="0.0 0.0 0.0"/>
    </collision>
  </link>
  <link name="r2/left_little_proximal">
    <inertial>
      <mass value=".0010"/>
      <inertia ixx=".0010" ixy="0.0" ixz="0.0" iyy=".0010" iyz="0.0" izz=".0010"/>
    </inertial>
    <visual>
      <geometry>
        <mesh filename="package://r2_description/meshes/r2_upperbody/Finger_Proximal.dae"/>
      </geometry>
      <origin rpy="0 0 1.5708" xyz="0.0 0.0 0.0"/>
    </visual>
    <collision>
      <geometry>
        <mesh filename="package://r2_description/meshes/r2_upperbody/Finger_Proximal.dae"/>
      </geometry>
      <origin rpy="0 0 1.5708" xyz="0.0 0.0 0.0"/>
    </collision>
  </link>
</robot>
