<?xml version="1.0" ?>
<!-- =================================================================================== -->
<!-- |    This document was autogenerated by xacro from ./robots/r2c5_control.xacro    | -->
<!-- |    EDITING THIS FILE BY HAND IS NOT RECOMMENDED                                 | -->
<!-- =================================================================================== -->
<robot name="r2" xmlns:xacro="http://www.ros.org/wiki/xacro">
  <link name="r2/world_ref"/>
  <joint name="r2/fixed/world_ref/robot_world" type="fixed">
    <parent link="r2/world_ref"/>
    <child link="r2/robot_world"/>
    <origin rpy="0 0 0" xyz="0 0 0"/>
  </joint>
  <link name="r2/robot_world">
    <inertial>
      <mass value="0.01"/>
      <inertia ixx="0.0001" ixy="0.0" ixz="0.0" iyy="0.0001" iyz="0.0" izz="0.0001"/>
    </inertial>
  </link>
  <joint name="r2/fixed/robot_world/robot_base" type="fixed">
    <parent link="r2/robot_world"/>
    <child link="r2/robot_base"/>
    <origin rpy="0.0 3.14159 3.14159" xyz="0.0 0.0 0.0"/>
  </joint>
  <link name="r2/robot_base">
    <inertial>
      <mass value="0.01"/>
      <inertia ixx="0.0001" ixy="0.0" ixz="0.0" iyy="0.0001" iyz="0.0" izz="0.0001"/>
    </inertial>
  </link>
  <material name="white">
    <color rgba="1.0 1.0 1.0 1.0"/>
  </material>
  <material name="dirty_white">
    <color rgba="0.322 0.322 0.322 1.0"/>
  </material>
  <material name="gold">
    <color rgba=".878 .49 0.008 1"/>
  </material>
  <material name="steel">
    <color rgba=".7 .7 .7 1"/>
  </material>
  <material name="blue">
    <color rgba="0 0 0.8 1"/>
  </material>
  <joint name="r2/fixed/robot_base/waist_mass" type="fixed">
    <parent link="r2/robot_base"/>
    <child link="r2/waist_mass"/>
    <origin rpy="0.0 0 0.0" xyz="0.0 0.0 -0.086855"/>
  </joint>
  <link name="r2/waist_mass">
    <inertial>
      <mass value="4.6259465"/>
      <origin rpy="0.0 0 0.0" xyz="-0.00012809088 0.000041480778 0.039080994"/>
      <inertia ixx="0.01684448" ixy="0.00021529806" ixz="-0.0000036013959" iyy="0.017313387" iyz="0.0" izz="0.028769348"/>
    </inertial>
  </link>
  <joint name="r2/waist/joint0" type="revolute">
    <parent link="r2/robot_base"/>
    <child link="r2/waist_center"/>
    <axis xyz="0 0 1"/>
    <origin rpy="0.0 0 0.0" xyz="0.0 0.0 0.0"/>
    <dynamics damping="10.0" friction="0.0"/>
    <limit effort="10000000.0" lower="-3.14" upper="3.14" velocity="1000"/>
  </joint>
  <!--includes mass properties of all torso componenents-->
  <link name="r2/waist_center">
    <visual>
      <geometry>
        <mesh filename="package://r2_description/meshes/r2_upperbody/Body.dae"/>
      </geometry>
      <origin rpy="-1.5708 0 -1.5708" xyz="0.02 0.05 -0.5625"/>
    </visual>
    <collision>
      <geometry>
        <mesh filename="package://r2_description/meshes/r2_upperbody/Body.dae"/>
      </geometry>
      <origin rpy="-1.5708 0 -1.5708" xyz="0.02 0.05 -0.5625"/>
    </collision>
    <inertial>
      <mass value="47.770842"/>
      <origin rpy="0.0 0 0.0" xyz="-0.020473299 0.0039268948 -0.36456539"/>
      <inertia ixx="1.9926945" ixy="-0.0069480619" ixz="-0.059104048" iyy="1.8449528" iyz="0.01958974" izz="0.69736445"/>
    </inertial>
  </link>
  <joint name="r2/fixed/waist_center/robot_reference" type="fixed">
    <parent link="r2/waist_center"/>
    <child link="r2/robot_reference"/>
    <origin rpy="0.0 0 0.0" xyz="0.1234 0.0 0.0"/>
  </joint>
  <joint name="r2/fixed/waist_center/body_cover" type="fixed">
    <parent link="r2/waist_center"/>
    <child link="r2/body_cover"/>
    <origin rpy="0.0 0.0 0.0" xyz="0 0.0 0.0"/>
  </joint>
  <joint name="r2/fixed/waist_center/backpack" type="fixed">
    <parent link="r2/waist_center"/>
    <child link="r2/backpack"/>
    <origin rpy="0.0 0.0 0.0" xyz="-0.145521 0.0 -0.421894"/>
  </joint>
  <joint name="r2/fixed/waist_center/left_shoulder_jr3" type="fixed">
    <parent link="r2/waist_center"/>
    <child link="r2/left_arm/shoulder/jr3"/>
    <origin rpy="0.0 0.0 1.8326" xyz="-0.0240898 -0.0996837 -0.413899"/>
  </joint>
  <joint name="r2/fixed/waist_center/right_shoulder_jr3" type="fixed">
    <parent link="r2/waist_center"/>
    <child link="r2/right_arm/shoulder/jr3"/>
    <origin rpy="0.0 0.0 -1.83259" xyz="-0.0240898 0.0996837 -0.413899"/>
  </joint>
  <link name="r2/robot_reference">
    <inertial>
      <mass value="0.01"/>
      <inertia ixx="0.0001" ixy="0.0" ixz="0.0" iyy="0.0001" iyz="0.0" izz="0.0001"/>
    </inertial>
  </link>
  <link name="r2/body_cover">
    <visual>
      <geometry>
        <mesh filename="package://r2_description/meshes/r2_upperbody/Body_Cover.dae"/>
      </geometry>
      <origin rpy="-1.5708 0 -1.5708" xyz="0.02 0.05 -0.5625"/>
    </visual>
    <collision>
      <geometry>
        <mesh filename="package://r2_description/meshes/r2_upperbody/Body_Cover.dae"/>
      </geometry>
      <origin rpy="-1.5708 0 -1.5708" xyz="0.02 0.05 -0.5625"/>
    </collision>
    <inertial>
      <mass value="0.1"/>
      <inertia ixx="0.001" ixy="0.0" ixz="0.0" iyy="0.001" iyz="0.0" izz="0.001"/>
    </inertial>
  </link>
  <link name="r2/backpack">
    <visual>
      <geometry>
        <mesh filename="package://r2_description/meshes/r2_upperbody/Backpack.dae"/>
      </geometry>
      <origin rpy="0 0 0.25" xyz="0.145521 0.0 -0.118106"/>
    </visual>
    <collision>
      <geometry>
        <mesh filename="package://r2_description/meshes/r2_upperbody/Backpack.dae"/>
      </geometry>
      <origin rpy="0 0 0.25" xyz="0.145521 0.0 -0.118106"/>
    </collision>
    <inertial>
      <mass value="23.505356"/>
      <origin rpy="0.0 0 0.0" xyz="-0.068110236 0.00026288234 -0.015523324"/>
      <inertia ixx="0.87608758" ixy="0.0031949152" ixz="-0.0042079052" iyy="0.57168416" iyz="0.0067562903" izz="0.41612859"/>
    </inertial>
  </link>
  <link name="r2/left_arm/shoulder/jr3">
    <inertial>
      <mass value="0.01"/>
      <inertia ixx="0.0001" ixy="0.0" ixz="0.0" iyy="0.0001" iyz="0.0" izz="0.0001"/>
    </inertial>
  </link>
  <link name="r2/right_arm/shoulder/jr3">
    <inertial>
      <mass value="0.01"/>
      <inertia ixx="0.0001" ixy="0.0" ixz="0.0" iyy="0.0001" iyz="0.0" izz="0.0001"/>
    </inertial>
  </link>
  <link name="r2/imu">
    <inertial>
      <mass value="0.01"/>
      <inertia ixx="0.0001" ixy="0.0" ixz="0.0" iyy="0.0001" iyz="0.0" izz="0.0001"/>
    </inertial>
  </link>
  <joint name="r2/fixed/robot_base/imu" type="fixed">
    <parent link="r2/waist_center"/>
    <child link="r2/imu"/>
    <origin rpy="1.5708 0 0" xyz="0.017351 -0.116179 -0.112236"/>
  </joint>
  <joint name="r2/neck/joint0" type="revolute">
    <parent link="r2/waist_center"/>
    <child link="r2/neck_lower"/>
    <origin rpy=" -1.5708 0.0 0.0 " xyz=" 0.08636 -0.0285749 -0.614172 "/>
    <dynamics damping="10.0" friction="0.0"/>
    <axis xyz="0 0 1"/>
    <limit effort="10000.0" lower="-0.7" upper="0.175" velocity="1000.0"/>
  </joint>
  <link name="r2/neck_lower">
    <visual>
      <geometry>
        <mesh filename="package://r2_description/meshes/r2_upperbody/Neck_Lower.dae"/>
      </geometry>
      <origin rpy="-1.5708 1.5708 0" xyz="0.0 0.0 0.0285749"/>
    </visual>
    <inertial>
      <mass value="1.531125"/>
      <origin rpy="0 0 0" xyz="-0.044614256 0.031785824 0.021419445"/>
      <inertia ixx="0.0032988044" ixy="0.0014889073" ixz="0.0004970659" iyy="0.0050478224" iyz="-0.00036827305" izz="0.0052160286"/>
    </inertial>
    <collision>
      <geometry>
        <mesh filename="package://r2_description/meshes/r2_upperbody/Neck_Lower.dae"/>
      </geometry>
      <origin rpy="-1.5708 1.5708 0" xyz="0.0 0.0 0.0285749"/>
    </collision>
  </link>
  <joint name="r2/neck/joint1" type="revolute">
    <parent link="r2/neck_lower"/>
    <child link="r2/neck_upper"/>
    <origin rpy=" -1.5708 0.0 0.0 " xyz=" -0.0762002 0.0762004 0.028575"/>
    <dynamics damping="10.0" friction="0.0"/>
    <axis xyz="0 0 1"/>
    <limit effort="10000.0" lower="-1.22" upper="1.22" velocity="1000.0"/>
  </joint>
  <link name="r2/neck_upper">
    <visual>
      <geometry>
        <mesh filename="package://r2_description/meshes/r2_upperbody/Neck_Upper.dae"/>
      </geometry>
      <origin rpy="0 0 1.5708" xyz="0.0762002 0 -0.0762004"/>
    </visual>
    <inertial>
      <mass value="2.234558"/>
      <origin rpy="0 0 0" xyz="0.0127259 0.0072291452 0.048896507"/>
      <inertia ixx="0.0074125667" ixy="-0.00042898316" ixz="-0.0014528455" iyy="0.0080268117" iyz="-0.00076230267" izz="0.00051467581"/>
    </inertial>
    <collision>
      <geometry>
        <mesh filename="package://r2_description/meshes/r2_upperbody/Neck_Upper.dae"/>
      </geometry>
      <origin rpy="0 0 1.5708" xyz="0.0762002 0 -0.0762004"/>
    </collision>
  </link>
  <joint name="r2/neck/joint2" type="revolute">
    <parent link="r2/neck_upper"/>
    <child link="r2/head"/>
    <origin rpy=" 1.5708 0.0 0.0 " xyz="0.0508 0.0074676 0.101587"/>
    <dynamics damping="10.0" friction="0.0"/>
    <axis xyz="0 0 1"/>
    <limit effort="10000.0" lower="-0.7" upper="0.175" velocity="1000.0"/>
  </joint>
  <link name="r2/head">
    <visual>
      <geometry>
        <mesh filename="package://r2_description/meshes/r2_upperbody/Head.dae"/>
      </geometry>
      <origin rpy="0 1.5708 0" xyz="0.0 0.07 0.0074676"/>
    </visual>
    <collision>
      <geometry>
        <mesh filename="package://r2_description/meshes/r2_upperbody/Head.dae"/>
      </geometry>
      <origin rpy="0 1.5708 0" xyz="0.0 0.07 0.0074676"/>
    </collision>
    <inertial>
      <mass value="5.8503785"/>
      <origin rpy="0 0 0" xyz="0.0048289919 0.074486518 0.013796703"/>
      <inertia ixx="0.045520172" ixy="0.0076844267" ixz="0.0005272352" iyy="0.035519354" iyz="0.001323319" izz="0.044699541"/>
    </inertial>
  </link>
  <joint name="r2/fixed/head/vision_base" type="fixed">
    <parent link="r2/head"/>
    <child link="r2/head/vision_base"/>
    <origin rpy=" 1.5708 0.0 0.0 " xyz=" 0.0 -0.058 0.0074676"/>
  </joint>
  <link name="r2/head/vision_base">
    <inertial>
      <mass value=".1"/>
      <inertia ixx=".0010" ixy="0.0" ixz="0.0" iyy=".0010" iyz="0.0" izz=".0010"/>
    </inertial>
  </link>
  <joint name="r2/fixed/head/vision_base/asus_frame" type="fixed">
    <parent link="r2/head/vision_base"/>
    <child link="r2/head/asus_frame"/>
    <origin rpy="-3.142 -0.071 0" xyz="0.12 -0.015 -0.14"/>
  </joint>
  <link name="r2/head/asus_frame">
    <inertial>
      <mass value="0.01"/>
      <inertia ixx="0.0001" ixy="0.0" ixz="0.0" iyy="0.0001" iyz="0.0" izz="0.0001"/>
    </inertial>
  </link>
  <joint name="r2/fixed/head/asus_frame/asus_depth_frame" type="fixed">
    <parent link="r2/head/asus_frame"/>
    <child link="r2/head/asus_depth_frame"/>
    <origin rpy="0 0 0 " xyz="0 -0.02 0 "/>
  </joint>
  <link name="r2/head/asus_depth_frame">
    <inertial>
      <mass value="0.01"/>
      <inertia ixx="0.0001" ixy="0.0" ixz="0.0" iyy="0.0001" iyz="0.0" izz="0.0001"/>
    </inertial>
  </link>
  <joint name="r2/fixed/head/vision_base/vision_center_frame" type="fixed">
    <parent link="r2/head/vision_base"/>
    <child link="r2/head/vision_center_frame"/>
    <dynamics damping="1.0"/>
    <origin rpy="1.5708 -1.5708 1.5708" xyz=" 0.066675 0.0 -0.116205 "/>
  </joint>
  <link name="r2/head/vision_center_frame">
    <inertial>
      <mass value="0.01"/>
      <inertia ixx="0.0001" ixy="0.0" ixz="0.0" iyy="0.0001" iyz="0.0" izz="0.0001"/>
    </inertial>
  </link>
  <joint name="r2/fixed/head/vision_center_frame/left_camera_frame" type="fixed">
    <parent link="r2/head/vision_center_frame"/>
    <child link="r2/head/left_camera_frame"/>
    <dynamics damping="1.0"/>
    <origin rpy="0 0 0" xyz="0.0087 0.04887 0.01789"/>
  </joint>
  <link name="r2/head/left_camera_frame">
    <inertial>
      <mass value="0.01"/>
      <inertia ixx="0.0001" ixy="0.0" ixz="0.0" iyy="0.0001" iyz="0.0" izz="0.0001"/>
    </inertial>
  </link>
  <joint name="r2/fixed/head/vision_center_frame/left_camera_frame/left_camera" type="fixed">
    <parent link="r2/head/left_camera_frame"/>
    <child link="r2/head/grasshopper/left_camera"/>
    <dynamics damping="1.0"/>
    <origin rpy="0 0 -1.5708" xyz="0 0 0"/>
  </joint>
  <link name="r2/head/grasshopper/left_camera">
    <inertial>
      <mass value="0.01"/>
      <inertia ixx="0.0001" ixy="0.0" ixz="0.0" iyy="0.0001" iyz="0.0" izz="0.0001"/>
    </inertial>
  </link>
  <joint name="r2/fixed/head/vision_center_frame/right_camera_frame" type="fixed">
    <parent link="r2/head/vision_center_frame"/>
    <child link="r2/head/right_camera_frame"/>
    <dynamics damping="1.0"/>
    <origin rpy="0 0 0" xyz="0.0087 -0.04887 0.01789"/>
  </joint>
  <link name="r2/head/right_camera_frame">
    <inertial>
      <mass value="0.01"/>
      <inertia ixx="0.0001" ixy="0.0" ixz="0.0" iyy="0.0001" iyz="0.0" izz="0.0001"/>
    </inertial>
  </link>
  <joint name="r2/fixed/head/vision_center_frame/right_camera_frame/right_camera" type="fixed">
    <parent link="r2/head/right_camera_frame"/>
    <child link="r2/head/grasshopper/right_camera"/>
    <dynamics damping="1.0"/>
    <origin rpy="0 0 -1.5708" xyz="0 0 0"/>
  </joint>
  <link name="r2/head/grasshopper/right_camera">
    <inertial>
      <mass value="0.01"/>
      <inertia ixx="0.0001" ixy="0.0" ixz="0.0" iyy="0.0001" iyz="0.0" izz="0.0001"/>
    </inertial>
  </link>
  <joint name="r2/left_arm/joint0" type="revolute">
    <parent link="r2/left_arm/shoulder/jr3"/>
    <child link="r2/left_shoulder_roll"/>
    <origin rpy="0.0 -1.5708 0.0" xyz="0.0054611 0.0 -0.13041"/>
    <axis xyz="0 0 1"/>
    <dynamics damping="10.0" friction="0.0"/>
    <limit effort="100.0" lower="-2.8270" upper="2.8270" velocity="1000"/>
  </joint>
  <link name="r2/left_shoulder_roll">
    <visual>
      <geometry>
        <mesh filename="package://r2_description/meshes/r2_upperbody/Left_Shoulder_Upper.dae"/>
      </geometry>
      <material name="dirty_white"/>
      <origin rpy="0.0 0.0 3.1416" xyz="0.0 0.0 -0.01274"/>
    </visual>
    <collision>
      <geometry>
        <mesh filename="package://r2_description/meshes/r2_upperbody/Left_Shoulder_Upper.dae"/>
      </geometry>
      <origin rpy="0.0 0.0 3.1416" xyz="0.0 0.0 -0.01274"/>
    </collision>
    <inertial>
      <origin xyz="0.00017093234 -0.0087284787   -0.10884506"/>
      <mass value="7.070314"/>
      <inertia ixx="0.076584602" ixy="0.000086319951" ixz="0.00054609047" iyy="0.08016999" iyz="0.0066841031" izz="0.02390013"/>
    </inertial>
  </link>
  <joint name="r2/left_arm/joint1" type="revolute">
    <parent link="r2/left_shoulder_roll"/>
    <child link="r2/left_shoulder_pitch"/>
    <origin rpy=" 0.0 -1.5708 1.5708" xyz=" 0.0 0.0466596 0.210022 "/>
    <axis xyz="0 0 1"/>
    <dynamics damping="10.0" friction="0.0"/>
    <limit effort="100.0" lower="-1.6758" upper="0.4292" velocity="1000"/>
  </joint>
  <link name="r2/left_shoulder_pitch">
    <visual>
      <geometry>
        <mesh filename="package://r2_description/meshes/r2_upperbody/Left_Shoulder_Lower.dae"/>
      </geometry>
      <material name="dirty_white"/>
      <origin rpy="0.0 0.0 0.0" xyz="0.0 0.0 0.0466596"/>
    </visual>
    <collision>
      <geometry>
        <mesh filename="package://r2_description/meshes/r2_upperbody/Left_Shoulder_Lower.dae"/>
      </geometry>
      <origin rpy="0.0 0.0 0.0" xyz="0.0 0.0 0.0466596"/>
    </collision>
    <inertial>
      <origin xyz="0.034871718 0.00026989995  -0.056391797"/>
      <mass value="4.7275387"/>
      <inertia ixx="0.01281093" ixy="-0.000025211205" ixz="-0.0019887882" iyy="0.026994354" iyz="-0.000056988895" izz="0.028670313"/>
    </inertial>
  </link>
  <joint name="r2/left_arm/joint2" type="revolute">
    <parent link="r2/left_shoulder_pitch"/>
    <child link="r2/left_upper_arm"/>
    <origin rpy="-1.5708 0.0 -1.5708" xyz="0.169324 0 0.0458976"/>
    <axis xyz="0 0 1"/>
    <dynamics damping="10.0" friction="0.0"/>
    <limit effort="100.0" lower="-4.5028" upper="-0.3318" velocity="1000"/>
  </joint>
  <link name="r2/left_upper_arm">
    <visual>
      <geometry>
        <mesh filename="package://r2_description/meshes/r2_upperbody/Left_Upper_Arm.dae"/>
      </geometry>
      <material name="dirty_white"/>
      <origin rpy="0.0 0.0 0.0" xyz="0.0 0.0 -0.067724"/>
    </visual>
    <collision>
      <geometry>
        <mesh filename="package://r2_description/meshes/r2_upperbody/Left_Upper_Arm.dae"/>
      </geometry>
      <origin rpy="0.0 0.0 0.0" xyz="0.0 0.0 -0.067724"/>
    </collision>
    <inertial>
      <origin xyz="0.011979384 -0.0073390714 0.079871897"/>
      <mass value="4.9025709"/>
      <inertia ixx="0.044036190" ixy="0.0013812407" ixz="-0.0068318982" iyy="0.048358309" iyz="0.0035598559" izz="0.016564943"/>
    </inertial>
  </link>
  <joint name="r2/left_arm/joint3" type="revolute">
    <parent link="r2/left_upper_arm"/>
    <child link="r2/left_elbow"/>
    <origin rpy="0.0 -1.5708 1.5708" xyz="0.05334 0.0313243 0.185006"/>
    <axis xyz="0 0 1"/>
    <dynamics damping="1.0" friction="0.0"/>
    <limit effort="100.0" lower="-2.7930" upper="0.0" velocity="1000"/>
  </joint>
  <link name="r2/left_elbow">
    <visual>
      <geometry>
        <mesh filename="package://r2_description/meshes/r2_upperbody/Left_Elbow.dae"/>
      </geometry>
      <material name="dirty_white"/>
      <origin rpy="0 0.0 0" xyz="0 0 0.0313243"/>
    </visual>
    <collision>
      <geometry>
        <mesh filename="package://r2_description/meshes/r2_upperbody/Left_Elbow.dae"/>
      </geometry>
      <origin rpy="0 0.0 0" xyz="0.0 0.0 0.0313243"/>
    </collision>
    <inertial>
      <origin xyz="0.035398630 0.025517855  -0.036241795"/>
      <mass value="2.3377006"/>
      <inertia ixx="0.0067529558" ixy="-0.0026092481" ixz="-0.00060380235" iyy="0.0080987220" iyz="-0.00047453566" izz="0.009863562"/>
    </inertial>
  </link>
  <joint name="r2/left_arm/joint4" type="revolute">
    <parent link="r2/left_elbow"/>
    <child link="r2/left_joint4_output"/>
    <origin rpy="-0.9550 1.5708 -0.9550" xyz="0.0541223 0.0533300 0.0305397"/>
    <axis xyz="0 0 1"/>
    <dynamics damping="1.0" friction="0.0"/>
    <limit effort="100.0" lower="-1.5360" upper="4.6770" velocity="1000"/>
  </joint>
  <link name="r2/left_joint4_output">
    <inertial>
      <mass value="0.01"/>
      <inertia ixx="0.0001" ixy="0.0" ixz="0.0" iyy="0.0001" iyz="0.0" izz="0.0001"/>
    </inertial>
  </link>
  <joint name="r2/fixed/left_lower_arm/left_forearm_jr3" type="fixed">
    <parent link="r2/left_joint4_output"/>
    <child link="r2/left_arm/forearm/jr3"/>
    <origin rpy="3.1416 0.0 0.78539" xyz="0.0 0.0 0.0897574"/>
  </joint>
  <link name="r2/left_arm/forearm/jr3">
    <inertial>
      <mass value="0.01"/>
      <inertia ixx="0.0001" ixy="0.0" ixz="0.0" iyy="0.0001" iyz="0.0" izz="0.0001"/>
    </inertial>
  </link>
  <joint name="r2/fixed/left_lower_arm/left_forearm" type="fixed">
    <parent link="r2/left_arm/forearm/jr3"/>
    <child link="r2/left_lower_arm"/>
    <origin rpy="3.1416 0.0 0.7854" xyz="0.0 0.0 0.0897574"/>
  </joint>
  <link name="r2/left_lower_arm">
    <visual>
      <geometry>
        <mesh filename="package://r2_description/meshes/r2_upperbody/Left_Forearm.dae"/>
      </geometry>
      <material name="dirty_white"/>
      <origin rpy="0 0 1.5708" xyz="0 0.0 0.0458777"/>
    </visual>
    <collision>
      <geometry>
        <mesh filename="package://r2_description/meshes/r2_upperbody/Left_Forearm.dae"/>
      </geometry>
      <origin rpy="0 0 1.5708" xyz="0 0.0 0.0458777"/>
    </collision>
    <inertial>
      <origin xyz="0.0039950818 0.00044312736  0.16275601"/>
      <mass value="8.1525875"/>
      <inertia ixx="0.10706156" ixy="0.00070538028" ixz="-0.0061176777" iyy="0.11007507" iyz="0.0020551081" izz="0.015240452"/>
    </inertial>
  </link>
  <joint name="r2/left_arm/wrist/pitch" type="revolute">
    <parent link="r2/left_lower_arm"/>
    <child link="r2/left_wrist_pitch"/>
    <origin rpy="0 -1.5708 0.0 " xyz="0.000616510 0 0.301768"/>
    <axis xyz="0 0 1"/>
    <dynamics damping="1.0" friction="0.0"/>
    <limit effort="100.0" lower="-0.8" upper="0.8" velocity="1000"/>
  </joint>
  <link name="r2/left_wrist_pitch">
    <inertial>
      <origin xyz="0.0 0.0 0.0"/>
      <mass value="0.01"/>
      <inertia ixx="0.0001" ixy="0.0" ixz="0.0" iyy="0.0001" iyz="0.0" izz="0.0001"/>
    </inertial>
  </link>
  <joint name="r2/left_arm/wrist/yaw" type="revolute">
    <parent link="r2/left_wrist_pitch"/>
    <child link="r2/left_wrist_yaw"/>
    <origin rpy="1.5708 0.0646 -0.0802" xyz="0.00635 0 0.00041451"/>
    <axis xyz="0 0 1"/>
    <dynamics damping="1.0" friction="0.0"/>
    <limit effort="100.0" lower="-0.75" upper="0.15" velocity="1000"/>
  </joint>
  <link name="r2/left_wrist_yaw">
    <inertial>
      <origin xyz="0.0 0.0 0.0"/>
      <mass value="0.01"/>
      <inertia ixx="0.0001" ixy="0.0" ixz="0.0" iyy="0.0001" iyz="0.0" izz="0.0001"/>
    </inertial>
  </link>
  <joint name="r2/fixed/left_wrist_yaw/left_palm" type="fixed">
    <parent link="r2/left_wrist_yaw"/>
    <child link="r2/left_palm"/>
    <origin rpy=" 0.0 0.0 0" xyz=" 0.0 0.0 0.0 "/>
  </joint>
  <link name="r2/left_palm">
    <visual>
      <geometry>
        <mesh filename="package://r2_description/meshes/r2_upperbody/Left_Palm.dae"/>
      </geometry>
      <origin rpy="3.1416 0 1.5708" xyz="0.0 0.0 0.0"/>
    </visual>
    <collision>
      <geometry>
        <mesh filename="package://r2_description/meshes/r2_upperbody/Left_Palm.dae"/>
      </geometry>
      <origin rpy="3.1416 0 1.5708" xyz="0.0 0.0 0.0"/>
    </collision>
    <inertial>
      <mass value="0.01"/>
      <inertia ixx="0.0001" ixy="0.0" ixz="0.0" iyy="0.0001" iyz="0.0" izz="0.0001"/>
    </inertial>
  </link>
  <!--
  <property name="left_arm_hand_index_j3_damping" value= "0.1" />
  <property name="left_arm_hand_index_j3_friction" value= "0.0" />
-->
  <!--
  <property name="left_arm_hand_middle_j3_damping" value= "0.1" />
  <property name="left_arm_hand_middle_j3_friction" value= "0.0" />
-->
  <!--
  <property name="left_arm_hand_ring_j1_damping" value= "0.1" />
  <property name="left_arm_hand_ring_j1_friction" value= "0.0" />
  <property name="left_arm_hand_ring_j2_damping" value= "0.1" />
  <property name="left_arm_hand_ring_j2_friction" value= "0.0" />
-->
  <!--
  <property name="left_arm_hand_little_j1_damping" value= "0.1" />
  <property name="left_arm_hand_little_j1_friction" value= "0.0" />
  <property name="left_arm_hand_little_j2_damping" value= "0.1" />
  <property name="left_arm_hand_little_j2_friction" value= "0.0" />
-->
  <joint name="r2/left_arm/hand/thumb/roll" type="revolute">
    <parent link="r2/left_wrist_yaw"/>
    <child link="r2/left_thumb_base"/>
    <origin rpy=" -1.5708 0.0 1.30899702752 " xyz=" 0.03302 0.03048 0.00635 "/>
    <axis xyz="0 0 1"/>
    <limit effort="10000000.0" lower="-4" upper="4" velocity="1000"/>
    <dynamics damping="0.1" friction="0.0"/>
  </joint>
  <joint name="r2/fixed/left_index_base/left_index_base" type="fixed">
    <parent link="r2/left_wrist_yaw"/>
    <child link="r2/left_index_base"/>
    <origin rpy=" 0.0 0.0 0.122172725275 " xyz=" 0.0994646728 0.0271119346 -0.0161544 "/>
  </joint>
  <joint name="r2/left_arm/hand/index/yaw" type="revolute">
    <parent link="r2/left_index_base"/>
    <child link="r2/left_index_yaw"/>
    <origin rpy="0.0 0.0 0.0" xyz="0.0 0.0 0.0"/>
    <axis xyz="0 0 1"/>
    <limit effort="10000000.0" lower="-4" upper="4" velocity="1000"/>
    <dynamics damping="0.1" friction="0.0"/>
  </joint>
  <joint name="r2/fixed/left_middle_base/left_middle_base" type="fixed">
    <parent link="r2/left_wrist_yaw"/>
    <child link="r2/left_middle_base"/>
    <origin rpy=" 0.0 0.0 0.0 " xyz=" 0.10646537 0.00254 -0.0161544 "/>
  </joint>
  <joint name="r2/left_arm/hand/middle/yaw" type="revolute">
    <parent link="r2/left_middle_base"/>
    <child link="r2/left_middle_yaw"/>
    <origin rpy="0.0 0.0 0.0" xyz="0.0 0.0 0.0"/>
    <axis xyz="0 0 1"/>
    <limit effort="10000000.0" lower="-4" upper="4" velocity="1000"/>
    <dynamics damping="0.1" friction="0.0"/>
  </joint>
  <joint name="r2/left_arm/hand/ringlittle/ring" type="revolute">
    <parent link="r2/left_wrist_yaw"/>
    <child link="r2/left_ring_proximal"/>
    <origin rpy=" 1.5708 -0.0 -0.122172725275 " xyz=" 0.1084570602 -0.0197673468 -0.012319 "/>
    <axis xyz="0 0 1"/>
    <limit effort="10000000.0" lower="-4" upper="4" velocity="1000"/>
    <dynamics damping="0.1" friction="0.0"/>
  </joint>
  <joint name="r2/left_arm/hand/ringlittle/little" type="revolute">
    <parent link="r2/left_wrist_yaw"/>
    <child link="r2/left_little_proximal"/>
    <origin rpy=" 1.60570321374 -0.0872667473393 -0.17453258148 " xyz=" 0.094635701 -0.0403792436 -0.0060878212 "/>
    <axis xyz="0 0 1"/>
    <limit effort="10000000.0" lower="-4" upper="4" velocity="1000"/>
    <dynamics damping="0.1" friction="0.0"/>
  </joint>
  <link name="r2/left_thumb_base">
    <inertial>
      <mass value=".05"/>
      <inertia ixx=".0010" ixy="0.0" ixz="0.0" iyy=".0010" iyz="0.0" izz=".0010"/>
    </inertial>
  </link>
  <joint name="r2/fixed/left_thumb_base/left_thumb_proximal" type="fixed">
    <parent link="r2/left_thumb_base"/>
    <child link="r2/left_thumb_proximal"/>
    <origin rpy=" -1.5708 -0.0 0.0 " xyz=" 0.011938 0.0 0.0 "/>
  </joint>
  <link name="r2/left_thumb_proximal">
    <inertial>
      <mass value=".0010"/>
      <inertia ixx=".0010" ixy="0.0" ixz="0.0" iyy=".0010" iyz="0.0" izz=".0010"/>
    </inertial>
    <visual>
      <geometry>
        <mesh filename="package://r2_description/meshes/r2_upperbody/Left_Thumb_Carp.dae"/>
      </geometry>
      <origin rpy="-1.5708 0 0" xyz="-0.01 0.0 0.0"/>
    </visual>
    <collision>
      <geometry>
        <mesh filename="package://r2_description/meshes/r2_upperbody/Left_Thumb_Carp.dae"/>
      </geometry>
      <origin rpy="-1.5708 0 0" xyz="-0.01 0.0 0.0"/>
    </collision>
  </link>
  <joint name="r2/left_arm/hand/thumb/proximal" type="revolute">
    <parent link="r2/left_thumb_proximal"/>
    <child link="r2/left_thumb_medial_prime"/>
    <origin rpy=" 0.0 0.0 0.0 " xyz=" 0.0 0.0 0.0 "/>
    <axis xyz="0 0 1"/>
    <limit effort="10000000.0" lower="-4" upper="4" velocity="1000"/>
    <dynamics damping="0.1" friction="0.0"/>
  </joint>
  <link name="r2/left_thumb_medial_prime">
    <inertial>
      <mass value=".0010"/>
      <inertia ixx=".0010" ixy="0.0" ixz="0.0" iyy=".0010" iyz="0.0" izz=".0010"/>
    </inertial>
    <visual>
      <geometry>
        <mesh filename="package://r2_description/meshes/r2_upperbody/Left_Thumb_MtCar.dae"/>
      </geometry>
      <origin rpy="-1.5708 -1.5708 0" xyz="-0.0 0 0.0"/>
    </visual>
    <collision>
      <geometry>
        <mesh filename="package://r2_description/meshes/r2_upperbody/Left_Thumb_MtCar.dae"/>
      </geometry>
      <origin rpy="-1.5708 -1.5708 0" xyz="0.0 0.0 0.0"/>
    </collision>
  </link>
  <joint name="r2/left_arm/hand/thumb/medial" type="revolute">
    <parent link="r2/left_thumb_medial_prime"/>
    <child link="r2/left_thumb_medial"/>
    <origin rpy=" -0.698132284627 -0.0 0.0 " xyz=" 0.030734 -0.001905 0.00254 "/>
    <axis xyz="0 0 1"/>
    <limit effort="10000000.0" lower="-4" upper="4" velocity="1000"/>
    <dynamics damping="0.1" friction="0.0"/>
  </joint>
  <link name="r2/left_thumb_medial">
    <inertial>
      <mass value=".0010"/>
      <inertia ixx=".0010" ixy="0.0" ixz="0.0" iyy=".0010" iyz="0.0" izz=".0010"/>
    </inertial>
    <visual>
      <geometry>
        <mesh filename="package://r2_description/meshes/r2_upperbody/Thumb_Proximal.dae"/>
      </geometry>
      <origin rpy="3.1416 0 1.5708" xyz="0.0 0.0 0.0"/>
    </visual>
    <collision>
      <geometry>
        <mesh filename="package://r2_description/meshes/r2_upperbody/Thumb_Proximal.dae"/>
      </geometry>
      <origin rpy="3.1416 0 1.5708" xyz="0.0 0.0 0.0"/>
    </collision>
  </link>
  <joint name="r2/left_arm/hand/thumb/distal" type="revolute">
    <parent link="r2/left_thumb_medial"/>
    <child link="r2/left_thumb_distal"/>
    <origin rpy=" 0.0 0.0 0.0 " xyz=" 0.03937 0.0 0.0 "/>
    <axis xyz="0 0 1"/>
    <limit effort="10000000.0" lower="-4" upper="4" velocity="1000"/>
    <dynamics damping="0.1" friction="0.0"/>
  </joint>
  <link name="r2/left_thumb_distal">
    <inertial>
      <mass value=".0010"/>
      <inertia ixx=".0010" ixy="0.0" ixz="0.0" iyy=".0010" iyz="0.0" izz=".0010"/>
    </inertial>
    <visual>
      <geometry>
        <mesh filename="package://r2_description/meshes/r2_upperbody/Thumb_Dist.dae"/>
      </geometry>
      <origin rpy="3.1416 3.1416 0" xyz="0.0 0.0 0.0"/>
    </visual>
    <collision>
      <geometry>
        <mesh filename="package://r2_description/meshes/r2_upperbody/Thumb_Dist.dae"/>
      </geometry>
      <origin rpy="3.1416 3.1416 0" xyz="0.0 0.0 0.0"/>
    </collision>
  </link>
  <joint name="r2/fixed/left_thumb_distal/left_thumb_tip" type="fixed">
    <parent link="r2/left_thumb_distal"/>
    <child link="r2/left_thumb_tip"/>
    <origin rpy=" 0.0 0.0 0.0 " xyz=" 0.03302 0.0 0.0 "/>
  </joint>
  <link name="r2/left_thumb_tip">
    <inertial>
      <mass value=".0010"/>
      <inertia ixx=".0010" ixy="0.0" ixz="0.0" iyy=".0010" iyz="0.0" izz=".0010"/>
    </inertial>
  </link>
  <link name="r2/left_index_base">
    <inertial>
      <mass value=".0010"/>
      <inertia ixx=".0010" ixy="0.0" ixz="0.0" iyy=".0010" iyz="0.0" izz=".0010"/>
    </inertial>
  </link>
  <link name="r2/left_index_yaw">
    <inertial>
      <mass value=".0010"/>
      <inertia ixx=".0010" ixy="0.0" ixz="0.0" iyy=".0010" iyz="0.0" izz=".0010"/>
    </inertial>
  </link>
  <joint name="r2/left_arm/hand/index/proximal" type="revolute">
    <parent link="r2/left_index_yaw"/>
    <child link="r2/left_index_proximal"/>
    <origin rpy=" 1.5708 0.0 0.0 " xyz=" 0.009652 0.0 0.0 "/>
    <axis xyz="0 0 1"/>
    <limit effort="10000000.0" lower="-4" upper="4" velocity="1000"/>
    <dynamics damping="0.1" friction="0.0"/>
  </joint>
  <link name="r2/left_index_proximal">
    <inertial>
      <mass value=".0010"/>
      <inertia ixx=".0010" ixy="0.0" ixz="0.0" iyy=".0010" iyz="0.0" izz=".0010"/>
    </inertial>
    <visual>
      <geometry>
        <mesh filename="package://r2_description/meshes/r2_upperbody/Finger_Proximal.dae"/>
      </geometry>
      <origin rpy="0 0 1.5708" xyz="0.0 0.0 0.0"/>
    </visual>
    <collision>
      <geometry>
        <mesh filename="package://r2_description/meshes/r2_upperbody/Finger_Proximal.dae"/>
      </geometry>
      <origin rpy="0 0 1.5708" xyz="0.0 0.0 0.0"/>
    </collision>
  </link>
  <joint name="r2/left_arm/hand/index/medial" type="revolute">
    <parent link="r2/left_index_proximal"/>
    <child link="r2/left_index_medial"/>
    <origin rpy=" 0.0 0.0 0.0 " xyz=" 0.04445 0.0 0.0 "/>
    <axis xyz="0 0 1"/>
    <limit effort="10000000.0" lower="-4" upper="4" velocity="1000"/>
    <dynamics damping="0.1" friction="0.0"/>
  </joint>
  <link name="r2/left_index_medial">
    <inertial>
      <mass value=".0010"/>
      <inertia ixx=".0010" ixy="0.0" ixz="0.0" iyy=".0010" iyz="0.0" izz=".0010"/>
    </inertial>
    <visual>
      <geometry>
        <mesh filename="package://r2_description/meshes/r2_upperbody/Finger_Mid.dae"/>
      </geometry>
      <origin rpy="3.1416 0 1.5708" xyz="0.0 0.0 0.0"/>
    </visual>
    <collision>
      <geometry>
        <mesh filename="package://r2_description/meshes/r2_upperbody/Finger_Mid.dae"/>
      </geometry>
      <origin rpy="3.1416 0 1.5708" xyz="0.0 0.0 0.0"/>
    </collision>
  </link>
  <link name="r2/left_middle_base">
    <inertial>
      <mass value=".0010"/>
      <inertia ixx=".0010" ixy="0.0" ixz="0.0" iyy=".0010" iyz="0.0" izz=".0010"/>
    </inertial>
  </link>
  <link name="r2/left_middle_yaw">
    <inertial>
      <mass value=".0010"/>
      <inertia ixx=".0010" ixy="0.0" ixz="0.0" iyy=".0010" iyz="0.0" izz=".0010"/>
    </inertial>
  </link>
  <joint name="r2/left_arm/hand/middle/proximal" type="revolute">
    <parent link="r2/left_middle_yaw"/>
    <child link="r2/left_middle_proximal"/>
    <origin rpy=" 1.5708 0.0 0.0 " xyz=" 0.009652 0.0 0.0 "/>
    <axis xyz="0 0 1"/>
    <limit effort="10000000.0" lower="-4" upper="4" velocity="1000"/>
    <dynamics damping="0.1" friction="0.0"/>
  </joint>
  <link name="r2/left_middle_proximal">
    <inertial>
      <mass value=".0010"/>
      <inertia ixx=".0010" ixy="0.0" ixz="0.0" iyy=".0010" iyz="0.0" izz=".0010"/>
    </inertial>
    <visual>
      <geometry>
        <mesh filename="package://r2_description/meshes/r2_upperbody/Finger_Proximal.dae"/>
      </geometry>
      <origin rpy="0 0 1.5708" xyz="0.0 0.0 0.0"/>
    </visual>
    <collision>
      <geometry>
        <mesh filename="package://r2_description/meshes/r2_upperbody/Finger_Proximal.dae"/>
      </geometry>
      <origin rpy="0 0 1.5708" xyz="0.0 0.0 0.0"/>
    </collision>
  </link>
  <joint name="r2/left_arm/hand/middle/medial" type="revolute">
    <parent link="r2/left_middle_proximal"/>
    <child link="r2/left_middle_medial"/>
    <origin rpy=" 0.0 0.0 0.0 " xyz=" 0.04445 0.0 0.0 "/>
    <axis xyz="0 0 1"/>
    <limit effort="10000000.0" lower="-4" upper="4" velocity="1000"/>
    <dynamics damping="0.1" friction="0.0"/>
  </joint>
  <link name="r2/left_middle_medial">
    <inertial>
      <mass value=".0010"/>
      <inertia ixx=".0010" ixy="0.0" ixz="0.0" iyy=".0010" iyz="0.0" izz=".0010"/>
    </inertial>
    <visual>
      <geometry>
        <mesh filename="package://r2_description/meshes/r2_upperbody/Finger_Mid.dae"/>
      </geometry>
      <origin rpy="3.1416 0 1.5708" xyz="0.0 0.0 0.0"/>
    </visual>
    <collision>
      <geometry>
        <mesh filename="package://r2_description/meshes/r2_upperbody/Finger_Mid.dae"/>
      </geometry>
      <origin rpy="3.1416 0 1.5708" xyz="0.0 0.0 0.0"/>
    </collision>
  </link>
  <link name="r2/left_ring_proximal">
    <inertial>
      <mass value=".0010"/>
      <inertia ixx=".0010" ixy="0.0" ixz="0.0" iyy=".0010" iyz="0.0" izz=".0010"/>
    </inertial>
    <visual>
      <geometry>
        <mesh filename="package://r2_description/meshes/r2_upperbody/Finger_Proximal.dae"/>
      </geometry>
      <origin rpy="0 0 1.5708" xyz="0.0 0.0 0.0"/>
    </visual>
    <collision>
      <geometry>
        <mesh filename="package://r2_description/meshes/r2_upperbody/Finger_Proximal.dae"/>
      </geometry>
      <origin rpy="0 0 1.5708" xyz="0.0 0.0 0.0"/>
    </collision>
  </link>
  <link name="r2/left_little_proximal">
    <inertial>
      <mass value=".0010"/>
      <inertia ixx=".0010" ixy="0.0" ixz="0.0" iyy=".0010" iyz="0.0" izz=".0010"/>
    </inertial>
    <visual>
      <geometry>
        <mesh filename="package://r2_description/meshes/r2_upperbody/Finger_Proximal.dae"/>
      </geometry>
      <origin rpy="0 0 1.5708" xyz="0.0 0.0 0.0"/>
    </visual>
    <collision>
      <geometry>
        <mesh filename="package://r2_description/meshes/r2_upperbody/Finger_Proximal.dae"/>
      </geometry>
      <origin rpy="0 0 1.5708" xyz="0.0 0.0 0.0"/>
    </collision>
  </link>
  <joint name="r2/right_arm/joint0" type="revolute">
    <parent link="r2/right_arm/shoulder/jr3"/>
    <child link="r2/right_shoulder_roll"/>
    <origin rpy="0.0 -1.5708 0.0" xyz="0.0054611 0.0 -0.13041"/>
    <axis xyz="0 0 1"/>
    <dynamics damping="10.0" friction="0.0"/>
    <limit effort="100.0" lower="-2.8270" upper="2.8270" velocity="1000"/>
  </joint>
  <link name="r2/right_shoulder_roll">
    <visual>
      <geometry>
        <mesh filename="package://r2_description/meshes/r2_upperbody/Right_Shoulder_Upper.dae"/>
      </geometry>
      <material name="dirty_white"/>
      <origin rpy="0.0 0.0 -2.4624" xyz="0.0 0.0 -0.07734"/>
    </visual>
    <collision>
      <geometry>
        <mesh filename="package://r2_description/meshes/r2_upperbody/Right_Shoulder_Upper.dae"/>
      </geometry>
      <origin rpy="0.0 0.0 -2.4624" xyz="0.0 0.0 -0.07234"/>
    </collision>
    <inertial>
      <origin xyz="0.00017093234 -0.0087284787   -0.10884506"/>
      <mass value="7.070314"/>
      <inertia ixx="0.076584602" ixy="0.000086319951" ixz="0.00054609047" iyy="0.08016999" iyz="0.0066841031" izz="0.02390013"/>
    </inertial>
  </link>
  <joint name="r2/right_arm/joint1" type="revolute">
    <parent link="r2/right_shoulder_roll"/>
    <child link="r2/right_shoulder_pitch"/>
    <origin rpy=" 0.0 -1.5708 1.5708" xyz=" 0.0 -0.0466596 0.210022 "/>
    <axis xyz="0 0 1"/>
    <dynamics damping="10.0" friction="0.0"/>
    <limit effort="100.0" lower="-1.6758" upper="0.4292" velocity="1000"/>
  </joint>
  <link name="r2/right_shoulder_pitch">
    <visual>
      <geometry>
        <mesh filename="package://r2_description/meshes/r2_upperbody/Right_Shoulder_Lower.dae"/>
      </geometry>
      <material name="dirty_white"/>
      <origin rpy="0.0 0.0 0.0" xyz="0.0 0.0 -0.0466596"/>
    </visual>
    <collision>
      <geometry>
        <mesh filename="package://r2_description/meshes/r2_upperbody/Right_Shoulder_Lower.dae"/>
      </geometry>
      <origin rpy="0.0 0.0 0.0" xyz="0.0 0.0 -0.0466596"/>
    </collision>
    <inertial>
      <origin xyz="0.034871718 0.00026989995  -0.056391797"/>
      <mass value="4.7275387"/>
      <inertia ixx="0.01281093" ixy="-0.000025211205" ixz="-0.0019887882" iyy="0.026994354" iyz="-0.000056988895" izz="0.028670313"/>
    </inertial>
  </link>
  <joint name="r2/right_arm/joint2" type="revolute">
    <parent link="r2/right_shoulder_pitch"/>
    <child link="r2/right_upper_arm"/>
    <origin rpy="-1.5708 0.0 -1.5708" xyz="0.169324 0 -0.0458976"/>
    <axis xyz="0 0 1"/>
    <dynamics damping="10.0" friction="0.0"/>
    <limit effort="100.0" lower="0.3318" upper="4.5028" velocity="1000"/>
  </joint>
  <link name="r2/right_upper_arm">
    <visual>
      <geometry>
        <mesh filename="package://r2_description/meshes/r2_upperbody/Right_Upper_Arm.dae"/>
      </geometry>
      <material name="dirty_white"/>
      <origin rpy="0.0 0.0 0.0" xyz="0.0 0.0 -0.067724"/>
    </visual>
    <collision>
      <geometry>
        <mesh filename="package://r2_description/meshes/r2_upperbody/Right_Upper_Arm.dae"/>
      </geometry>
      <origin rpy="0.0 0.0 0.0" xyz="0.0 0.0 -0.067724"/>
    </collision>
    <inertial>
      <origin xyz="0.011979384 -0.0073390714 0.079871897"/>
      <mass value="4.9025709"/>
      <inertia ixx="0.044036190" ixy="0.0013812407" ixz="-0.0068318982" iyy="0.048358309" iyz="0.0035598559" izz="0.016564943"/>
    </inertial>
  </link>
  <joint name="r2/right_arm/joint3" type="revolute">
    <parent link="r2/right_upper_arm"/>
    <child link="r2/right_elbow"/>
    <origin rpy="0.0 -1.5708 1.5708" xyz="0.05334 -0.0313243 0.185006"/>
    <axis xyz="0 0 1"/>
    <dynamics damping="1.0" friction="0.0"/>
    <limit effort="100.0" lower="-2.7930" upper="0.0" velocity="1000"/>
  </joint>
  <link name="r2/right_elbow">
    <visual>
      <geometry>
        <mesh filename="package://r2_description/meshes/r2_upperbody/Right_Elbow.dae"/>
      </geometry>
      <material name="dirty_white"/>
      <origin rpy="0 0.0 0" xyz="0 0 -0.0313243"/>
    </visual>
    <collision>
      <geometry>
        <mesh filename="package://r2_description/meshes/r2_upperbody/Right_Elbow.dae"/>
      </geometry>
      <origin rpy="0 0.0 0" xyz="0 0 -0.0313243"/>
    </collision>
    <inertial>
      <origin xyz="0.035398630 0.025517855  -0.036241795"/>
      <mass value="2.3377006"/>
      <inertia ixx="0.0067529558" ixy="-0.0026092481" ixz="-0.00060380235" iyy="0.0080987220" iyz="-0.00047453566" izz="0.009863562"/>
    </inertial>
  </link>
  <joint name="r2/right_arm/joint4" type="revolute">
    <parent link="r2/right_elbow"/>
    <child link="r2/right_joint4_output"/>
    <origin rpy="-0.9550 1.5708 -0.9550" xyz="0.0541223 0.0533300 -0.0305397"/>
    <axis xyz="0 0 1"/>
    <dynamics damping="1.0" friction="0.0"/>
    <limit effort="100.0" lower="-4.6770" upper="1.5360" velocity="1000"/>
  </joint>
  <link name="r2/right_joint4_output">
    <inertial>
      <mass value="0.01"/>
      <inertia ixx="0.0001" ixy="0.0" ixz="0.0" iyy="0.0001" iyz="0.0" izz="0.0001"/>
    </inertial>
  </link>
  <joint name="r2/fixed/right_lower_arm/right_forearm_jr3" type="fixed">
    <parent link="r2/right_joint4_output"/>
    <child link="r2/right_arm/forearm/jr3"/>
    <origin rpy="3.1416 0.0 0.78539" xyz="0.0 0.0 0.0897574"/>
  </joint>
  <link name="r2/right_arm/forearm/jr3">
    <inertial>
      <mass value="0.01"/>
      <inertia ixx="0.0001" ixy="0.0" ixz="0.0" iyy="0.0001" iyz="0.0" izz="0.0001"/>
    </inertial>
  </link>
  <joint name="r2/fixed/right_lower_arm/right_forearm" type="fixed">
    <parent link="r2/right_arm/forearm/jr3"/>
    <child link="r2/right_lower_arm"/>
    <origin rpy="3.1416 0.0 0.7854" xyz="0.0 0.0 0.0897574"/>
  </joint>
  <link name="r2/right_lower_arm">
    <visual>
      <geometry>
        <mesh filename="package://r2_description/meshes/r2_upperbody/Right_Forearm.dae"/>
      </geometry>
      <material name="dirty_white"/>
      <origin rpy="0 0 1.5708" xyz="0 0.0 0.0458777"/>
    </visual>
    <collision>
      <geometry>
        <mesh filename="package://r2_description/meshes/r2_upperbody/Right_Forearm.dae"/>
      </geometry>
      <origin rpy="0 0 1.5708" xyz="0 0.0 0.0458777"/>
    </collision>
    <inertial>
      <origin xyz="0.0039950818 0.00044312736  0.16275601"/>
      <mass value="8.1525875"/>
      <inertia ixx="0.10706156" ixy="0.00070538028" ixz="-0.0061176777" iyy="0.11007507" iyz="0.0020551081" izz="0.015240452"/>
    </inertial>
  </link>
  <joint name="r2/right_arm/wrist/pitch" type="revolute">
    <parent link="r2/right_lower_arm"/>
    <child link="r2/right_wrist_pitch"/>
    <origin rpy="0 -1.5708 0" xyz="-0.000616510 0 0.301768"/>
    <axis xyz="0 0 1"/>
    <dynamics damping="1.0" friction="0.0"/>
    <limit effort="100.0" lower="-0.8" upper="0.8" velocity="1000"/>
  </joint>
  <link name="r2/right_wrist_pitch">
    <inertial>
      <origin xyz="0.0 0.0 0.0"/>
      <mass value="0.01"/>
      <inertia ixx=".0001" ixy="0.0" ixz="0.0" iyy="0.0001" iyz="0.0" izz="0.0001"/>
    </inertial>
  </link>
  <joint name="r2/right_arm/wrist/yaw" type="revolute">
    <parent link="r2/right_wrist_pitch"/>
    <child link="r2/right_wrist_yaw"/>
    <origin rpy="1.5708 0.0646 -0.0802" xyz="0.00635 0 -0.00041451"/>
    <axis xyz="0 0 1"/>
    <dynamics damping="1.0" friction="0.0"/>
    <limit effort="100.0" lower="-0.15" upper="0.75" velocity="1000"/>
  </joint>
  <link name="r2/right_wrist_yaw">
    <inertial>
      <origin xyz="0.0 0.0 0.0"/>
      <mass value="0.01"/>
      <inertia ixx="0.0001" ixy="0.0" ixz="0.0" iyy="0.0001" iyz="0.0" izz="0.0001"/>
    </inertial>
  </link>
  <joint name="r2/fixed/right_wrist_yaw/right_palm" type="fixed">
    <parent link="r2/right_wrist_yaw"/>
    <child link="r2/right_palm"/>
    <origin rpy=" 0.0 0.0 0" xyz=" 0.0 0.0 0.0"/>
  </joint>
  <link name="r2/right_palm">
    <visual>
      <geometry>
        <mesh filename="package://r2_description/meshes/r2_upperbody/Right_Palm.dae"/>
      </geometry>
      <origin rpy="3.1416 0 1.5708" xyz="0.0 0.0 0.0"/>
    </visual>
    <collision>
      <geometry>
        <mesh filename="package://r2_description/meshes/r2_upperbody/Right_Palm.dae"/>
      </geometry>
      <origin rpy="3.1416 0 1.5708" xyz="0.0 0.0 0.0"/>
    </collision>
    <inertial>
      <mass value="0.01"/>
      <inertia ixx="0.0001" ixy="0.0" ixz="0.0" iyy="0.0001" iyz="0.0" izz="0.0001"/>
    </inertial>
  </link>
  <!--
  <property name="right_arm_hand_index_j3_damping" value= "0.1" />
  <property name="right_arm_hand_index_j3_friction" value= "0.0" />
-->
  <!--
  <property name="right_arm_hand_middle_j3_damping" value= "0.1" />
  <property name="right_arm_hand_middle_j3_friction" value= "0.0" />
-->
  <!--
  <property name="right_arm_hand_ring_j1_damping" value= "0.1" />
  <property name="right_arm_hand_ring_j1_friction" value= "0.0" />
  <property name="right_arm_hand_ring_j2_damping" value= "0.1" />
  <property name="right_arm_hand_ring_j2_friction" value= "0.0" />
-->
  <!--
  <property name="right_arm_hand_little_j1_damping" value= "0.1" />
  <property name="right_arm_hand_little_j1_friction" value= "0.0" />
  <property name="right_arm_hand_little_j2_damping" value= "0.1" />
  <property name="right_arm_hand_little_j2_friction" value= "0.0" />
-->
  <joint name="r2/right_arm/hand/thumb/roll" type="revolute">
    <parent link="r2/right_wrist_yaw"/>
    <child link="r2/right_thumb_base"/>
    <origin rpy=" 1.5708 0.174532791018 -1.30899687745 " xyz="0.03302 -0.03048 0.00635 "/>
    <axis xyz="0 0 1"/>
    <limit effort="10000000.0" lower="-4" upper="4" velocity="1000"/>
    <dynamics damping="0.1" friction="0.0"/>
  </joint>
  <joint name="r2/fixed/right_index_base/right_index_base" type="fixed">
    <parent link="r2/right_wrist_yaw"/>
    <child link="r2/right_index_base"/>
    <origin rpy=" 0.0 0.0 -0.122172725275  " xyz=" 0.0994646728 -0.0271119346 -0.0161544 "/>
  </joint>
  <joint name="r2/right_arm/hand/index/yaw" type="revolute">
    <parent link="r2/right_index_base"/>
    <child link="r2/right_index_yaw"/>
    <origin rpy="0.0 0.0 0.0" xyz="0.0 0.0 0.0"/>
    <axis xyz="0 0 1"/>
    <limit effort="10000000.0" lower="-4" upper="4" velocity="1000"/>
    <dynamics damping="0.1" friction="0.0"/>
  </joint>
  <joint name="r2/fixed/right_middle_base/right_middle_base" type="fixed">
    <parent link="r2/right_wrist_yaw"/>
    <child link="r2/right_middle_base"/>
    <origin rpy=" 0.0 0.0 0.0 " xyz="0.10646537 -0.00254 -0.0161544 "/>
  </joint>
  <joint name="r2/right_arm/hand/middle/yaw" type="revolute">
    <parent link="r2/right_middle_base"/>
    <child link="r2/right_middle_yaw"/>
    <origin rpy="0.0 0.0 0.0" xyz="0.0 0.0 0.0"/>
    <axis xyz="0 0 1"/>
    <limit effort="10000000.0" lower="-4" upper="4" velocity="1000"/>
    <dynamics damping="0.1" friction="0.0"/>
  </joint>
  <joint name="r2/right_arm/hand/ringlittle/ring" type="revolute">
    <parent link="r2/right_wrist_yaw"/>
    <child link="r2/right_ring_proximal"/>
    <origin rpy=" 1.57079632679 -0.0 0.122172725275  " xyz=" 0.1084539614 0.019792569 -0.012319 "/>
    <axis xyz="0 0 1"/>
    <limit effort="10000000.0" lower="-4" upper="4" velocity="1000"/>
    <dynamics damping="0.1" friction="0.0"/>
  </joint>
  <joint name="r2/right_arm/hand/ringlittle/little" type="revolute">
    <parent link="r2/right_wrist_yaw"/>
    <child link="r2/right_little_proximal"/>
    <origin rpy=" 1.53588943985 -0.0872667473393 0.17453258148  " xyz=" 0.094635701 0.0403792436 -0.0060878212 "/>
    <axis xyz="0 0 1"/>
    <limit effort="10000000.0" lower="-4" upper="4" velocity="1000"/>
    <dynamics damping="0.1" friction="0.0"/>
  </joint>
  <link name="r2/right_thumb_base">
    <inertial>
      <mass value=".05"/>
      <inertia ixx=".0010" ixy="0.0" ixz="0.0" iyy=".0010" iyz="0.0" izz=".0010"/>
    </inertial>
  </link>
  <joint name="r2/fixed/right_thumb_base/right_thumb_proximal" type="fixed">
    <parent link="r2/right_thumb_base"/>
    <child link="r2/right_thumb_proximal"/>
    <origin rpy=" -1.5708 -0.0 0.0 " xyz=" 0.011938 0.0 0.0 "/>
  </joint>
  <link name="r2/right_thumb_proximal">
    <inertial>
      <mass value=".05"/>
      <inertia ixx=".0010" ixy="0.0" ixz="0.0" iyy=".0010" iyz="0.0" izz=".0010"/>
    </inertial>
    <visual>
      <geometry>
        <mesh filename="package://r2_description/meshes/r2_upperbody/Left_Thumb_Carp.dae"/>
      </geometry>
      <origin rpy="-1.5708 0 0" xyz="-0.01 0.0 0.0"/>
    </visual>
    <collision>
      <geometry>
        <mesh filename="package://r2_description/meshes/r2_upperbody/Left_Thumb_Carp.dae" scale="0.9 0.9 0.9"/>
      </geometry>
      <origin rpy="-1.5708 0 0" xyz="-0.01 0.0 0.0"/>
    </collision>
  </link>
  <joint name="r2/right_arm/hand/thumb/proximal" type="revolute">
    <parent link="r2/right_thumb_proximal"/>
    <child link="r2/right_thumb_medial_prime"/>
    <origin rpy=" 0.0 0.0 0.0 " xyz=" 0.0 0.0 0.0 "/>
    <axis xyz="0 0 1"/>
    <limit effort="10000000.0" lower="-4" upper="4" velocity="1000"/>
    <dynamics damping="0.1" friction="0.0"/>
  </joint>
  <link name="r2/right_thumb_medial_prime">
    <inertial>
      <mass value=".05"/>
      <inertia ixx=".0010" ixy="0.0" ixz="0.0" iyy=".0010" iyz="0.0" izz=".0010"/>
    </inertial>
    <visual>
      <geometry>
        <mesh filename="package://r2_description/meshes/r2_upperbody/Right_Thumb_MtCar.dae"/>
      </geometry>
      <origin rpy="-1.5708 -1.5708 0 " xyz="-0.0 0 0.0"/>
    </visual>
    <collision>
      <geometry>
        <mesh filename="package://r2_description/meshes/r2_upperbody/Right_Thumb_MtCar.dae" scale="0.9 0.9 0.9"/>
      </geometry>
      <origin rpy="-1.5708 -1.5708 0 " xyz="-0.0 0 0.0"/>
    </collision>
  </link>
  <joint name="r2/right_arm/hand/thumb/medial" type="revolute">
    <parent link="r2/right_thumb_medial_prime"/>
    <child link="r2/right_thumb_medial"/>
    <origin rpy=" 0.698132284627 0.0 0.0 " xyz=" 0.030734 -0.001905 -0.00254 "/>
    <axis xyz="0 0 1"/>
    <limit effort="10000000.0" lower="-4" upper="4" velocity="1000"/>
    <dynamics damping="0.1" friction="0.0"/>
  </joint>
  <link name="r2/right_thumb_medial">
    <inertial>
      <mass value=".05"/>
      <inertia ixx=".0010" ixy="0.0" ixz="0.0" iyy=".0010" iyz="0.0" izz=".0010"/>
    </inertial>
    <visual>
      <geometry>
        <mesh filename="package://r2_description/meshes/r2_upperbody/Thumb_Proximal.dae"/>
      </geometry>
      <origin rpy="3.1416 0 1.5708" xyz="0.0 0.0 0.0"/>
    </visual>
    <collision>
      <geometry>
        <mesh filename="package://r2_description/meshes/r2_upperbody/Thumb_Proximal.dae"/>
      </geometry>
      <origin rpy="3.1416 0 1.5708" xyz="0.0 0.0 0.0"/>
    </collision>
  </link>
  <joint name="r2/right_arm/hand/thumb/distal" type="revolute">
    <parent link="r2/right_thumb_medial"/>
    <child link="r2/right_thumb_distal"/>
    <origin rpy=" 0.0 0.0 0.0 " xyz=" 0.03937 0.0 0.0 "/>
    <axis xyz="0 0 1"/>
    <limit effort="10000000.0" lower="-4" upper="4" velocity="1000"/>
    <dynamics damping="0.1" friction="0.0"/>
  </joint>
  <link name="r2/right_thumb_distal">
    <inertial>
      <mass value=".05"/>
      <inertia ixx=".0010" ixy="0.0" ixz="0.0" iyy=".0010" iyz="0.0" izz=".0010"/>
    </inertial>
    <visual>
      <geometry>
        <mesh filename="package://r2_description/meshes/r2_upperbody/Thumb_Dist.dae"/>
      </geometry>
      <origin rpy="3.1416 3.1416 0" xyz="0.0 0.0 0.0"/>
    </visual>
    <collision>
      <geometry>
        <mesh filename="package://r2_description/meshes/r2_upperbody/Thumb_Dist.dae"/>
      </geometry>
      <origin rpy="3.1416 3.1416 0" xyz="0.0 0.0 0.0"/>
    </collision>
  </link>
  <joint name="r2/fixed/right_thumb_distal/right_thumb_tip" type="fixed">
    <parent link="r2/right_thumb_distal"/>
    <child link="r2/right_thumb_tip"/>
    <origin rpy=" 0.0 0.0 0.0 " xyz=" 0.03302 0.0 0.0 "/>
  </joint>
  <link name="r2/right_thumb_tip">
    <inertial>
      <mass value=".05"/>
      <inertia ixx=".0010" ixy="0.0" ixz="0.0" iyy=".0010" iyz="0.0" izz=".0010"/>
    </inertial>
  </link>
  <link name="r2/right_index_base">
    <inertial>
      <mass value=".05"/>
      <inertia ixx=".0010" ixy="0.0" ixz="0.0" iyy=".0010" iyz="0.0" izz=".0010"/>
    </inertial>
  </link>
  <link name="r2/right_index_yaw">
    <inertial>
      <mass value=".05"/>
      <inertia ixx=".0010" ixy="0.0" ixz="0.0" iyy=".0010" iyz="0.0" izz=".0010"/>
    </inertial>
  </link>
  <joint name="r2/right_arm/hand/index/proximal" type="revolute">
    <parent link="r2/right_index_yaw"/>
    <child link="r2/right_index_proximal"/>
    <origin rpy=" 1.5708 -0.0 0.0 " xyz=" 0.009652 0.0 0.0 "/>
    <axis xyz="0 0 1"/>
    <limit effort="10000000.0" lower="-4" upper="4" velocity="1000"/>
    <dynamics damping="0.1" friction="0.0"/>
  </joint>
  <link name="r2/right_index_proximal">
    <inertial>
      <mass value=".05"/>
      <inertia ixx=".0010" ixy="0.0" ixz="0.0" iyy=".0010" iyz="0.0" izz=".0010"/>
    </inertial>
    <visual>
      <geometry>
        <mesh filename="package://r2_description/meshes/r2_upperbody/Finger_Proximal.dae"/>
      </geometry>
      <origin rpy="0 0 1.5708" xyz="0.0 0.0 0.0"/>
    </visual>
    <collision>
      <geometry>
        <mesh filename="package://r2_description/meshes/r2_upperbody/Finger_Proximal.dae"/>
      </geometry>
      <origin rpy="0 0 1.5708" xyz="0.0 0.0 0.0"/>
    </collision>
  </link>
  <joint name="r2/right_arm/hand/index/medial" type="revolute">
    <parent link="r2/right_index_proximal"/>
    <child link="r2/right_index_medial"/>
    <origin rpy=" 0.0 0.0 0.0 " xyz=" 0.04445 0.0 0.0 "/>
    <axis xyz="0 0 1"/>
    <limit effort="10000000.0" lower="-4" upper="4" velocity="1000"/>
    <dynamics damping="0.1" friction="0.0"/>
  </joint>
  <link name="r2/right_index_medial">
    <inertial>
      <mass value=".05"/>
      <inertia ixx=".0010" ixy="0.0" ixz="0.0" iyy=".0010" iyz="0.0" izz=".0010"/>
    </inertial>
    <visual>
      <geometry>
        <mesh filename="package://r2_description/meshes/r2_upperbody/Finger_Mid.dae"/>
      </geometry>
      <origin rpy="3.1416 0 1.5708" xyz="0.0 0.0 0.0"/>
    </visual>
    <collision>
      <geometry>
        <mesh filename="package://r2_description/meshes/r2_upperbody/Finger_Mid.dae"/>
      </geometry>
      <origin rpy="3.1416 0 1.5708" xyz="0.0 0.0 0.0"/>
    </collision>
  </link>
  <link name="r2/right_middle_base">
    <inertial>
      <mass value=".0010"/>
      <inertia ixx=".0010" ixy="0.0" ixz="0.0" iyy=".0010" iyz="0.0" izz=".0010"/>
    </inertial>
  </link>
  <link name="r2/right_middle_yaw">
    <inertial>
      <mass value=".0010"/>
      <inertia ixx=".0010" ixy="0.0" ixz="0.0" iyy=".0010" iyz="0.0" izz=".0010"/>
    </inertial>
  </link>
  <joint name="r2/right_arm/hand/middle/proximal" type="revolute">
    <parent link="r2/right_middle_yaw"/>
    <child link="r2/right_middle_proximal"/>
    <origin rpy=" 1.5708 -0.0 0.0 " xyz=" 0.009652 0.0 0.0 "/>
    <axis xyz="0 0 1"/>
    <limit effort="10000000.0" lower="-4" upper="4" velocity="1000"/>
    <dynamics damping="0.1" friction="0.0"/>
  </joint>
  <link name="r2/right_middle_proximal">
    <inertial>
      <mass value=".05"/>
      <inertia ixx=".0010" ixy="0.0" ixz="0.0" iyy=".0010" iyz="0.0" izz=".0010"/>
    </inertial>
    <visual>
      <geometry>
        <mesh filename="package://r2_description/meshes/r2_upperbody/Finger_Proximal.dae"/>
      </geometry>
      <origin rpy="0 0 1.5708" xyz="0.0 0.0 0.0"/>
    </visual>
    <collision>
      <geometry>
        <mesh filename="package://r2_description/meshes/r2_upperbody/Finger_Proximal.dae" scale="0.9 0.9 0.9"/>
      </geometry>
      <origin rpy="0 0 1.5708" xyz="0.0 0.0 0.0"/>
    </collision>
  </link>
  <joint name="r2/right_arm/hand/middle/medial" type="revolute">
    <parent link="r2/right_middle_proximal"/>
    <child link="r2/right_middle_medial"/>
    <origin rpy=" 0.0 0.0 0.0 " xyz=" 0.04445 0.0 0.0 "/>
    <axis xyz="0 0 1"/>
    <limit effort="10000000.0" lower="-4" upper="4" velocity="1000"/>
    <dynamics damping="0.1" friction="0.0"/>
  </joint>
  <link name="r2/right_middle_medial">
    <inertial>
      <mass value=".05"/>
      <inertia ixx=".0010" ixy="0.0" ixz="0.0" iyy=".0010" iyz="0.0" izz=".0010"/>
    </inertial>
    <visual>
      <geometry>
        <mesh filename="package://r2_description/meshes/r2_upperbody/Finger_Mid.dae"/>
      </geometry>
      <origin rpy="3.1416 0 1.5708" xyz="0.0 0.0 0.0"/>
    </visual>
    <collision>
      <geometry>
        <mesh filename="package://r2_description/meshes/r2_upperbody/Finger_Mid.dae" scale="0.9 0.9 0.9"/>
      </geometry>
      <origin rpy="3.1416 0 1.5708" xyz="0.0 0.0 0.0"/>
    </collision>
  </link>
  <link name="r2/right_ring_proximal">
    <inertial>
      <mass value=".05"/>
      <inertia ixx=".0010" ixy="0.0" ixz="0.0" iyy=".0010" iyz="0.0" izz=".0010"/>
    </inertial>
    <visual>
      <geometry>
        <mesh filename="package://r2_description/meshes/r2_upperbody/Finger_Proximal.dae"/>
      </geometry>
      <origin rpy="0 0 1.5708" xyz="0.0 0.0 0.0"/>
    </visual>
    <collision>
      <geometry>
        <mesh filename="package://r2_description/meshes/r2_upperbody/Finger_Proximal.dae" scale="0.9 0.9 0.9"/>
      </geometry>
      <origin rpy="0 0 1.5708" xyz="0.0 0.0 0.0"/>
    </collision>
  </link>
  <link name="r2/right_little_proximal">
    <inertial>
      <mass value=".05"/>
      <inertia ixx=".0010" ixy="0.0" ixz="0.0" iyy=".0010" iyz="0.0" izz=".0010"/>
    </inertial>
    <visual>
      <geometry>
        <mesh filename="package://r2_description/meshes/r2_upperbody/Finger_Proximal.dae"/>
      </geometry>
      <origin rpy="0 0 1.5708" xyz="0.0 0.0 0.0"/>
    </visual>
    <collision>
      <geometry>
        <mesh filename="package://r2_description/meshes/r2_upperbody/Finger_Proximal.dae" scale="0.9 0.9 0.9"/>
      </geometry>
      <origin rpy="0 0 1.5708" xyz="0.0 0.0 0.0"/>
    </collision>
  </link>
</robot>
