<?xml version="1.0" ?>
<!-- =================================================================================== -->
<!-- |    This document was autogenerated by xacro from ./robots/r2_left_gripper.xacro | -->
<!-- |    EDITING THIS FILE BY HAND IS NOT RECOMMENDED                                 | -->
<!-- =================================================================================== -->
<robot name="r2" xmlns:xacro="http://www.ros.org/wiki/xacro">
  <link name="r2/world_ref"/>
  <joint name="r2/fixed/world_ref/robot_world" type="fixed">
    <parent link="r2/world_ref"/>
    <child link="r2/robot_world"/>
    <origin rpy="0 0 0" xyz="0 0 0"/>
  </joint>
  <joint name="r2/fixed/robot_world/left_leg" type="fixed">
    <parent link="r2/robot_world"/>
    <child link="r2/left_leg/ati"/>
    <origin rpy="0 0 0" xyz="0.0 0.0 0.0"/>
  </joint>
  <link name="r2/left_leg/ati">
    <inertial>
      <mass value="0.01"/>
      <inertia ixx="0.0001" ixy="0.0" ixz="0.0" iyy="0.0001" iyz="0.0" izz="0.0001"/>
    </inertial>
  </link>
  <link name="r2/robot_world">
    <inertial>
      <mass value="0.01"/>
      <inertia ixx="0.0001" ixy="0.0" ixz="0.0" iyy="0.0001" iyz="0.0" izz="0.0001"/>
    </inertial>
  </link>
  <joint name="r2/fixed/robot_world/robot_base" type="fixed">
    <parent link="r2/robot_world"/>
    <child link="r2/robot_base"/>
    <origin rpy="0.0 3.14159 3.14159" xyz="0.0 0.0 0.0"/>
  </joint>
  <link name="r2/robot_base">
    <inertial>
      <mass value="0.01"/>
      <inertia ixx="0.0001" ixy="0.0" ixz="0.0" iyy="0.0001" iyz="0.0" izz="0.0001"/>
    </inertial>
  </link>
  <material name="white">
    <color rgba="1.0 1.0 1.0 1.0"/>
  </material>
  <material name="dirty_white">
    <color rgba="0.322 0.322 0.322 1.0"/>
  </material>
  <material name="gold">
    <color rgba=".878 .49 0.008 1"/>
  </material>
  <material name="steel">
    <color rgba=".7 .7 .7 1"/>
  </material>
  <material name="blue">
    <color rgba="0 0 0.8 1"/>
  </material>
  <joint name="r2/fixed/left_ankle_roll/left_leg_ati" type="fixed">
    <parent link="r2/left_ankle_roll"/>
    <child link="r2/left_leg/ati"/>
    <origin rpy="3.1416 0.0 -1.5708" xyz="0.0 0.0 0.070182"/>
  </joint>
  <link name="r2/left_leg/ati">
    <inertial>
      <mass value="0.01"/>
      <inertia ixx="0.0001" ixy="0.0" ixz="0.0" iyy="0.0001" iyz="0.0" izz="0.0001"/>
    </inertial>
  </link>
  <joint name="r2/fixed/left_leg_ati/left_leg_foot" type="fixed">
    <parent link="r2/left_leg/ati"/>
    <child link="r2/left_leg_foot"/>
    <origin rpy="3.1416 0.0 -1.5708" xyz="0.0 0.0 0.0206502"/>
  </joint>
  <link name="r2/left_leg_foot">
    <inertial>
      <mass value="4.63812"/>
      <inertia ixx="0.01951" ixy="-0.00030332" ixz="-0.00011945" iyy="0.017896" iyz="-0.000689634" izz="0.010101"/>
      <origin rpy="0 0 0" xyz="-0.0015 -0.00021835 0.08493"/>
    </inertial>
    <visual>
      <geometry>
        <mesh filename="package://r2_description/meshes/r2c_legs/foot_body.dae"/>
      </geometry>
      <origin rpy="0 0 -1.5708" xyz="0 0 0"/>
    </visual>
    <collision>
      <geometry>
        <mesh filename="package://r2_description/meshes/r2c_legs/foot_body.dae"/>
      </geometry>
      <origin rpy="0 0 -1.5708" xyz="0 0 0"/>
    </collision>
  </link>
  <joint name="r2/fixed/left_leg_foot/left_hr_tip" type="fixed">
    <parent link="r2/left_leg_foot"/>
    <child link="r2/left_leg/gripper/tip"/>
    <origin rpy="0.0 0 0" xyz="0 0 0.19451"/>
  </joint>
  <link name="r2/left_leg/gripper/tip">
    <inertial>
      <mass value="0.01"/>
      <inertia ixx="0.0001" ixy="0.0" ixz="0.0" iyy="0.0001" iyz="0.0" izz="0.0001"/>
    </inertial>
  </link>
  <joint name="r2/fixed/left_leg_foot/left_st_tip" type="fixed">
    <parent link="r2/left_leg_foot"/>
    <child link="r2/left_leg/gripper/st_tip"/>
    <origin rpy="0.0 0 0" xyz="0 0 0.21991"/>
  </joint>
  <link name="r2/left_leg/gripper/st_tip">
    <inertial>
      <mass value="0.01"/>
      <inertia ixx="0.0001" ixy="0.0" ixz="0.0" iyy="0.0001" iyz="0.0" izz="0.0001"/>
    </inertial>
  </link>
  <joint name="r2/fixed/left_leg_foot/left_leg_nano_physical" type="fixed">
    <parent link="r2/left_leg_foot"/>
    <child link="r2/left_leg/nano_physical"/>
    <origin rpy="0 0 0" xyz="-0.025 .07 0.13"/>
  </joint>
  <link name="r2/left_leg/nano_physical">
    <inertial>
      <mass value="0.01"/>
      <inertia ixx="0.0001" ixy="0.0" ixz="0.0" iyy="0.0001" iyz="0.0" izz="0.0001"/>
    </inertial>
  </link>
  <joint name="r2/fixed/left_leg_foot/left_leg_flea_physical" type="fixed">
    <parent link="r2/left_leg_foot"/>
    <child link="r2/left_leg/flea_physical"/>
    <origin rpy="0.0 0 0" xyz="0.025 .07 0.13"/>
  </joint>
  <link name="r2/left_leg/flea_physical">
    <inertial>
      <mass value="0.01"/>
      <inertia ixx="0.0001" ixy="0.0" ixz="0.0" iyy="0.0001" iyz="0.0" izz="0.0001"/>
    </inertial>
  </link>
  <!--  placeholder for screw joint-->
  <joint name="r2/left_leg/gripper/joint0" type="revolute">
    <parent link="r2/left_leg_foot"/>
    <child link="r2/left_leg/gripper/link0"/>
    <origin rpy="0 0 0" xyz="0 0 0"/>
    <axis xyz="0 0 1"/>
    <dynamics damping="1.0" friction="0.0"/>
    <limit effort="330.0" lower="-.1" upper=".75" velocity="1.0"/>
  </joint>
  <link name="r2/left_leg/gripper/link0">
    <inertial>
      <mass value="0.01"/>
      <inertia ixx="0.0001" ixy="0.0" ixz="0.0" iyy="0.0001" iyz="0.0" izz="0.0001"/>
    </inertial>
  </link>
  <joint name="r2/left_leg/gripper/jawLeft" type="revolute">
    <parent link="r2/left_leg_foot"/>
    <child link="r2/left_leg/gripper/jaw_left"/>
    <origin rpy="0.0 -0.087266 0.0" xyz="0.01905 0 0.17546"/>
    <axis xyz="0 1 0"/>
    <dynamics damping="1.0" friction="0.0"/>
    <limit effort="330.0" lower="-.1" upper=".75" velocity="1.0"/>
    <traits spring_k="2.5"/>
  </joint>
  <link name="r2/left_leg/gripper/jaw_left">
    <inertial>
      <mass value="0.01"/>
      <inertia ixx="0.1" ixy="0.0" ixz="0.0" iyy="0.1" iyz="0.0" izz="0.1"/>
      <origin rpy="0 0 -1.5708" xyz="0.00236 0 0.02395"/>
    </inertial>
    <visual>
      <geometry>
        <mesh filename="package://r2_description/meshes/r2c_legs/foot_jaw.dae"/>
      </geometry>
      <origin rpy="0 0 -1.5708" xyz="0 0 0"/>
    </visual>
    <collision>
      <geometry>
        <mesh filename="package://r2_description/meshes/r2c_legs/foot_jaw.dae"/>
      </geometry>
      <origin rpy="0 0 -1.5708" xyz="0 0 0"/>
    </collision>
  </link>
  <joint name="r2/left_leg/gripper/jawRight" type="revolute">
    <parent link="r2/left_leg_foot"/>
    <child link="r2/left_leg/gripper/jaw_right"/>
    <origin rpy="0.0 0.087266 0.0" xyz="-0.01905 0 0.17546"/>
    <axis xyz="0 -1 0"/>
    <dynamics damping="1.0" friction="0.0"/>
    <limit effort="330.0" lower="-.1" upper=".75" velocity="1.0"/>
    <traits spring_k="2.5"/>
  </joint>
  <link name="r2/left_leg/gripper/jaw_right">
    <inertial>
      <mass value="0.01"/>
      <inertia ixx="0.1" ixy="0.0" ixz="0.0" iyy="0.1" iyz="0.0" izz="0.1"/>
      <origin rpy="0 0 1.5708" xyz="0.00236 0 0.02395"/>
    </inertial>
    <visual>
      <geometry>
        <mesh filename="package://r2_description/meshes/r2c_legs/foot_jaw.dae"/>
      </geometry>
      <origin rpy="0 0 1.5708" xyz="0 0 0"/>
    </visual>
    <collision>
      <geometry>
        <mesh filename="package://r2_description/meshes/r2c_legs/foot_jaw.dae"/>
      </geometry>
      <origin rpy="0 0 1.5708" xyz="0 0 0"/>
    </collision>
  </link>
</robot>
