<?xml version="1.0" ?>
<!-- =================================================================================== -->
<!-- |    This document was autogenerated by xacro from ./robots/r2c_sim_legs_control.urdf.xacro | -->
<!-- |    EDITING THIS FILE BY HAND IS NOT RECOMMENDED                                 | -->
<!-- =================================================================================== -->
<robot name="r2" xmlns:xacro="http://www.ros.org/wiki/xacro">
  <link name="r2/world_ref"/>
  <joint name="r2/fixed/world_ref/robot_world" type="fixed">
    <parent link="r2/world_ref"/>
    <child link="r2/robot_world"/>
    <origin rpy="0 0 0" xyz="0 0 0"/>
  </joint>
  <link name="r2/robot_world">
    <inertial>
      <mass value="0.01"/>
      <inertia ixx="0.0001" ixy="0.0" ixz="0.0" iyy="0.0001" iyz="0.0" izz="0.0001"/>
    </inertial>
  </link>
  <joint name="r2/fixed/robot_world/robot_base" type="fixed">
    <parent link="r2/robot_world"/>
    <child link="r2/robot_base"/>
    <origin rpy="0.0 3.14159 3.14159" xyz="0.0 0.0 0.0"/>
  </joint>
  <link name="r2/robot_base">
    <inertial>
      <mass value="0.01"/>
      <inertia ixx="0.0001" ixy="0.0" ixz="0.0" iyy="0.0001" iyz="0.0" izz="0.0001"/>
    </inertial>
  </link>
  <material name="white">
    <color rgba="1.0 1.0 1.0 1.0"/>
  </material>
  <material name="dirty_white">
    <color rgba="0.322 0.322 0.322 1.0"/>
  </material>
  <material name="gold">
    <color rgba=".878 .49 0.008 1"/>
  </material>
  <material name="steel">
    <color rgba=".7 .7 .7 1"/>
  </material>
  <material name="blue">
    <color rgba="0 0 0.8 1"/>
  </material>
  <link name="r2/pelvis">
    <inertial>
      <mass value="12.2831"/>
      <inertia ixx="0.10679" ixy="0.00009239" ixz="-0.00002105" iyy="0.05595" iyz="0.0" izz="0.1022"/>
      <origin rpy="0 0 0" xyz="0.00001909 0.0 -0.008524"/>
    </inertial>
    <visual>
      <geometry>
        <mesh filename="package://r2_description/meshes/r2c_legs/r2cl_ext_pelvis.dae"/>
      </geometry>
      <material name="gold"/>
      <origin rpy="0 0 0" xyz="0 0 0"/>
    </visual>
    <collision>
      <geometry>
        <mesh filename="package://r2_description/meshes/r2c_legs/r2cl_ext_pelvis.dae"/>
      </geometry>
      <origin rpy="0 0 0" xyz="0 0 0"/>
    </collision>
  </link>
  <joint name="r2/fixed/robot_base/pelvis" type="fixed">
    <parent link="r2/robot_base"/>
    <child link="r2/pelvis"/>
    <origin rpy="0 3.14159 0" xyz="0 0 0.098"/>
  </joint>
  <joint name="r2/fixed/pelvis/left_leg_base" type="fixed">
    <parent link="r2/pelvis"/>
    <child link="r2/left_leg_base"/>
    <origin rpy="0 0.000000 1.570796" xyz="0.0 0 0.0"/>
  </joint>
  <link name="r2/left_leg_base">
    <inertial>
      <mass value="0.01"/>
      <inertia ixx="0.0001" ixy="0.0" ixz="0.0" iyy="0.0001" iyz="0.0" izz="0.0001"/>
    </inertial>
  </link>
  <joint name="r2/fixed/left_leg_base/left_leg_j0_base" type="fixed">
    <parent link="r2/left_leg_base"/>
    <child link="r2/left_leg_j0_base"/>
    <origin rpy="0.0 1.8325957 3.14159" xyz="-0.1104900 0.0 -0.0297180"/>
  </joint>
  <link name="r2/left_leg_j0_base">
    <inertial>
      <mass value="0.01"/>
      <inertia ixx="0.0001" ixy="0.0" ixz="0.0" iyy="0.0001" iyz="0.0" izz="0.0001"/>
    </inertial>
  </link>
  <joint name="r2/left_leg/joint0" type="revolute">
    <parent link="r2/left_leg_j0_base"/>
    <child link="r2/left_hip_roll"/>
    <origin rpy="0.0 0 0" xyz="0 0 0"/>
    <axis xyz="0 0 1"/>
    <dynamics damping="10.0" friction="0.0"/>
    <limit effort="330.0" lower="-3.14159" upper="3.14159" velocity="1.0"/>
    <traits spring_k="2.5"/>
  </joint>
  <link name="r2/left_hip_roll">
    <inertial>
      <mass value="2.5410"/>
      <inertia ixx="0.006434" ixy="0.0007087" ixz="-0.001543" iyy="0.009325" iyz="0.0008694" izz="0.006904"/>
      <origin rpy="0.0 0.0 0.0" xyz="0.03372 -0.02428 0.07903"/>
    </inertial>
    <visual>
      <geometry>
        <mesh filename="package://r2_description/meshes/r2c_legs/r2cl_ext_bone3.dae"/>
      </geometry>
      <origin rpy="0 0 0" xyz="0.0 0.0 0.0"/>
    </visual>
    <collision>
      <geometry>
        <mesh filename="package://r2_description/meshes/r2c_legs/r2cl_ext_bone3.dae"/>
      </geometry>
      <origin rpy="0 0 0" xyz="0.0 0.0 0.0"/>
    </collision>
  </link>
  <joint name="r2/left_leg/joint1" type="revolute">
    <parent link="r2/left_hip_roll"/>
    <child link="r2/left_hip_pitch"/>
    <origin rpy="-1.570796  -0.2617994 0.0000000" xyz="0.050629765 +0.0022860 0.103498576"/>
    <axis xyz="0 0 1"/>
    <dynamics damping="5.0" friction="0.0"/>
    <limit effort="330.0" lower="-1.42244" upper="1.20427" velocity="1.0"/>
    <traits spring_k="2.5"/>
  </joint>
  <link name="r2/left_hip_pitch">
    <inertial>
      <mass value="4.6734"/>
      <inertia ixx="0.01002" ixy="0.007194" ixz="0.002041" iyy="0.03307" iyz="-0.0007281" izz="0.03728"/>
      <origin rpy="0 0 0" xyz="0.09450 -0.03354 0.008185"/>
    </inertial>
    <visual>
      <geometry>
        <mesh filename="package://r2_description/meshes/r2c_legs/r2cl_ext_bone1.dae"/>
      </geometry>
      <origin rpy="0 0 0" xyz="0 0 0"/>
    </visual>
    <collision>
      <geometry>
        <mesh filename="package://r2_description/meshes/r2c_legs/r2cl_ext_bone1.dae"/>
      </geometry>
      <origin rpy="0 0 0" xyz="0 0 0"/>
    </collision>
  </link>
  <joint name="r2/left_leg/joint2" type="revolute">
    <parent link="r2/left_hip_pitch"/>
    <child link="r2/left_upper_leg"/>
    <origin rpy=" 1.570796 0.0 1.570796" xyz="0.200 -0.050 0.004"/>
    <axis xyz="0 0 1"/>
    <dynamics damping="5.0" friction="0.0"/>
    <limit effort="330.0" lower="-3.14159" upper="3.14159" velocity="1.0"/>
    <traits spring_k="2.5"/>
  </joint>
  <link name="r2/left_upper_leg">
    <inertial>
      <mass value="3.7745"/>
      <inertia ixx="0.02163" ixy="-0.001453" ixz="0.003137" iyy="0.01832" iyz="0.004738" izz="0.009798"/>
      <origin rpy="0 0 0" xyz="-0.01485 -0.02188 0.09676"/>
    </inertial>
    <visual>
      <geometry>
        <mesh filename="package://r2_description/meshes/r2c_legs/r2cl_ext_bone2.dae"/>
      </geometry>
      <origin rpy="0 0 0" xyz="0 0 0"/>
    </visual>
    <collision>
      <geometry>
        <mesh filename="package://r2_description/meshes/r2c_legs/r2cl_ext_bone2.dae"/>
      </geometry>
      <origin rpy="0 0 0" xyz="0 0 0"/>
    </collision>
  </link>
  <joint name="r2/left_leg/joint3" type="revolute">
    <parent link="r2/left_upper_leg"/>
    <child link="r2/left_knee"/>
    <origin rpy="0.0 -1.570796 3.14159" xyz="-0.002 -0.050 0.157"/>
    <axis xyz="0 0 1"/>
    <dynamics damping="5.0" friction="0.0"/>
    <limit effort="330.0" lower="-0.10472" upper="2.68781" velocity="1.0"/>
    <traits spring_k="2.5"/>
  </joint>
  <link name="r2/left_knee">
    <inertial>
      <mass value="4.6734"/>
      <inertia ixx="0.01002" ixy="0.007194" ixz="0.002041" iyy="0.03307" iyz="-0.0007281" izz="0.03728"/>
      <origin rpy="0 0 0" xyz="0.09450 -0.03354 0.008185"/>
    </inertial>
    <visual>
      <geometry>
        <mesh filename="package://r2_description/meshes/r2c_legs/r2cl_ext_bone1.dae"/>
      </geometry>
      <origin rpy="0 0 0" xyz="0 0 0"/>
    </visual>
    <collision>
      <geometry>
        <mesh filename="package://r2_description/meshes/r2c_legs/r2cl_ext_bone1.dae"/>
      </geometry>
      <material name="gold"/>
      <origin rpy="0 0 0" xyz="0 0 0"/>
    </collision>
  </link>
  <joint name="r2/left_leg/joint4" type="revolute">
    <parent link="r2/left_knee"/>
    <child link="r2/left_lower_leg"/>
    <origin rpy="0 1.570796 0" xyz="0.200 -0.050 0.004"/>
    <axis xyz="0 0 1"/>
    <dynamics damping="5.0" friction="0.0"/>
    <limit effort="330.0" lower="-3.14159" upper="3.14159" velocity="1.0"/>
    <traits spring_k="2.5"/>
  </joint>
  <link name="r2/left_lower_leg">
    <inertial>
      <mass value="3.7745"/>
      <inertia ixx="0.02163" ixy="-0.001453" ixz="0.003137" iyy="0.01832" iyz="0.004738" izz="0.009798"/>
      <origin rpy="0 0 0" xyz="-0.01485 -0.02188 0.09676"/>
    </inertial>
    <visual>
      <geometry>
        <mesh filename="package://r2_description/meshes/r2c_legs/r2cl_ext_bone2.dae"/>
      </geometry>
      <origin rpy="0 0 0" xyz="0 0 0"/>
    </visual>
    <collision>
      <geometry>
        <mesh filename="package://r2_description/meshes/r2c_legs/r2cl_ext_bone2.dae"/>
      </geometry>
      <origin rpy="0 0 0" xyz="0 0 0"/>
    </collision>
  </link>
  <joint name="r2/left_leg/joint5" type="revolute">
    <parent link="r2/left_lower_leg"/>
    <child link="r2/left_ankle_pitch"/>
    <origin rpy="0.0 -1.570796 3.14159" xyz="-0.002 -0.050 0.157"/>
    <axis xyz="0 0 1"/>
    <dynamics damping="5.0" friction="0.0"/>
    <limit effort="330.0" lower="-0.10472" upper="2.68781" velocity="1.0"/>
    <traits spring_k="2.5"/>
  </joint>
  <link name="r2/left_ankle_pitch">
    <inertial>
      <mass value="4.6734"/>
      <inertia ixx="0.01002" ixy="0.007194" ixz="0.002041" iyy="0.03307" iyz="-0.0007281" izz="0.03728"/>
      <origin rpy="0 0 0" xyz="0.09450 -0.03354 0.008185"/>
    </inertial>
    <visual>
      <geometry>
        <mesh filename="package://r2_description/meshes/r2c_legs/r2cl_ext_bone1.dae"/>
      </geometry>
      <origin rpy="0 0 0" xyz="0 0 0"/>
    </visual>
    <collision>
      <geometry>
        <mesh filename="package://r2_description/meshes/r2c_legs/r2cl_ext_bone1.dae"/>
      </geometry>
      <origin rpy="0 0 0" xyz="0 0 0"/>
    </collision>
  </link>
  <joint name="r2/left_leg/joint6" type="revolute">
    <parent link="r2/left_ankle_pitch"/>
    <child link="r2/left_ankle_roll"/>
    <origin rpy="3.14159 -1.570796 0" xyz="0.199643 -0.0508 0.00325"/>
    <axis xyz="0 0 1"/>
    <dynamics damping="5.0" friction="0.0"/>
    <limit effort="330.0" lower="-3.14159" upper="3.14159" velocity="1.0"/>
    <traits spring_k="2.5"/>
  </joint>
  <link name="r2/left_ankle_roll">
    <inertial>
      <mass value="1.4461"/>
      <inertia ixx="0.001780" ixy="0.00001801" ixz="0.0000002218" iyy="0.001767" iyz="0.0000006717" izz="0.002949"/>
      <origin rpy="0 0 0" xyz="-0.00004402 0.0001052 0.02940"/>
    </inertial>
    <visual>
      <geometry>
        <cylinder length=".06" radius=".066"/>
      </geometry>
      <material name="dirty_white"/>
      <origin rpy="0 0 0" xyz="0 0 0.025"/>
    </visual>
    <collision>
      <geometry>
        <cylinder length=".06" radius=".066"/>
      </geometry>
      <origin rpy="0 0 0" xyz="0 0 0.025"/>
    </collision>
  </link>
  <joint name="r2/fixed/left_ankle_roll/left_leg_ati" type="fixed">
    <parent link="r2/left_ankle_roll"/>
    <child link="r2/left_leg/ati"/>
    <origin rpy="3.1416 0.0 -1.5708" xyz="0.0 0.0 0.070182"/>
  </joint>
  <link name="r2/left_leg/ati">
    <inertial>
      <mass value="0.01"/>
      <inertia ixx="0.0001" ixy="0.0" ixz="0.0" iyy="0.0001" iyz="0.0" izz="0.0001"/>
    </inertial>
  </link>
  <joint name="r2/fixed/left_leg_ati/left_leg_foot" type="fixed">
    <parent link="r2/left_leg/ati"/>
    <child link="r2/left_leg_foot"/>
    <origin rpy="3.1416 0.0 -1.5708" xyz="0.0 0.0 0.0206502"/>
  </joint>
  <link name="r2/left_leg_foot">
    <inertial>
      <mass value="4.63812"/>
      <inertia ixx="0.01951" ixy="-0.00030332" ixz="-0.00011945" iyy="0.017896" iyz="-0.000689634" izz="0.010101"/>
      <origin rpy="0 0 0" xyz="-0.0015 -0.00021835 0.08493"/>
    </inertial>
    <visual>
      <geometry>
        <mesh filename="package://r2_description/meshes/r2c_legs/foot_body.dae"/>
      </geometry>
      <origin rpy="0 0 -1.5708" xyz="0 0 0"/>
    </visual>
    <collision>
      <geometry>
        <mesh filename="package://r2_description/meshes/r2c_legs/foot_body.dae"/>
      </geometry>
      <origin rpy="0 0 -1.5708" xyz="0 0 0"/>
    </collision>
  </link>
  <joint name="r2/fixed/left_leg_foot/left_hr_tip" type="fixed">
    <parent link="r2/left_leg_foot"/>
    <child link="r2/left_leg/gripper/tip"/>
    <origin rpy="0.0 0 0" xyz="0 0 0.19451"/>
  </joint>
  <link name="r2/left_leg/gripper/tip">
    <inertial>
      <mass value="0.01"/>
      <inertia ixx="0.0001" ixy="0.0" ixz="0.0" iyy="0.0001" iyz="0.0" izz="0.0001"/>
    </inertial>
  </link>
  <joint name="r2/fixed/left_leg_foot/left_st_tip" type="fixed">
    <parent link="r2/left_leg_foot"/>
    <child link="r2/left_leg/gripper/st_tip"/>
    <origin rpy="0.0 0 0" xyz="0 0 0.21991"/>
  </joint>
  <link name="r2/left_leg/gripper/st_tip">
    <inertial>
      <mass value="0.01"/>
      <inertia ixx="0.0001" ixy="0.0" ixz="0.0" iyy="0.0001" iyz="0.0" izz="0.0001"/>
    </inertial>
  </link>
  <joint name="r2/fixed/left_leg_foot/left_leg_nano_physical" type="fixed">
    <parent link="r2/left_leg_foot"/>
    <child link="r2/left_leg/nano_physical"/>
    <origin rpy="0 0 0" xyz="-0.025 .07 0.13"/>
  </joint>
  <link name="r2/left_leg/nano_physical">
    <inertial>
      <mass value="0.01"/>
      <inertia ixx="0.0001" ixy="0.0" ixz="0.0" iyy="0.0001" iyz="0.0" izz="0.0001"/>
    </inertial>
  </link>
  <joint name="r2/fixed/left_leg_foot/left_leg_flea_physical" type="fixed">
    <parent link="r2/left_leg_foot"/>
    <child link="r2/left_leg/flea_physical"/>
    <origin rpy="0.0 0 0" xyz="0.025 .07 0.13"/>
  </joint>
  <link name="r2/left_leg/flea_physical">
    <inertial>
      <mass value="0.01"/>
      <inertia ixx="0.0001" ixy="0.0" ixz="0.0" iyy="0.0001" iyz="0.0" izz="0.0001"/>
    </inertial>
  </link>
  <joint name="r2/fixed/pelvis/right_leg_base" type="fixed">
    <parent link="r2/pelvis"/>
    <child link="r2/right_leg_base"/>
    <origin rpy="0 0.000000 1.570796" xyz="0.0 0 0.0"/>
  </joint>
  <link name="r2/right_leg_base">
    <inertial>
      <mass value="0.01"/>
      <inertia ixx="0.0001" ixy="0.0" ixz="0.0" iyy="0.0001" iyz="0.0" izz="0.0001"/>
    </inertial>
  </link>
  <joint name="r2/fixed/right_leg_base/right_leg_j0_base" type="fixed">
    <parent link="r2/right_leg_base"/>
    <child link="r2/right_leg_j0_base"/>
    <origin rpy="0.0 1.8325957 0.0" xyz="0.1104900 0.0 -0.0297180"/>
  </joint>
  <link name="r2/right_leg_j0_base">
    <inertial>
      <mass value="0.01"/>
      <inertia ixx="0.0001" ixy="0.0" ixz="0.0" iyy="0.0001" iyz="0.0" izz="0.0001"/>
    </inertial>
  </link>
  <joint name="r2/right_leg/joint0" type="revolute">
    <parent link="r2/right_leg_j0_base"/>
    <child link="r2/right_hip_roll"/>
    <origin rpy="0.0 0.0 0.0" xyz="0 0 0"/>
    <axis xyz="0 0 1"/>
    <dynamics damping="10.0" friction="0.0"/>
    <limit effort="330.0" lower="-3.14159" upper="3.14159" velocity="1.0"/>
    <traits spring_k="2.5"/>
  </joint>
  <link name="r2/right_hip_roll">
    <inertial>
      <mass value="2.5410"/>
      <inertia ixx="0.006434" ixy="0.0007087" ixz="-0.001543" iyy="0.009325" iyz="0.0008694" izz="0.006904"/>
      <origin rpy="0.0 0.0 0.0" xyz="0.03372 -0.02428 0.07903"/>
    </inertial>
    <visual>
      <geometry>
        <mesh filename="package://r2_description/meshes/r2c_legs/r2cl_ext_bone3.dae"/>
      </geometry>
      <origin rpy="0 0 0" xyz="0.0 0.0 0.0"/>
    </visual>
    <collision>
      <geometry>
        <mesh filename="package://r2_description/meshes/r2c_legs/r2cl_ext_bone3.dae"/>
      </geometry>
      <origin rpy="0 0 0" xyz="0.0 0.0 0.0"/>
    </collision>
  </link>
  <joint name="r2/right_leg/joint1" type="revolute">
    <parent link="r2/right_hip_roll"/>
    <child link="r2/right_hip_pitch"/>
    <origin rpy="-1.570796  -0.2617994 0.0000000" xyz="0.050629765 -0.0022860 0.103498576"/>
    <axis xyz="0 0 1"/>
    <dynamics damping="5.0" friction="0.0"/>
    <limit effort="330.0" lower="-1.42244" upper="1.20427" velocity="1.0"/>
    <traits spring_k="2.5"/>
  </joint>
  <link name="r2/right_hip_pitch">
    <inertial>
      <mass value="4.6734"/>
      <inertia ixx="0.01002" ixy="0.007194" ixz="0.002041" iyy="0.03307" iyz="-0.0007281" izz="0.03728"/>
      <origin rpy="0 0 0" xyz="0.09450 -0.03354 0.008185"/>
    </inertial>
    <visual>
      <geometry>
        <mesh filename="package://r2_description/meshes/r2c_legs/r2cl_ext_bone1.dae"/>
      </geometry>
      <origin rpy="0 0 0" xyz="0 0 0"/>
    </visual>
    <collision>
      <geometry>
        <mesh filename="package://r2_description/meshes/r2c_legs/r2cl_ext_bone1.dae"/>
      </geometry>
      <origin rpy="0 0 0" xyz="0 0 0"/>
    </collision>
  </link>
  <joint name="r2/right_leg/joint2" type="revolute">
    <parent link="r2/right_hip_pitch"/>
    <child link="r2/right_upper_leg"/>
    <origin rpy="-1.570796 0.0 -1.570796" xyz="0.200 -0.050 0.004"/>
    <axis xyz="0 0 1"/>
    <dynamics damping="5.0" friction="0.0"/>
    <limit effort="330.0" lower="-3.14159" upper="3.14159" velocity="1.0"/>
    <traits spring_k="2.5"/>
  </joint>
  <link name="r2/right_upper_leg">
    <inertial>
      <mass value="3.7745"/>
      <inertia ixx="0.02163" ixy="-0.001453" ixz="0.003137" iyy="0.01832" iyz="0.004738" izz="0.009798"/>
      <origin rpy="0 0 0" xyz="-0.01485 -0.02188 0.09676"/>
    </inertial>
    <visual>
      <geometry>
        <mesh filename="package://r2_description/meshes/r2c_legs/r2cl_ext_bone2.dae"/>
      </geometry>
      <origin rpy="0 0 0" xyz="0 0 0"/>
    </visual>
    <collision>
      <geometry>
        <mesh filename="package://r2_description/meshes/r2c_legs/r2cl_ext_bone2.dae"/>
      </geometry>
      <origin rpy="0 0 0" xyz="0 0 0.0"/>
    </collision>
  </link>
  <joint name="r2/right_leg/joint3" type="revolute">
    <parent link="r2/right_upper_leg"/>
    <child link="r2/right_knee"/>
    <origin rpy="0.0 -1.570796 3.14159" xyz="-0.00200 -0.050  0.157"/>
    <axis xyz="0 0 1"/>
    <dynamics damping="5.0" friction="0.0"/>
    <limit effort="330.0" lower="-0.10472" upper="2.68781" velocity="1.0"/>
    <traits spring_k="2.5"/>
  </joint>
  <link name="r2/right_knee">
    <inertial>
      <mass value="4.6734"/>
      <inertia ixx="0.01002" ixy="0.007194" ixz="0.002041" iyy="0.03307" iyz="-0.0007281" izz="0.03728"/>
      <origin rpy="0 0 0" xyz="0.09450 -0.03354 0.008185"/>
    </inertial>
    <visual>
      <geometry>
        <mesh filename="package://r2_description/meshes/r2c_legs/r2cl_ext_bone1.dae"/>
      </geometry>
      <origin rpy="0 0 0" xyz="0 0 0"/>
    </visual>
    <collision>
      <geometry>
        <mesh filename="package://r2_description/meshes/r2c_legs/r2cl_ext_bone1.dae"/>
      </geometry>
      <material name="gold"/>
      <origin rpy="0 0 0" xyz="0 0 0"/>
    </collision>
  </link>
  <joint name="r2/right_leg/joint4" type="revolute">
    <parent link="r2/right_knee"/>
    <child link="r2/right_lower_leg"/>
    <origin rpy="0 1.570796 0" xyz="0.200 -0.050 0.004"/>
    <axis xyz="0 0 1"/>
    <dynamics damping="5.0" friction="0.0"/>
    <limit effort="330.0" lower="-3.14159" upper="3.14159" velocity="1.0"/>
    <traits spring_k="2.5"/>
  </joint>
  <link name="r2/right_lower_leg">
    <inertial>
      <mass value="3.7745"/>
      <inertia ixx="0.02163" ixy="-0.001453" ixz="0.003137" iyy="0.01832" iyz="0.004738" izz="0.009798"/>
      <origin rpy="0 0 0" xyz="-0.01485 -0.02188 0.09676"/>
    </inertial>
    <visual>
      <geometry>
        <mesh filename="package://r2_description/meshes/r2c_legs/r2cl_ext_bone2.dae"/>
      </geometry>
      <origin rpy="0 0 0" xyz="0 0 0"/>
    </visual>
    <collision>
      <geometry>
        <mesh filename="package://r2_description/meshes/r2c_legs/r2cl_ext_bone2.dae"/>
      </geometry>
      <origin rpy="0 0 0" xyz="0 0 0.0"/>
    </collision>
  </link>
  <joint name="r2/right_leg/joint5" type="revolute">
    <parent link="r2/right_lower_leg"/>
    <child link="r2/right_ankle_pitch"/>
    <origin rpy="0.0 -1.570796 3.14159" xyz="-0.002 -0.050 0.157"/>
    <axis xyz="0 0 1"/>
    <dynamics damping="5.0" friction="0.0"/>
    <limit effort="330.0" lower="-0.10472" upper="2.68781" velocity="1.0"/>
    <traits spring_k="2.5"/>
  </joint>
  <link name="r2/right_ankle_pitch">
    <inertial>
      <mass value="4.6734"/>
      <inertia ixx="0.01002" ixy="0.007194" ixz="0.002041" iyy="0.03307" iyz="-0.0007281" izz="0.03728"/>
      <origin rpy="0 0 0" xyz="0.09450 -0.03354 0.008185"/>
    </inertial>
    <visual>
      <geometry>
        <mesh filename="package://r2_description/meshes/r2c_legs/r2cl_ext_bone1.dae"/>
      </geometry>
      <origin rpy="0 0 0" xyz="0 0 0"/>
    </visual>
    <collision>
      <geometry>
        <mesh filename="package://r2_description/meshes/r2c_legs/r2cl_ext_bone1.dae"/>
      </geometry>
      <origin rpy="0 0 0" xyz="0 0 0"/>
    </collision>
  </link>
  <joint name="r2/right_leg/joint6" type="revolute">
    <parent link="r2/right_ankle_pitch"/>
    <child link="r2/right_ankle_roll"/>
    <origin rpy="3.14159 -1.570796 0 " xyz="0.199643 -0.0508 0.00325"/>
    <axis xyz="0 0 1"/>
    <dynamics damping="5.0" friction="0.0"/>
    <limit effort="330.0" lower="-3.14159" upper="3.14159" velocity="1.0"/>
    <traits spring_k="2.5"/>
  </joint>
  <link name="r2/right_ankle_roll">
    <inertial>
      <mass value="1.4461"/>
      <inertia ixx="0.001780" ixy="0.00001801" ixz="0.0000002218" iyy="0.001767" iyz="0.0000006717" izz="0.002949"/>
      <origin rpy="0 0 0" xyz="-0.00004402 0.0001052 0.02940"/>
    </inertial>
    <visual>
      <geometry>
        <cylinder length=".06" radius=".066"/>
      </geometry>
      <material name="dirty_white"/>
      <origin rpy="0 0 0" xyz="0 0 0.025"/>
    </visual>
    <collision>
      <geometry>
        <cylinder length=".06" radius=".066"/>
      </geometry>
      <origin rpy="0 0 0" xyz="0 0 0.025"/>
    </collision>
  </link>
  <joint name="r2/fixed/right_ankle_roll/right_leg_ati" type="fixed">
    <parent link="r2/right_ankle_roll"/>
    <child link="r2/right_leg/ati"/>
    <origin rpy="3.1416 0.0 -1.5708" xyz="0.0 0.0 0.070182"/>
  </joint>
  <link name="r2/right_leg/ati">
    <inertial>
      <mass value="0.01"/>
      <inertia ixx="0.0001" ixy="0.0" ixz="0.0" iyy="0.0001" iyz="0.0" izz="0.0001"/>
    </inertial>
  </link>
  <joint name="r2/fixed/right_leg_ati/right_leg_foot" type="fixed">
    <parent link="r2/right_leg/ati"/>
    <child link="r2/right_leg_foot"/>
    <origin rpy="3.1416 0.0 -1.5708" xyz="0.0 0.0 0.0206502"/>
  </joint>
  <link name="r2/right_leg_foot">
    <inertial>
      <mass value="4.63812"/>
      <inertia ixx="0.01951" ixy="-0.00030332" ixz="-0.00011945" iyy="0.017896" iyz="-0.000689634" izz="0.010101"/>
      <origin rpy="0 0 0" xyz="-0.0015 -0.00021835 0.08493"/>
    </inertial>
    <visual>
      <geometry>
        <mesh filename="package://r2_description/meshes/r2c_legs/foot_body.dae"/>
      </geometry>
      <origin rpy="0 0 -1.5708" xyz="0 0 0"/>
    </visual>
    <collision>
      <geometry>
        <mesh filename="package://r2_description/meshes/r2c_legs/foot_body.dae"/>
      </geometry>
      <origin rpy="0 0 -1.5708" xyz="0 0 0"/>
    </collision>
  </link>
  <joint name="r2/fixed/right_leg_foot/right_hr_tip" type="fixed">
    <parent link="r2/right_leg_foot"/>
    <child link="r2/right_leg/gripper/tip"/>
    <origin rpy="0.0 0 0" xyz="0 0 0.19451"/>
  </joint>
  <link name="r2/right_leg/gripper/tip">
    <inertial>
      <mass value="0.01"/>
      <inertia ixx="0.0001" ixy="0.0" ixz="0.0" iyy="0.0001" iyz="0.0" izz="0.0001"/>
    </inertial>
  </link>
  <joint name="r2/fixed/right_leg_foot/right_st_tip" type="fixed">
    <parent link="r2/right_leg_foot"/>
    <child link="r2/right_leg/gripper/st_tip"/>
    <origin rpy="0.0 0 0" xyz="0 0 0.21991"/>
  </joint>
  <link name="r2/right_leg/gripper/st_tip">
    <inertial>
      <mass value="0.01"/>
      <inertia ixx="0.0001" ixy="0.0" ixz="0.0" iyy="0.0001" iyz="0.0" izz="0.0001"/>
    </inertial>
  </link>
  <joint name="r2/fixed/right_leg_foot/right_leg_nano_physical" type="fixed">
    <parent link="r2/right_leg_foot"/>
    <child link="r2/right_leg/nano_physical"/>
    <origin rpy="0 0 0" xyz="-0.025 .07 0.13"/>
  </joint>
  <link name="r2/right_leg/nano_physical">
    <inertial>
      <mass value="0.01"/>
      <inertia ixx="0.0001" ixy="0.0" ixz="0.0" iyy="0.0001" iyz="0.0" izz="0.0001"/>
    </inertial>
  </link>
  <joint name="r2/fixed/right_leg_foot/right_leg_flea_physical" type="fixed">
    <parent link="r2/right_leg_foot"/>
    <child link="r2/right_leg/flea_physical"/>
    <origin rpy="0.0 0 0" xyz="0.025 .07 0.13"/>
  </joint>
  <link name="r2/right_leg/flea_physical">
    <inertial>
      <mass value="0.01"/>
      <inertia ixx="0.0001" ixy="0.0" ixz="0.0" iyy="0.0001" iyz="0.0" izz="0.0001"/>
    </inertial>
  </link>
</robot>
